<?xml version="1.0" ?>
<!-- =================================================================================== -->
<!-- |    This document was autogenerated by xacro from robot_core.xacro               | -->
<!-- |    EDITING THIS FILE BY HAND IS NOT RECOMMENDED                                 | -->
<!-- =================================================================================== -->
<robot>
  <!-- Specify some standard inertial calculations https://en.wikipedia.org/wiki/List_of_moments_of_inertia -->
  <!-- These make use of xacro's mathematical functionality -->
  <material name="white">
    <color rgba="1 1 1 1"/>
  </material>
  <material name="orange">
    <color rgba="1 0.3 0.1 1"/>
  </material>
  <material name="blue">
    <color rgba="0.2 0.2 1 1"/>
  </material>
  <material name="black">
    <color rgba="0 0 0 1"/>
  </material>
  <link name="base_link">
    </link>
  <joint name="chassis_joint" type="fixed">
    <parent link="base_link"/>
    <child link="chassis"/>
    <origin xyz="-0.3 0 0"/>
  </joint>
  <link name="chassis">
    <visual>
      <origin rpy="0 0 0" xyz="0.8225 0 0.85"/>
      <geometry>
        <box size="1.645 0.8 1.8"/>
      </geometry>
      <material name="white"/>
    </visual>
    <collision>
      <origin rpy="0 0 0" xyz="0.8225 0 0.85"/>
      <geometry>
        <box size="1.645 0.8 1.8"/>
      </geometry>
    </collision>
    <inertial>
      <origin rpy="0 0 0" xyz="0.8225 0 0.85"/>
      <mass value="50"/>
      <inertia ixx="16.166666666666664" ixy="0.0" ixz="0.0" iyy="24.775104166666665" iyz="0.0" izz="13.941770833333331"/>
    </inertial>
  </link>
  <gazebo reference="chassis">
    <material>Gazebo/White</material>
  </gazebo>
  <!-- LEFT WHEEL -->
  <joint name="left_wheel_joint" type="continuous">
    <parent link="base_link"/>
    <child link="left_wheel"/>
    <origin rpy="-1.5707963267948966 0 0" xyz="0 0.4 0"/>
    <axis xyz="0 0 1"/>
  </joint>
  <link name="left_wheel">
    <visual>
      <geometry>
        <cylinder length="0.1" radius="0.2"/>
      </geometry>
      <material name="blue"/>
    </visual>
    <collision>
      <geometry>
        <cylinder length="0.1" radius="0.2"/>
      </geometry>
    </collision>
    <inertial>
      <origin rpy="0 0 0" xyz="0 0 0"/>
      <mass value="5"/>
      <inertia ixx="0.054166666666666675" ixy="0.0" ixz="0.0" iyy="0.054166666666666675" iyz="0.0" izz="0.10000000000000002"/>
    </inertial>
  </link>
  <gazebo reference="left_wheel">
    <material>Gazebo/Blue</material>
  </gazebo>
  <!-- RIGHT WHEEL -->
  <joint name="right_wheel_joint" type="continuous">
    <parent link="base_link"/>
    <child link="right_wheel"/>
    <origin rpy="1.5707963267948966 0 0" xyz="0 -0.4 0"/>
    <axis xyz="0 0 -1"/>
  </joint>
  <link name="right_wheel">
    <visual>
      <geometry>
        <cylinder length="0.1" radius="0.2"/>
      </geometry>
      <material name="blue"/>
    </visual>
    <collision>
      <geometry>
        <cylinder length="0.1" radius="0.2"/>
      </geometry>
    </collision>
    <inertial>
      <origin rpy="0 0 0" xyz="0 0 0"/>
      <mass value="5"/>
      <inertia ixx="0.054166666666666675" ixy="0.0" ixz="0.0" iyy="0.054166666666666675" iyz="0.0" izz="0.10000000000000002"/>
    </inertial>
  </link>
  <gazebo reference="right_wheel">
    <material>Gazebo/Blue</material>
  </gazebo>
  <!-- CASTER WHEEL -->
  <joint name="caster_wheel_joint" type="fixed">
    <parent link="chassis"/>
    <child link="caster_wheel"/>
    <origin rpy="0 0 0" xyz="1.4 0 -0.1"/>
  </joint>
  <link name="caster_wheel">
    <visual>
      <geometry>
        <sphere radius="0.1"/>
      </geometry>
      <material name="black"/>
    </visual>
    <collision>
      <geometry>
        <sphere radius="0.1"/>
      </geometry>
    </collision>
    <inertial>
      <origin rpy="0 0 0" xyz="0 0 0"/>
      <mass value="5"/>
      <inertia ixx="0.020000000000000004" ixy="0.0" ixz="0.0" iyy="0.020000000000000004" iyz="0.0" izz="0.020000000000000004"/>
    </inertial>
  </link>
  <gazebo reference="caster_wheel">
    <material>Gazebo/Black</material>
    <mu1 value="0.15"/>
    <mu2 value="0.15"/>
  </gazebo>
  <!-- Cart -->
  <joint name="cart_joint" type="revolute">
    <parent link="chassis"/>
    <child link="cart"/>
    <origin rpy="0 0 3.141592653589793" xyz="-0.5334 0 0"/>
    <axis xyz="0 0 1"/>
    <limit effort="10" lower="-1.57" upper="1.57" velocity="1.0"/>
  </joint>
  <link name="cart">
    <visual>
      <origin rpy="0 0 0" xyz="0.9 0 0.7"/>
      <geometry>
        <box size="1.8 1.11 1.5"/>
      </geometry>
      <material name="white"/>
    </visual>
    <collision>
      <origin rpy="0 0 0" xyz="0.9 0 1.12"/>
      <geometry>
        <box size="1.8 1.11 1.5"/>
      </geometry>
    </collision>
    <inertial>
      <origin rpy="0 0 0" xyz="0.9 0 1.12"/>
      <mass value="50"/>
      <inertia ixx="14.508749999999997" ixy="0.0" ixz="0.0" iyy="22.874999999999996" iyz="0.0" izz="18.63375"/>
    </inertial>
  </link>
  <!-- Cart Left Wheel -->
  <joint name="cart_left_wheel_joint" type="continuous">
    <parent link="cart"/>
    <child link="cart_left_wheel"/>
    <origin rpy="-1.5707963267948966 0 0" xyz="1.6 0.55 0"/>
    <axis xyz="0 0 1"/>
  </joint>
  <link name="cart_left_wheel">
    <visual>
      <geometry>
        <cylinder length="0.2" radius="0.15"/>
      </geometry>
      <material name="blue"/>
    </visual>
    <collision>
      <geometry>
        <cylinder length="0.2" radius="0.15"/>
      </geometry>
    </collision>
    <inertial>
      <origin rpy="0 0 0" xyz="0 0 0"/>
      <mass value="5"/>
      <inertia ixx="0.04479166666666666" ixy="0.0" ixz="0.0" iyy="0.04479166666666666" iyz="0.0" izz="0.056249999999999994"/>
    </inertial>
  </link>
  <gazebo reference="cart_left_wheel">
    <material>Gazebo/Blue</material>
  </gazebo>
  <!-- Cart Right Wheel -->
  <joint name="cart_right_wheel_joint" type="continuous">
    <parent link="cart"/>
    <child link="cart_right_wheel"/>
    <origin rpy="1.5707963267948966 0 0" xyz="1.6 -0.55 0"/>
    <axis xyz="0 0 -1"/>
  </joint>
  <link name="cart_right_wheel">
    <visual>
      <geometry>
        <cylinder length="0.2" radius="0.15"/>
      </geometry>
      <material name="blue"/>
    </visual>
    <collision>
      <geometry>
        <cylinder length="0.2" radius="0.15"/>
      </geometry>
    </collision>
    <inertial>
      <origin rpy="0 0 0" xyz="0 0 0"/>
      <mass value="5"/>
      <inertia ixx="0.04479166666666666" ixy="0.0" ixz="0.0" iyy="0.04479166666666666" iyz="0.0" izz="0.056249999999999994"/>
    </inertial>
  </link>
  <gazebo reference="cart_right_wheel">
    <material>Gazebo/Blue</material>
  </gazebo>
  <!-- 2.3334 -->
  <!-- Cart 2 -->
  <joint name="cart2_joint" type="revolute">
    <parent link="cart"/>
    <child link="cart2"/>
    <origin rpy="0 0 0" xyz="2.7334 0 0"/>
    <axis xyz="0 0 1"/>
    <limit effort="10" lower="-1.57" upper="1.57" velocity="1.0"/>
  </joint>
  <link name="cart2">
    <visual>
      <origin rpy="0 0 0" xyz="0.9 0 0.7"/>
      <geometry>
        <box size="1.8 1.11 1.5"/>
      </geometry>
      <material name="white"/>
    </visual>
    <collision>
      <origin rpy="0 0 0" xyz="0.9 0 1.12"/>
      <geometry>
        <box size="1.8 1.11 1.5"/>
      </geometry>
    </collision>
    <inertial>
      <origin rpy="0 0 0" xyz="0.9 0 1.12"/>
      <mass value="20"/>
      <inertia ixx="5.8035" ixy="0.0" ixz="0.0" iyy="9.15" iyz="0.0" izz="7.4535"/>
    </inertial>
  </link>
  <joint name="cart2_left_wheel_joint" type="continuous">
    <parent link="cart2"/>
    <child link="cart2_left_wheel"/>
    <origin rpy="-1.5707963267948966 0 0" xyz="1.6 0.55 0"/>
    <axis xyz="0 0 1"/>
  </joint>
  <link name="cart2_left_wheel">
    <visual>
      <geometry>
        <cylinder length="0.2" radius="0.15"/>
      </geometry>
      <material name="blue"/>
    </visual>
    <collision>
      <geometry>
        <cylinder length="0.2" radius="0.15"/>
      </geometry>
    </collision>
    <inertial>
      <origin rpy="0 0 0" xyz="0 0 0"/>
      <mass value="5"/>
      <inertia ixx="0.04479166666666666" ixy="0.0" ixz="0.0" iyy="0.04479166666666666" iyz="0.0" izz="0.056249999999999994"/>
    </inertial>
  </link>
  <gazebo reference="cart2_left_wheel">
    <material>Gazebo/Blue</material>
  </gazebo>
  <joint name="cart2_right_wheel_joint" type="continuous">
    <parent link="cart2"/>
    <child link="cart2_right_wheel"/>
    <origin rpy="1.5707963267948966 0 0" xyz="1.6 -0.55 0"/>
    <axis xyz="0 0 -1"/>
  </joint>
  <link name="cart2_right_wheel">
    <visual>
      <geometry>
        <cylinder length="0.2" radius="0.15"/>
      </geometry>
      <material name="blue"/>
    </visual>
    <collision>
      <geometry>
        <cylinder length="0.2" radius="0.15"/>
      </geometry>
    </collision>
    <inertial>
      <origin rpy="0 0 0" xyz="0 0 0"/>
      <mass value="5"/>
      <inertia ixx="0.04479166666666666" ixy="0.0" ixz="0.0" iyy="0.04479166666666666" iyz="0.0" izz="0.056249999999999994"/>
    </inertial>
  </link>
  <gazebo reference="cart2_right_wheel">
    <material>Gazebo/Blue</material>
  </gazebo>
</robot>
