<sdf version='1.7'>
  <world name='default'>
    <light name='sun' type='directional'>
      <cast_shadows>1</cast_shadows>
      <pose>0 0 10 0 -0 0</pose>
      <diffuse>0.8 0.8 0.8 1</diffuse>
      <specular>0.2 0.2 0.2 1</specular>
      <attenuation>
        <range>1000</range>
        <constant>0.9</constant>
        <linear>0.01</linear>
        <quadratic>0.001</quadratic>
      </attenuation>
      <direction>-0.5 0.1 -0.9</direction>
      <spot>
        <inner_angle>0</inner_angle>
        <outer_angle>0</outer_angle>
        <falloff>0</falloff>
      </spot>
    </light>
    <model name='ground_plane'>
      <static>1</static>
      <link name='link'>
        <collision name='collision'>
          <geometry>
            <plane>
              <normal>0 0 1</normal>
              <size>100 100</size>
            </plane>
          </geometry>
          <surface>
            <friction>
              <ode>
                <mu>100</mu>
                <mu2>50</mu2>
              </ode>
              <torsional>
                <ode/>
              </torsional>
            </friction>
            <contact>
              <ode/>
            </contact>
            <bounce/>
          </surface>
          <max_contacts>10</max_contacts>
        </collision>
        <visual name='visual'>
          <cast_shadows>0</cast_shadows>
          <geometry>
            <plane>
              <normal>0 0 1</normal>
              <size>100 100</size>
            </plane>
          </geometry>
          <material>
            <script>
              <uri>file://media/materials/scripts/gazebo.material</uri>
              <name>Gazebo/Grey</name>
            </script>
          </material>
        </visual>
        <self_collide>0</self_collide>
        <enable_wind>0</enable_wind>
        <kinematic>0</kinematic>
      </link>
    </model>
    <gravity>0 0 -9.8</gravity>
    <magnetic_field>6e-06 2.3e-05 -4.2e-05</magnetic_field>
    <atmosphere type='adiabatic'/>
    <physics type='ode'>
      <max_step_size>0.001</max_step_size>
      <real_time_factor>1</real_time_factor>
      <real_time_update_rate>1000</real_time_update_rate>
    </physics>
    <scene>
      <ambient>0.4 0.4 0.4 1</ambient>
      <background>0.7 0.7 0.7 1</background>
      <shadows>1</shadows>
    </scene>
    <audio>
      <device>default</device>
    </audio>
    <wind/>
    <spherical_coordinates>
      <surface_model>EARTH_WGS84</surface_model>
      <latitude_deg>0</latitude_deg>
      <longitude_deg>0</longitude_deg>
      <elevation>0</elevation>
      <heading_deg>0</heading_deg>
    </spherical_coordinates>
    <model name='my_bot'>
      <link name='base_link'>
        <inertial>
          <pose>0.577808 0 0.764493 0 -0 0</pose>
          <mass>55.2</mass>
          <inertia>
            <ixx>20.3322</ixx>
            <ixy>0</ixy>
            <ixz>2.45725</ixz>
            <iyy>30.5443</iyy>
            <iyz>0</iyz>
            <izz>15.6296</izz>
          </inertia>
        </inertial>
        <collision name='base_link_fixed_joint_lump__chassis_collision'>
          <pose>0.5225 0 0.85 0 -0 0</pose>
          <geometry>
            <box>
              <size>1.645 0.8 1.8</size>
            </box>
          </geometry>
          <surface>
            <contact>
              <ode/>
            </contact>
            <friction>
              <ode/>
              <torsional>
                <ode/>
              </torsional>
            </friction>
            <bounce/>
          </surface>
          <max_contacts>10</max_contacts>
        </collision>
        <collision name='base_link_fixed_joint_lump__caster_wheel_collision_1'>
          <pose>1.1 0 -0.1 0 -0 0</pose>
          <geometry>
            <sphere>
              <radius>0.1</radius>
            </sphere>
          </geometry>
          <surface>
            <contact>
              <ode/>
            </contact>
            <friction>
              <ode>
                <mu>0.15</mu>
                <mu2>0.15</mu2>
              </ode>
              <torsional>
                <ode/>
              </torsional>
            </friction>
            <bounce/>
          </surface>
          <max_contacts>10</max_contacts>
        </collision>
        <collision name='base_link_fixed_joint_lump__lidar_l_collision_2'>
          <pose>1.35 0.4 1 0 -0 0</pose>
          <geometry>
            <cylinder>
              <length>0.04</length>
              <radius>0.05</radius>
            </cylinder>
          </geometry>
          <surface>
            <contact>
              <ode/>
            </contact>
            <friction>
              <ode/>
              <torsional>
                <ode/>
              </torsional>
            </friction>
            <bounce/>
          </surface>
          <max_contacts>10</max_contacts>
        </collision>
        <collision name='base_link_fixed_joint_lump__lidar_r_collision_3'>
          <pose>1.35 -0.4 1 0 -0 0</pose>
          <geometry>
            <cylinder>
              <length>0.04</length>
              <radius>0.05</radius>
            </cylinder>
          </geometry>
          <surface>
            <contact>
              <ode/>
            </contact>
            <friction>
              <ode/>
              <torsional>
                <ode/>
              </torsional>
            </friction>
            <bounce/>
          </surface>
          <max_contacts>10</max_contacts>
        </collision>
        <visual name='base_link_fixed_joint_lump__chassis_visual'>
          <pose>0.5225 0 0.85 0 -0 0</pose>
          <geometry>
            <box>
              <size>1.645 0.8 1.8</size>
            </box>
          </geometry>
          <material>
            <script>
              <name>Gazebo/White</name>
              <uri>file://media/materials/scripts/gazebo.material</uri>
            </script>
          </material>
        </visual>
        <visual name='base_link_fixed_joint_lump__caster_wheel_visual_1'>
          <pose>1.1 0 -0.1 0 -0 0</pose>
          <geometry>
            <sphere>
              <radius>0.1</radius>
            </sphere>
          </geometry>
          <material>
            <script>
              <name>Gazebo/Black</name>
              <uri>file://media/materials/scripts/gazebo.material</uri>
            </script>
          </material>
        </visual>
        <visual name='base_link_fixed_joint_lump__lidar_l_visual_2'>
          <pose>1.35 0.4 1 0 -0 0</pose>
          <geometry>
            <cylinder>
              <length>0.04</length>
              <radius>0.05</radius>
            </cylinder>
          </geometry>
          <material>
            <script>
              <name>Gazebo/Red</name>
              <uri>file://media/materials/scripts/gazebo.material</uri>
            </script>
          </material>
        </visual>
        <visual name='base_link_fixed_joint_lump__lidar_r_visual_3'>
          <pose>1.35 -0.4 1 0 -0 0</pose>
          <geometry>
            <cylinder>
              <length>0.04</length>
              <radius>0.05</radius>
            </cylinder>
          </geometry>
          <material>
            <script>
              <name>Gazebo/Yellow</name>
              <uri>file://media/materials/scripts/gazebo.material</uri>
            </script>
          </material>
        </visual>
        <sensor name='lidar_l' type='ray'>
          <visualize>1</visualize>
          <update_rate>10</update_rate>
          <ray>
            <scan>
              <horizontal>
                <samples>360</samples>
                <min_angle>-3.14</min_angle>
                <max_angle>3.14</max_angle>
                <resolution>1</resolution>
              </horizontal>
              <vertical>
                <samples>1</samples>
                <min_angle>0</min_angle>
                <max_angle>0</max_angle>
              </vertical>
            </scan>
            <range>
              <min>0.3</min>
              <max>12</max>
            </range>
          </ray>
          <plugin name='lidar_l_controller' filename='libgazebo_ros_ray_sensor.so'>
            <ros>
              <argument>~/out:=scan</argument>
            </ros>
            <output_type>sensor_msgs/LaserScan</output_type>
            <frame_name>lidar_l</frame_name>
          </plugin>
          <pose>1.35 0.4 1 0 -0 0</pose>
        </sensor>
        <sensor name='lidar_r' type='ray'>
          <visualize>1</visualize>
          <update_rate>10</update_rate>
          <ray>
            <scan>
              <horizontal>
                <samples>360</samples>
                <min_angle>-3.14</min_angle>
                <max_angle>3.14</max_angle>
                <resolution>1</resolution>
              </horizontal>
              <vertical>
                <samples>1</samples>
                <min_angle>0</min_angle>
                <max_angle>0</max_angle>
              </vertical>
            </scan>
            <range>
              <min>0.3</min>
              <max>12</max>
            </range>
          </ray>
          <plugin name='lidar_r_controller' filename='libgazebo_ros_ray_sensor.so'>
            <ros>
              <argument>~/out:=scan</argument>
            </ros>
            <output_type>sensor_msgs/LaserScan</output_type>
            <frame_name>lidar_r</frame_name>
          </plugin>
          <pose>1.35 -0.4 1 0 -0 0</pose>
        </sensor>
        <self_collide>0</self_collide>
        <enable_wind>0</enable_wind>
        <kinematic>0</kinematic>
      </link>
      <joint name='cart_joint' type='revolute'>
        <pose relative_to='base_link'>-1.8334 0 0 0 -0 3.14159</pose>
        <parent>base_link</parent>
        <child>cart</child>
        <axis>
          <xyz>0 0 1</xyz>
          <limit>
            <lower>-1.57</lower>
            <upper>1.57</upper>
            <effort>10</effort>
            <velocity>1</velocity>
          </limit>
          <dynamics>
            <spring_reference>0</spring_reference>
            <spring_stiffness>0</spring_stiffness>
          </dynamics>
        </axis>
      </joint>
      <link name='cart'>
        <pose relative_to='cart_joint'>0 0 0 0 -0 0</pose>
        <inertial>
          <pose>0.9 0 1.11905 0 -0 0</pose>
          <mass>50.4</mass>
          <inertia>
            <ixx>16.5915</ixx>
            <ixy>1.249e-17</ixy>
            <ixz>1.42109e-14</ixz>
            <iyy>56.1932</iyy>
            <iyz>1.55299e-17</iyz>
            <izz>54.0231</izz>
          </inertia>
        </inertial>
        <collision name='cart_collision'>
          <pose>0.9 0 1.12 0 -0 0</pose>
          <geometry>
            <box>
              <size>3.315 1.3 1.5</size>
            </box>
          </geometry>
          <max_contacts>10</max_contacts>
          <surface>
            <contact>
              <ode/>
            </contact>
            <bounce/>
            <friction>
              <torsional>
                <ode/>
              </torsional>
              <ode/>
            </friction>
          </surface>
        </collision>
        <collision name='cart_fixed_joint_lump__ultrasonic_t1l1_collision_1'>
          <pose>-0.7 -0.65 1 0 0 -1.5708</pose>
          <geometry>
            <cylinder>
              <length>0.05</length>
              <radius>0.01</radius>
            </cylinder>
          </geometry>
          <surface>
            <contact>
              <ode/>
            </contact>
            <friction>
              <ode/>
              <torsional>
                <ode/>
              </torsional>
            </friction>
            <bounce/>
          </surface>
          <max_contacts>10</max_contacts>
        </collision>
        <collision name='cart_fixed_joint_lump__ultrasonic_t1l2_collision_2'>
          <pose>2.5 -0.65 1 0 0 -1.5708</pose>
          <geometry>
            <cylinder>
              <length>0.05</length>
              <radius>0.01</radius>
            </cylinder>
          </geometry>
          <surface>
            <contact>
              <ode/>
            </contact>
            <friction>
              <ode/>
              <torsional>
                <ode/>
              </torsional>
            </friction>
            <bounce/>
          </surface>
          <max_contacts>10</max_contacts>
        </collision>
        <collision name='cart_fixed_joint_lump__ultrasonic_t1r1_collision_3'>
          <pose>-0.7 0.65 1 0 -0 1.5708</pose>
          <geometry>
            <cylinder>
              <length>0.05</length>
              <radius>0.01</radius>
            </cylinder>
          </geometry>
          <surface>
            <contact>
              <ode/>
            </contact>
            <friction>
              <ode/>
              <torsional>
                <ode/>
              </torsional>
            </friction>
            <bounce/>
          </surface>
          <max_contacts>10</max_contacts>
        </collision>
        <collision name='cart_fixed_joint_lump__ultrasonic_t1r2_collision_4'>
          <pose>2.5 0.65 1 0 -0 1.5708</pose>
          <geometry>
            <cylinder>
              <length>0.05</length>
              <radius>0.01</radius>
            </cylinder>
          </geometry>
          <surface>
            <contact>
              <ode/>
            </contact>
            <friction>
              <ode/>
              <torsional>
                <ode/>
              </torsional>
            </friction>
            <bounce/>
          </surface>
          <max_contacts>10</max_contacts>
        </collision>
        <visual name='cart_visual'>
          <pose>0.9 0 0.7 0 -0 0</pose>
          <geometry>
            <box>
              <size>3.315 1.3 1.5</size>
            </box>
          </geometry>
        </visual>
        <visual name='cart_fixed_joint_lump__ultrasonic_t1l1_visual_1'>
          <pose>-0.7 -0.65 1 0 0 -1.5708</pose>
          <geometry>
            <cylinder>
              <length>0.05</length>
              <radius>0.01</radius>
            </cylinder>
          </geometry>
          <material>
            <script>
              <name>Gazebo/Green</name>
              <uri>file://media/materials/scripts/gazebo.material</uri>
            </script>
          </material>
        </visual>
        <visual name='cart_fixed_joint_lump__ultrasonic_t1l2_visual_2'>
          <pose>2.5 -0.65 1 0 0 -1.5708</pose>
          <geometry>
            <cylinder>
              <length>0.05</length>
              <radius>0.01</radius>
            </cylinder>
          </geometry>
          <material>
            <script>
              <name>Gazebo/LightGrey</name>
              <uri>file://media/materials/scripts/gazebo.material</uri>
            </script>
          </material>
        </visual>
        <visual name='cart_fixed_joint_lump__ultrasonic_t1r1_visual_3'>
          <pose>-0.7 0.65 1 0 -0 1.5708</pose>
          <geometry>
            <cylinder>
              <length>0.05</length>
              <radius>0.01</radius>
            </cylinder>
          </geometry>
          <material>
            <script>
              <name>Gazebo/Brown</name>
              <uri>file://media/materials/scripts/gazebo.material</uri>
            </script>
          </material>
        </visual>
        <visual name='cart_fixed_joint_lump__ultrasonic_t1r2_visual_4'>
          <pose>2.5 0.65 1 0 -0 1.5708</pose>
          <geometry>
            <cylinder>
              <length>0.05</length>
              <radius>0.01</radius>
            </cylinder>
          </geometry>
          <material>
            <script>
              <name>Gazebo/DarkGrey</name>
              <uri>file://media/materials/scripts/gazebo.material</uri>
            </script>
          </material>
        </visual>
        <sensor name='ultrasonic_t1l1' type='ray'>
          <visualize>1</visualize>
          <update_rate>10</update_rate>
          <ray>
            <scan>
              <horizontal>
                <samples>15</samples>
                <min_angle>-0.4363</min_angle>
                <max_angle>0.4363</max_angle>
                <resolution>1</resolution>
              </horizontal>
              <vertical>
                <samples>1</samples>
                <min_angle>0</min_angle>
                <max_angle>0</max_angle>
              </vertical>
            </scan>
            <range>
              <min>0.3</min>
              <max>3.6</max>
            </range>
          </ray>
          <plugin name='ultrasonic_t1l1_controller' filename='libgazebo_ros_ray_sensor.so'>
            <ros>
              <argument>~/out:=scan</argument>
            </ros>
            <output_type>sensor_msgs/LaserScan</output_type>
            <frame_name>ultrasonic_t1l1</frame_name>
          </plugin>
          <pose>-0.7 -0.65 1 0 0 -1.5708</pose>
        </sensor>
        <sensor name='ultrasonic_t1l2' type='ray'>
          <visualize>1</visualize>
          <update_rate>10</update_rate>
          <ray>
            <scan>
              <horizontal>
                <samples>15</samples>
                <min_angle>-0.4363</min_angle>
                <max_angle>0.4363</max_angle>
                <resolution>1</resolution>
              </horizontal>
              <vertical>
                <samples>1</samples>
                <min_angle>0</min_angle>
                <max_angle>0</max_angle>
              </vertical>
            </scan>
            <range>
              <min>0.3</min>
              <max>3.6</max>
            </range>
          </ray>
          <plugin name='ultrasonic_t1l2_controller' filename='libgazebo_ros_ray_sensor.so'>
            <ros>
              <argument>~/out:=scan</argument>
            </ros>
            <output_type>sensor_msgs/LaserScan</output_type>
            <frame_name>ultrasonic_t1l2</frame_name>
          </plugin>
          <pose>2.5 -0.65 1 0 0 -1.5708</pose>
        </sensor>
        <sensor name='ultrasonic_t1r1' type='ray'>
          <visualize>1</visualize>
          <update_rate>10</update_rate>
          <ray>
            <scan>
              <horizontal>
                <samples>15</samples>
                <min_angle>-0.4363</min_angle>
                <max_angle>0.4363</max_angle>
                <resolution>1</resolution>
              </horizontal>
              <vertical>
                <samples>1</samples>
                <min_angle>0</min_angle>
                <max_angle>0</max_angle>
              </vertical>
            </scan>
            <range>
              <min>0.3</min>
              <max>3.6</max>
            </range>
          </ray>
          <plugin name='ultrasonic_t1r1_controller' filename='libgazebo_ros_ray_sensor.so'>
            <ros>
              <argument>~/out:=scan</argument>
            </ros>
            <output_type>sensor_msgs/LaserScan</output_type>
            <frame_name>ultrasonic_t1r1</frame_name>
          </plugin>
          <pose>-0.7 0.65 1 0 -0 1.5708</pose>
        </sensor>
        <sensor name='ultrasonic_t1r2' type='ray'>
          <visualize>1</visualize>
          <update_rate>10</update_rate>
          <ray>
            <scan>
              <horizontal>
                <samples>15</samples>
                <min_angle>-0.4363</min_angle>
                <max_angle>0.4363</max_angle>
                <resolution>1</resolution>
              </horizontal>
              <vertical>
                <samples>1</samples>
                <min_angle>0</min_angle>
                <max_angle>0</max_angle>
              </vertical>
            </scan>
            <range>
              <min>0.3</min>
              <max>3.6</max>
            </range>
          </ray>
          <plugin name='ultrasonic_t1r2_controller' filename='libgazebo_ros_ray_sensor.so'>
            <ros>
              <argument>~/out:=scan</argument>
            </ros>
            <output_type>sensor_msgs/LaserScan</output_type>
            <frame_name>ultrasonic_t1r2</frame_name>
          </plugin>
          <pose>2.5 0.65 1 0 -0 1.5708</pose>
        </sensor>
        <self_collide>0</self_collide>
        <enable_wind>0</enable_wind>
        <kinematic>0</kinematic>
      </link>
      <joint name='cart2_joint' type='revolute'>
        <pose relative_to='cart'>3.2334 0 0 0 -0 0</pose>
        <parent>cart</parent>
        <child>cart2</child>
        <axis>
          <xyz>0 0 1</xyz>
          <limit>
            <lower>-1.57</lower>
            <upper>1.57</upper>
            <effort>10</effort>
            <velocity>1</velocity>
          </limit>
          <dynamics>
            <spring_reference>0</spring_reference>
            <spring_stiffness>0</spring_stiffness>
          </dynamics>
        </axis>
      </joint>
      <link name='cart2'>
        <pose relative_to='cart2_joint'>0 0 0 0 -0 0</pose>
        <inertial>
          <pose>0.9 -0 1.11765 0 -0 0</pose>
          <mass>20.4</mass>
          <inertia>
            <ixx>5.93024</ixx>
            <ixy>-2.63678e-17</ixy>
            <ixz>0</ixz>
            <iyy>9.41174</iyy>
            <iyz>-1.55105e-17</iyz>
            <izz>7.83052</izz>
          </inertia>
        </inertial>
        <collision name='cart2_collision'>
          <pose>0.9 0 1.12 0 -0 0</pose>
          <geometry>
            <box>
              <size>1.8 1.11 1.5</size>
            </box>
          </geometry>
          <max_contacts>10</max_contacts>
          <surface>
            <contact>
              <ode/>
            </contact>
            <bounce/>
            <friction>
              <torsional>
                <ode/>
              </torsional>
              <ode/>
            </friction>
          </surface>
        </collision>
        <collision name='cart2_fixed_joint_lump__ultrasonic_t2l1_collision_1'>
          <pose>0.1 -0.55 1 0 0 -1.5708</pose>
          <geometry>
            <cylinder>
              <length>0.05</length>
              <radius>0.01</radius>
            </cylinder>
          </geometry>
          <surface>
            <contact>
              <ode/>
            </contact>
            <friction>
              <ode/>
              <torsional>
                <ode/>
              </torsional>
            </friction>
            <bounce/>
          </surface>
          <max_contacts>10</max_contacts>
        </collision>
        <collision name='cart2_fixed_joint_lump__ultrasonic_t2l2_collision_2'>
          <pose>1.7 -0.55 1 0 0 -1.5708</pose>
          <geometry>
            <cylinder>
              <length>0.05</length>
              <radius>0.01</radius>
            </cylinder>
          </geometry>
          <surface>
            <contact>
              <ode/>
            </contact>
            <friction>
              <ode/>
              <torsional>
                <ode/>
              </torsional>
            </friction>
            <bounce/>
          </surface>
          <max_contacts>10</max_contacts>
        </collision>
        <collision name='cart2_fixed_joint_lump__ultrasonic_t2r1_collision_3'>
          <pose>0.1 0.55 1 0 -0 1.5708</pose>
          <geometry>
            <cylinder>
              <length>0.05</length>
              <radius>0.01</radius>
            </cylinder>
          </geometry>
          <surface>
            <contact>
              <ode/>
            </contact>
            <friction>
              <ode/>
              <torsional>
                <ode/>
              </torsional>
            </friction>
            <bounce/>
          </surface>
          <max_contacts>10</max_contacts>
        </collision>
        <collision name='cart2_fixed_joint_lump__ultrasonic_t2r2_collision_4'>
          <pose>1.7 0.55 1 0 -0 1.5708</pose>
          <geometry>
            <cylinder>
              <length>0.05</length>
              <radius>0.01</radius>
            </cylinder>
          </geometry>
          <surface>
            <contact>
              <ode/>
            </contact>
            <friction>
              <ode/>
              <torsional>
                <ode/>
              </torsional>
            </friction>
            <bounce/>
          </surface>
          <max_contacts>10</max_contacts>
        </collision>
        <visual name='cart2_visual'>
          <pose>0.9 0 0.7 0 -0 0</pose>
          <geometry>
            <box>
              <size>1.8 1.11 1.5</size>
            </box>
          </geometry>
        </visual>
        <visual name='cart2_fixed_joint_lump__ultrasonic_t2l1_visual_1'>
          <pose>0.1 -0.55 1 0 0 -1.5708</pose>
          <geometry>
            <cylinder>
              <length>0.05</length>
              <radius>0.01</radius>
            </cylinder>
          </geometry>
          <material>
            <script>
              <name>ambient</name>
              <uri>file://media/materials/scripts/gazebo.material</uri>
            </script>
          </material>
        </visual>
        <visual name='cart2_fixed_joint_lump__ultrasonic_t2l2_visual_2'>
          <pose>1.7 -0.55 1 0 0 -1.5708</pose>
          <geometry>
            <cylinder>
              <length>0.05</length>
              <radius>0.01</radius>
            </cylinder>
          </geometry>
          <material>
            <script>
              <name>ambient</name>
              <uri>file://media/materials/scripts/gazebo.material</uri>
            </script>
          </material>
        </visual>
        <visual name='cart2_fixed_joint_lump__ultrasonic_t2r1_visual_3'>
          <pose>0.1 0.55 1 0 -0 1.5708</pose>
          <geometry>
            <cylinder>
              <length>0.05</length>
              <radius>0.01</radius>
            </cylinder>
          </geometry>
          <material>
            <script>
              <name>ambient</name>
              <uri>file://media/materials/scripts/gazebo.material</uri>
            </script>
          </material>
        </visual>
        <visual name='cart2_fixed_joint_lump__ultrasonic_t2r2_visual_4'>
          <pose>1.7 0.55 1 0 -0 1.5708</pose>
          <geometry>
            <cylinder>
              <length>0.05</length>
              <radius>0.01</radius>
            </cylinder>
          </geometry>
          <material>
            <script>
              <name>ambient</name>
              <uri>file://media/materials/scripts/gazebo.material</uri>
            </script>
          </material>
        </visual>
        <sensor name='ultrasonic_t2l1' type='ray'>
          <visualize>1</visualize>
          <update_rate>10</update_rate>
          <ray>
            <scan>
              <horizontal>
                <samples>15</samples>
                <min_angle>-0.4363</min_angle>
                <max_angle>0.4363</max_angle>
                <resolution>1</resolution>
              </horizontal>
              <vertical>
                <samples>1</samples>
                <min_angle>0</min_angle>
                <max_angle>0</max_angle>
              </vertical>
            </scan>
            <range>
              <min>0.3</min>
              <max>3.6</max>
            </range>
          </ray>
          <plugin name='ultrasonic_t2l1_controller' filename='libgazebo_ros_ray_sensor.so'>
            <ros>
              <argument>~/out:=scan</argument>
            </ros>
            <output_type>sensor_msgs/LaserScan</output_type>
            <frame_name>ultrasonic_t2l1</frame_name>
          </plugin>
          <pose>0.1 -0.55 1 0 0 -1.5708</pose>
        </sensor>
        <sensor name='ultrasonic_t2l2' type='ray'>
          <visualize>1</visualize>
          <update_rate>10</update_rate>
          <ray>
            <scan>
              <horizontal>
                <samples>15</samples>
                <min_angle>-0.4363</min_angle>
                <max_angle>0.4363</max_angle>
                <resolution>1</resolution>
              </horizontal>
              <vertical>
                <samples>1</samples>
                <min_angle>0</min_angle>
                <max_angle>0</max_angle>
              </vertical>
            </scan>
            <range>
              <min>0.3</min>
              <max>3.6</max>
            </range>
          </ray>
          <plugin name='ultrasonic_t2l2_controller' filename='libgazebo_ros_ray_sensor.so'>
            <ros>
              <argument>~/out:=scan</argument>
            </ros>
            <output_type>sensor_msgs/LaserScan</output_type>
            <frame_name>ultrasonic_t2l2</frame_name>
          </plugin>
          <pose>1.7 -0.55 1 0 0 -1.5708</pose>
        </sensor>
        <sensor name='ultrasonic_t2r1' type='ray'>
          <visualize>1</visualize>
          <update_rate>10</update_rate>
          <ray>
            <scan>
              <horizontal>
                <samples>15</samples>
                <min_angle>-0.4363</min_angle>
                <max_angle>0.4363</max_angle>
                <resolution>1</resolution>
              </horizontal>
              <vertical>
                <samples>1</samples>
                <min_angle>0</min_angle>
                <max_angle>0</max_angle>
              </vertical>
            </scan>
            <range>
              <min>0.3</min>
              <max>3.6</max>
            </range>
          </ray>
          <plugin name='ultrasonic_t2r1_controller' filename='libgazebo_ros_ray_sensor.so'>
            <ros>
              <argument>~/out:=scan</argument>
            </ros>
            <output_type>sensor_msgs/LaserScan</output_type>
            <frame_name>ultrasonic_t2r1</frame_name>
          </plugin>
          <pose>0.1 0.55 1 0 -0 1.5708</pose>
        </sensor>
        <sensor name='ultrasonic_t2r2' type='ray'>
          <visualize>1</visualize>
          <update_rate>10</update_rate>
          <ray>
            <scan>
              <horizontal>
                <samples>15</samples>
                <min_angle>-0.4363</min_angle>
                <max_angle>0.4363</max_angle>
                <resolution>1</resolution>
              </horizontal>
              <vertical>
                <samples>1</samples>
                <min_angle>0</min_angle>
                <max_angle>0</max_angle>
              </vertical>
            </scan>
            <range>
              <min>0.3</min>
              <max>3.6</max>
            </range>
          </ray>
          <plugin name='ultrasonic_t2r2_controller' filename='libgazebo_ros_ray_sensor.so'>
            <ros>
              <argument>~/out:=scan</argument>
            </ros>
            <output_type>sensor_msgs/LaserScan</output_type>
            <frame_name>ultrasonic_t2r2</frame_name>
          </plugin>
          <pose>1.7 0.55 1 0 -0 1.5708</pose>
        </sensor>
        <self_collide>0</self_collide>
        <enable_wind>0</enable_wind>
        <kinematic>0</kinematic>
      </link>
      <joint name='cart2_left_wheel_joint' type='revolute'>
        <pose relative_to='cart2'>1.6 0.55 0 -1.5708 0 0</pose>
        <parent>cart2</parent>
        <child>cart2_left_wheel</child>
        <axis>
          <xyz>0 0 1</xyz>
          <limit>
            <lower>-1e+16</lower>
            <upper>1e+16</upper>
          </limit>
          <dynamics>
            <spring_reference>0</spring_reference>
            <spring_stiffness>0</spring_stiffness>
          </dynamics>
        </axis>
      </joint>
      <link name='cart2_left_wheel'>
        <pose relative_to='cart2_left_wheel_joint'>0 0 0 0 -0 0</pose>
        <inertial>
          <pose>0 0 0 0 -0 0</pose>
          <mass>5</mass>
          <inertia>
            <ixx>0.0447917</ixx>
            <ixy>0</ixy>
            <ixz>0</ixz>
            <iyy>0.0447917</iyy>
            <iyz>0</iyz>
            <izz>0.05625</izz>
          </inertia>
        </inertial>
        <collision name='cart2_left_wheel_collision'>
          <pose>0 0 0 0 -0 0</pose>
          <geometry>
            <cylinder>
              <length>0.2</length>
              <radius>0.15</radius>
            </cylinder>
          </geometry>
          <surface>
            <contact>
              <ode/>
            </contact>
            <friction>
              <ode/>
              <torsional>
                <ode/>
              </torsional>
            </friction>
            <bounce/>
          </surface>
          <max_contacts>10</max_contacts>
        </collision>
        <visual name='cart2_left_wheel_visual'>
          <pose>0 0 0 0 -0 0</pose>
          <geometry>
            <cylinder>
              <length>0.2</length>
              <radius>0.15</radius>
            </cylinder>
          </geometry>
          <material>
            <script>
              <name>Gazebo/Blue</name>
              <uri>file://media/materials/scripts/gazebo.material</uri>
            </script>
          </material>
        </visual>
        <self_collide>0</self_collide>
        <enable_wind>0</enable_wind>
        <kinematic>0</kinematic>
      </link>
      <joint name='cart2_right_wheel_joint' type='revolute'>
        <pose relative_to='cart2'>1.6 -0.55 0 1.5708 -0 0</pose>
        <parent>cart2</parent>
        <child>cart2_right_wheel</child>
        <axis>
          <xyz>0 0 -1</xyz>
          <limit>
            <lower>-1e+16</lower>
            <upper>1e+16</upper>
          </limit>
          <dynamics>
            <spring_reference>0</spring_reference>
            <spring_stiffness>0</spring_stiffness>
          </dynamics>
        </axis>
      </joint>
      <link name='cart2_right_wheel'>
        <pose relative_to='cart2_right_wheel_joint'>0 0 0 0 -0 0</pose>
        <inertial>
          <pose>0 0 0 0 -0 0</pose>
          <mass>5</mass>
          <inertia>
            <ixx>0.0447917</ixx>
            <ixy>0</ixy>
            <ixz>0</ixz>
            <iyy>0.0447917</iyy>
            <iyz>0</iyz>
            <izz>0.05625</izz>
          </inertia>
        </inertial>
        <collision name='cart2_right_wheel_collision'>
          <pose>0 0 0 0 -0 0</pose>
          <geometry>
            <cylinder>
              <length>0.2</length>
              <radius>0.15</radius>
            </cylinder>
          </geometry>
          <surface>
            <contact>
              <ode/>
            </contact>
            <friction>
              <ode/>
              <torsional>
                <ode/>
              </torsional>
            </friction>
            <bounce/>
          </surface>
          <max_contacts>10</max_contacts>
        </collision>
        <visual name='cart2_right_wheel_visual'>
          <pose>0 0 0 0 -0 0</pose>
          <geometry>
            <cylinder>
              <length>0.2</length>
              <radius>0.15</radius>
            </cylinder>
          </geometry>
          <material>
            <script>
              <name>Gazebo/Blue</name>
              <uri>file://media/materials/scripts/gazebo.material</uri>
            </script>
          </material>
        </visual>
        <self_collide>0</self_collide>
        <enable_wind>0</enable_wind>
        <kinematic>0</kinematic>
      </link>
      <joint name='cart3_joint' type='revolute'>
        <pose relative_to='cart2'>2.7334 0 0 0 -0 0</pose>
        <parent>cart2</parent>
        <child>cart3</child>
        <axis>
          <xyz>0 0 1</xyz>
          <limit>
            <lower>-1.57</lower>
            <upper>1.57</upper>
            <effort>10</effort>
            <velocity>1</velocity>
          </limit>
          <dynamics>
            <spring_reference>0</spring_reference>
            <spring_stiffness>0</spring_stiffness>
          </dynamics>
        </axis>
      </joint>
      <link name='cart3'>
        <pose relative_to='cart3_joint'>0 0 0 0 -0 0</pose>
        <inertial>
          <pose>0.899755 0 1.11765 0 -0 0</pose>
          <mass>20.4</mass>
          <inertia>
            <ixx>4.78888</ixx>
            <ixy>1.38778e-17</ixy>
            <ixz>-0.000588235</ixz>
            <iyy>10.957</iyy>
            <iyz>0</iyz>
            <izz>8.23445</izz>
          </inertia>
        </inertial>
        <collision name='cart3_collision'>
          <pose>0.9 0 1.12 0 -0 0</pose>
          <geometry>
            <box>
              <size>2.03 0.765 1.5</size>
            </box>
          </geometry>
          <max_contacts>10</max_contacts>
          <surface>
            <contact>
              <ode/>
            </contact>
            <bounce/>
            <friction>
              <torsional>
                <ode/>
              </torsional>
              <ode/>
            </friction>
          </surface>
        </collision>
        <collision name='cart3_fixed_joint_lump__ultrasonic_t3l1_collision_1'>
          <pose>-0.025 -0.38 1 0 0 -1.5708</pose>
          <geometry>
            <cylinder>
              <length>0.05</length>
              <radius>0.01</radius>
            </cylinder>
          </geometry>
          <surface>
            <contact>
              <ode/>
            </contact>
            <friction>
              <ode/>
              <torsional>
                <ode/>
              </torsional>
            </friction>
            <bounce/>
          </surface>
          <max_contacts>10</max_contacts>
        </collision>
        <collision name='cart3_fixed_joint_lump__ultrasonic_t3l2_collision_2'>
          <pose>1.8 -0.38 1 0 0 -1.5708</pose>
          <geometry>
            <cylinder>
              <length>0.05</length>
              <radius>0.01</radius>
            </cylinder>
          </geometry>
          <surface>
            <contact>
              <ode/>
            </contact>
            <friction>
              <ode/>
              <torsional>
                <ode/>
              </torsional>
            </friction>
            <bounce/>
          </surface>
          <max_contacts>10</max_contacts>
        </collision>
        <collision name='cart3_fixed_joint_lump__ultrasonic_t3r1_collision_3'>
          <pose>-0.025 0.38 1 0 -0 1.5708</pose>
          <geometry>
            <cylinder>
              <length>0.05</length>
              <radius>0.01</radius>
            </cylinder>
          </geometry>
          <surface>
            <contact>
              <ode/>
            </contact>
            <friction>
              <ode/>
              <torsional>
                <ode/>
              </torsional>
            </friction>
            <bounce/>
          </surface>
          <max_contacts>10</max_contacts>
        </collision>
        <collision name='cart3_fixed_joint_lump__ultrasonic_t3r2_collision_4'>
          <pose>1.8 0.38 1 0 -0 1.5708</pose>
          <geometry>
            <cylinder>
              <length>0.05</length>
              <radius>0.01</radius>
            </cylinder>
          </geometry>
          <surface>
            <contact>
              <ode/>
            </contact>
            <friction>
              <ode/>
              <torsional>
                <ode/>
              </torsional>
            </friction>
            <bounce/>
          </surface>
          <max_contacts>10</max_contacts>
        </collision>
        <visual name='cart3_visual'>
          <pose>0.9 0 0.7 0 -0 0</pose>
          <geometry>
            <box>
              <size>2.03 0.765 1.5</size>
            </box>
          </geometry>
        </visual>
        <visual name='cart3_fixed_joint_lump__ultrasonic_t3l1_visual_1'>
          <pose>-0.025 -0.38 1 0 0 -1.5708</pose>
          <geometry>
            <cylinder>
              <length>0.05</length>
              <radius>0.01</radius>
            </cylinder>
          </geometry>
          <material>
            <script>
              <name>ambient</name>
              <uri>file://media/materials/scripts/gazebo.material</uri>
            </script>
          </material>
        </visual>
        <visual name='cart3_fixed_joint_lump__ultrasonic_t3l2_visual_2'>
          <pose>1.8 -0.38 1 0 0 -1.5708</pose>
          <geometry>
            <cylinder>
              <length>0.05</length>
              <radius>0.01</radius>
            </cylinder>
          </geometry>
          <material>
            <script>
              <name>ambient</name>
              <uri>file://media/materials/scripts/gazebo.material</uri>
            </script>
          </material>
        </visual>
        <visual name='cart3_fixed_joint_lump__ultrasonic_t3r1_visual_3'>
          <pose>-0.025 0.38 1 0 -0 1.5708</pose>
          <geometry>
            <cylinder>
              <length>0.05</length>
              <radius>0.01</radius>
            </cylinder>
          </geometry>
          <material>
            <script>
              <name>ambient</name>
              <uri>file://media/materials/scripts/gazebo.material</uri>
            </script>
          </material>
        </visual>
        <visual name='cart3_fixed_joint_lump__ultrasonic_t3r2_visual_4'>
          <pose>1.8 0.38 1 0 -0 1.5708</pose>
          <geometry>
            <cylinder>
              <length>0.05</length>
              <radius>0.01</radius>
            </cylinder>
          </geometry>
          <material>
            <script>
              <name>ambient</name>
              <uri>file://media/materials/scripts/gazebo.material</uri>
            </script>
          </material>
        </visual>
        <sensor name='ultrasonic_t3l1' type='ray'>
          <visualize>1</visualize>
          <update_rate>10</update_rate>
          <ray>
            <scan>
              <horizontal>
                <samples>15</samples>
                <min_angle>-0.4363</min_angle>
                <max_angle>0.4363</max_angle>
                <resolution>1</resolution>
              </horizontal>
              <vertical>
                <samples>1</samples>
                <min_angle>0</min_angle>
                <max_angle>0</max_angle>
              </vertical>
            </scan>
            <range>
              <min>0.3</min>
              <max>3.6</max>
            </range>
          </ray>
          <plugin name='ultrasonic_t3l1_controller' filename='libgazebo_ros_ray_sensor.so'>
            <ros>
              <argument>~/out:=scan</argument>
            </ros>
            <output_type>sensor_msgs/LaserScan</output_type>
            <frame_name>ultrasonic_t3l1</frame_name>
          </plugin>
          <pose>-0.025 -0.38 1 0 0 -1.5708</pose>
        </sensor>
        <sensor name='ultrasonic_t3l2' type='ray'>
          <visualize>1</visualize>
          <update_rate>10</update_rate>
          <ray>
            <scan>
              <horizontal>
                <samples>15</samples>
                <min_angle>-0.4363</min_angle>
                <max_angle>0.4363</max_angle>
                <resolution>1</resolution>
              </horizontal>
              <vertical>
                <samples>1</samples>
                <min_angle>0</min_angle>
                <max_angle>0</max_angle>
              </vertical>
            </scan>
            <range>
              <min>0.3</min>
              <max>3.6</max>
            </range>
          </ray>
          <plugin name='ultrasonic_t3l2_controller' filename='libgazebo_ros_ray_sensor.so'>
            <ros>
              <argument>~/out:=scan</argument>
            </ros>
            <output_type>sensor_msgs/LaserScan</output_type>
            <frame_name>ultrasonic_t3l2</frame_name>
          </plugin>
          <pose>1.8 -0.38 1 0 0 -1.5708</pose>
        </sensor>
        <sensor name='ultrasonic_t3r1' type='ray'>
          <visualize>1</visualize>
          <update_rate>10</update_rate>
          <ray>
            <scan>
              <horizontal>
                <samples>15</samples>
                <min_angle>-0.4363</min_angle>
                <max_angle>0.4363</max_angle>
                <resolution>1</resolution>
              </horizontal>
              <vertical>
                <samples>1</samples>
                <min_angle>0</min_angle>
                <max_angle>0</max_angle>
              </vertical>
            </scan>
            <range>
              <min>0.3</min>
              <max>3.6</max>
            </range>
          </ray>
          <plugin name='ultrasonic_t3r1_controller' filename='libgazebo_ros_ray_sensor.so'>
            <ros>
              <argument>~/out:=scan</argument>
            </ros>
            <output_type>sensor_msgs/LaserScan</output_type>
            <frame_name>ultrasonic_t3r1</frame_name>
          </plugin>
          <pose>-0.025 0.38 1 0 -0 1.5708</pose>
        </sensor>
        <sensor name='ultrasonic_t3r2' type='ray'>
          <visualize>1</visualize>
          <update_rate>10</update_rate>
          <ray>
            <scan>
              <horizontal>
                <samples>15</samples>
                <min_angle>-0.4363</min_angle>
                <max_angle>0.4363</max_angle>
                <resolution>1</resolution>
              </horizontal>
              <vertical>
                <samples>1</samples>
                <min_angle>0</min_angle>
                <max_angle>0</max_angle>
              </vertical>
            </scan>
            <range>
              <min>0.3</min>
              <max>3.6</max>
            </range>
          </ray>
          <plugin name='ultrasonic_t3r2_controller' filename='libgazebo_ros_ray_sensor.so'>
            <ros>
              <argument>~/out:=scan</argument>
            </ros>
            <output_type>sensor_msgs/LaserScan</output_type>
            <frame_name>ultrasonic_t3r2</frame_name>
          </plugin>
          <pose>1.8 0.38 1 0 -0 1.5708</pose>
        </sensor>
        <self_collide>0</self_collide>
        <enable_wind>0</enable_wind>
        <kinematic>0</kinematic>
      </link>
      <joint name='cart3_left_wheel_joint' type='revolute'>
        <pose relative_to='cart3'>1.6 0.55 0 -1.5708 0 0</pose>
        <parent>cart3</parent>
        <child>cart3_left_wheel</child>
        <axis>
          <xyz>0 0 1</xyz>
          <limit>
            <lower>-1e+16</lower>
            <upper>1e+16</upper>
          </limit>
          <dynamics>
            <spring_reference>0</spring_reference>
            <spring_stiffness>0</spring_stiffness>
          </dynamics>
        </axis>
      </joint>
      <link name='cart3_left_wheel'>
        <pose relative_to='cart3_left_wheel_joint'>0 0 0 0 -0 0</pose>
        <inertial>
          <pose>0 0 0 0 -0 0</pose>
          <mass>5</mass>
          <inertia>
            <ixx>0.0447917</ixx>
            <ixy>0</ixy>
            <ixz>0</ixz>
            <iyy>0.0447917</iyy>
            <iyz>0</iyz>
            <izz>0.05625</izz>
          </inertia>
        </inertial>
        <collision name='cart3_left_wheel_collision'>
          <pose>0 0 0 0 -0 0</pose>
          <geometry>
            <cylinder>
              <length>0.2</length>
              <radius>0.15</radius>
            </cylinder>
          </geometry>
          <surface>
            <contact>
              <ode/>
            </contact>
            <friction>
              <ode/>
              <torsional>
                <ode/>
              </torsional>
            </friction>
            <bounce/>
          </surface>
          <max_contacts>10</max_contacts>
        </collision>
        <visual name='cart3_left_wheel_visual'>
          <pose>0 0 0 0 -0 0</pose>
          <geometry>
            <cylinder>
              <length>0.2</length>
              <radius>0.15</radius>
            </cylinder>
          </geometry>
          <material>
            <script>
              <name>Gazebo/Blue</name>
              <uri>file://media/materials/scripts/gazebo.material</uri>
            </script>
          </material>
        </visual>
        <self_collide>0</self_collide>
        <enable_wind>0</enable_wind>
        <kinematic>0</kinematic>
      </link>
      <joint name='cart3_right_wheel_joint' type='revolute'>
        <pose relative_to='cart3'>1.6 -0.55 0 1.5708 -0 0</pose>
        <parent>cart3</parent>
        <child>cart3_right_wheel</child>
        <axis>
          <xyz>0 0 -1</xyz>
          <limit>
            <lower>-1e+16</lower>
            <upper>1e+16</upper>
          </limit>
          <dynamics>
            <spring_reference>0</spring_reference>
            <spring_stiffness>0</spring_stiffness>
          </dynamics>
        </axis>
      </joint>
      <link name='cart3_right_wheel'>
        <pose relative_to='cart3_right_wheel_joint'>0 0 0 0 -0 0</pose>
        <inertial>
          <pose>0 0 0 0 -0 0</pose>
          <mass>5</mass>
          <inertia>
            <ixx>0.0447917</ixx>
            <ixy>0</ixy>
            <ixz>0</ixz>
            <iyy>0.0447917</iyy>
            <iyz>0</iyz>
            <izz>0.05625</izz>
          </inertia>
        </inertial>
        <collision name='cart3_right_wheel_collision'>
          <pose>0 0 0 0 -0 0</pose>
          <geometry>
            <cylinder>
              <length>0.2</length>
              <radius>0.15</radius>
            </cylinder>
          </geometry>
          <surface>
            <contact>
              <ode/>
            </contact>
            <friction>
              <ode/>
              <torsional>
                <ode/>
              </torsional>
            </friction>
            <bounce/>
          </surface>
          <max_contacts>10</max_contacts>
        </collision>
        <visual name='cart3_right_wheel_visual'>
          <pose>0 0 0 0 -0 0</pose>
          <geometry>
            <cylinder>
              <length>0.2</length>
              <radius>0.15</radius>
            </cylinder>
          </geometry>
          <material>
            <script>
              <name>Gazebo/Blue</name>
              <uri>file://media/materials/scripts/gazebo.material</uri>
            </script>
          </material>
        </visual>
        <self_collide>0</self_collide>
        <enable_wind>0</enable_wind>
        <kinematic>0</kinematic>
      </link>
      <joint name='cart_left_wheel_joint' type='revolute'>
        <pose relative_to='cart'>2.2 0.6 0 -1.5708 0 0</pose>
        <parent>cart</parent>
        <child>cart_left_wheel</child>
        <axis>
          <xyz>0 0 1</xyz>
          <limit>
            <lower>-1e+16</lower>
            <upper>1e+16</upper>
          </limit>
          <dynamics>
            <spring_reference>0</spring_reference>
            <spring_stiffness>0</spring_stiffness>
          </dynamics>
        </axis>
      </joint>
      <link name='cart_left_wheel'>
        <pose relative_to='cart_left_wheel_joint'>0 0 0 0 -0 0</pose>
        <inertial>
          <pose>0 0 0 0 -0 0</pose>
          <mass>5</mass>
          <inertia>
            <ixx>0.0447917</ixx>
            <ixy>0</ixy>
            <ixz>0</ixz>
            <iyy>0.0447917</iyy>
            <iyz>0</iyz>
            <izz>0.05625</izz>
          </inertia>
        </inertial>
        <collision name='cart_left_wheel_collision'>
          <pose>0 0 0 0 -0 0</pose>
          <geometry>
            <cylinder>
              <length>0.2</length>
              <radius>0.15</radius>
            </cylinder>
          </geometry>
          <surface>
            <contact>
              <ode/>
            </contact>
            <friction>
              <ode/>
              <torsional>
                <ode/>
              </torsional>
            </friction>
            <bounce/>
          </surface>
          <max_contacts>10</max_contacts>
        </collision>
        <visual name='cart_left_wheel_visual'>
          <pose>0 0 0 0 -0 0</pose>
          <geometry>
            <cylinder>
              <length>0.2</length>
              <radius>0.15</radius>
            </cylinder>
          </geometry>
          <material>
            <script>
              <name>Gazebo/Blue</name>
              <uri>file://media/materials/scripts/gazebo.material</uri>
            </script>
          </material>
        </visual>
        <self_collide>0</self_collide>
        <enable_wind>0</enable_wind>
        <kinematic>0</kinematic>
      </link>
      <joint name='cart_right_wheel_joint' type='revolute'>
        <pose relative_to='cart'>2.2 -0.6 0 1.5708 -0 0</pose>
        <parent>cart</parent>
        <child>cart_right_wheel</child>
        <axis>
          <xyz>0 0 -1</xyz>
          <limit>
            <lower>-1e+16</lower>
            <upper>1e+16</upper>
          </limit>
          <dynamics>
            <spring_reference>0</spring_reference>
            <spring_stiffness>0</spring_stiffness>
          </dynamics>
        </axis>
      </joint>
      <link name='cart_right_wheel'>
        <pose relative_to='cart_right_wheel_joint'>0 0 0 0 -0 0</pose>
        <inertial>
          <pose>0 0 0 0 -0 0</pose>
          <mass>5</mass>
          <inertia>
            <ixx>0.0447917</ixx>
            <ixy>0</ixy>
            <ixz>0</ixz>
            <iyy>0.0447917</iyy>
            <iyz>0</iyz>
            <izz>0.05625</izz>
          </inertia>
        </inertial>
        <collision name='cart_right_wheel_collision'>
          <pose>0 0 0 0 -0 0</pose>
          <geometry>
            <cylinder>
              <length>0.2</length>
              <radius>0.15</radius>
            </cylinder>
          </geometry>
          <surface>
            <contact>
              <ode/>
            </contact>
            <friction>
              <ode/>
              <torsional>
                <ode/>
              </torsional>
            </friction>
            <bounce/>
          </surface>
          <max_contacts>10</max_contacts>
        </collision>
        <visual name='cart_right_wheel_visual'>
          <pose>0 0 0 0 -0 0</pose>
          <geometry>
            <cylinder>
              <length>0.2</length>
              <radius>0.15</radius>
            </cylinder>
          </geometry>
          <material>
            <script>
              <name>Gazebo/Blue</name>
              <uri>file://media/materials/scripts/gazebo.material</uri>
            </script>
          </material>
        </visual>
        <self_collide>0</self_collide>
        <enable_wind>0</enable_wind>
        <kinematic>0</kinematic>
      </link>
      <joint name='left_wheel_joint' type='revolute'>
        <pose relative_to='base_link'>0 0.4 0 -1.5708 0 0</pose>
        <parent>base_link</parent>
        <child>left_wheel</child>
        <axis>
          <xyz>0 0 1</xyz>
          <limit>
            <lower>-1e+16</lower>
            <upper>1e+16</upper>
          </limit>
          <dynamics>
            <spring_reference>0</spring_reference>
            <spring_stiffness>0</spring_stiffness>
          </dynamics>
        </axis>
      </joint>
      <link name='left_wheel'>
        <pose relative_to='left_wheel_joint'>0 0 0 0 -0 0</pose>
        <inertial>
          <pose>0 0 0 0 -0 0</pose>
          <mass>5</mass>
          <inertia>
            <ixx>0.0541667</ixx>
            <ixy>0</ixy>
            <ixz>0</ixz>
            <iyy>0.0541667</iyy>
            <iyz>0</iyz>
            <izz>0.1</izz>
          </inertia>
        </inertial>
        <collision name='left_wheel_collision'>
          <pose>0 0 0 0 -0 0</pose>
          <geometry>
            <cylinder>
              <length>0.1</length>
              <radius>0.2</radius>
            </cylinder>
          </geometry>
          <surface>
            <contact>
              <ode/>
            </contact>
            <friction>
              <ode/>
              <torsional>
                <ode/>
              </torsional>
            </friction>
            <bounce/>
          </surface>
          <max_contacts>10</max_contacts>
        </collision>
        <visual name='left_wheel_visual'>
          <pose>0 0 0 0 -0 0</pose>
          <geometry>
            <cylinder>
              <length>0.1</length>
              <radius>0.2</radius>
            </cylinder>
          </geometry>
          <material>
            <script>
              <name>Gazebo/Blue</name>
              <uri>file://media/materials/scripts/gazebo.material</uri>
            </script>
          </material>
        </visual>
        <self_collide>0</self_collide>
        <enable_wind>0</enable_wind>
        <kinematic>0</kinematic>
      </link>
      <joint name='right_wheel_joint' type='revolute'>
        <pose relative_to='base_link'>0 -0.4 0 1.5708 -0 0</pose>
        <parent>base_link</parent>
        <child>right_wheel</child>
        <axis>
          <xyz>0 0 -1</xyz>
          <limit>
            <lower>-1e+16</lower>
            <upper>1e+16</upper>
          </limit>
          <dynamics>
            <spring_reference>0</spring_reference>
            <spring_stiffness>0</spring_stiffness>
          </dynamics>
        </axis>
      </joint>
      <link name='right_wheel'>
        <pose relative_to='right_wheel_joint'>0 0 0 0 -0 0</pose>
        <inertial>
          <pose>0 0 0 0 -0 0</pose>
          <mass>5</mass>
          <inertia>
            <ixx>0.0541667</ixx>
            <ixy>0</ixy>
            <ixz>0</ixz>
            <iyy>0.0541667</iyy>
            <iyz>0</iyz>
            <izz>0.1</izz>
          </inertia>
        </inertial>
        <collision name='right_wheel_collision'>
          <pose>0 0 0 0 -0 0</pose>
          <geometry>
            <cylinder>
              <length>0.1</length>
              <radius>0.2</radius>
            </cylinder>
          </geometry>
          <surface>
            <contact>
              <ode/>
            </contact>
            <friction>
              <ode/>
              <torsional>
                <ode/>
              </torsional>
            </friction>
            <bounce/>
          </surface>
          <max_contacts>10</max_contacts>
        </collision>
        <visual name='right_wheel_visual'>
          <pose>0 0 0 0 -0 0</pose>
          <geometry>
            <cylinder>
              <length>0.1</length>
              <radius>0.2</radius>
            </cylinder>
          </geometry>
          <material>
            <script>
              <name>Gazebo/Blue</name>
              <uri>file://media/materials/scripts/gazebo.material</uri>
            </script>
          </material>
        </visual>
        <self_collide>0</self_collide>
        <enable_wind>0</enable_wind>
        <kinematic>0</kinematic>
      </link>
      <static>0</static>
      <plugin name='diff_drive' filename='libgazebo_ros_diff_drive.so'>
        <left_joint>left_wheel_joint</left_joint>
        <right_joint>right_wheel_joint</right_joint>
        <wheel_separation>0.35</wheel_separation>
        <wheel_diameter>0.1</wheel_diameter>
        <max_wheel_torque>200</max_wheel_torque>
        <max_wheel_acceleration>10.0</max_wheel_acceleration>
        <odometry_frame>odom</odometry_frame>
        <robot_base_frame>base_link</robot_base_frame>
        <publish_odom>1</publish_odom>
        <publish_odom_tf>1</publish_odom_tf>
        <publish_wheel_tf>1</publish_wheel_tf>
      </plugin>
      <pose>0 0 0 0 -0 0</pose>
    </model>
    <model name='unit_box'>
      <pose>-8.09481 -3.53722 0.5 0 -0 0</pose>
      <link name='link'>
        <inertial>
          <mass>1</mass>
          <inertia>
            <ixx>0.166667</ixx>
            <ixy>0</ixy>
            <ixz>0</ixz>
            <iyy>0.166667</iyy>
            <iyz>0</iyz>
            <izz>0.166667</izz>
          </inertia>
          <pose>0 0 0 0 -0 0</pose>
        </inertial>
        <collision name='collision'>
          <geometry>
            <box>
              <size>1 1 1</size>
            </box>
          </geometry>
          <max_contacts>10</max_contacts>
          <surface>
            <contact>
              <ode/>
            </contact>
            <bounce/>
            <friction>
              <torsional>
                <ode/>
              </torsional>
              <ode/>
            </friction>
          </surface>
        </collision>
        <visual name='visual'>
          <geometry>
            <box>
              <size>1 1 1</size>
            </box>
          </geometry>
          <material>
            <script>
              <name>Gazebo/Grey</name>
              <uri>file://media/materials/scripts/gazebo.material</uri>
            </script>
          </material>
        </visual>
        <self_collide>0</self_collide>
        <enable_wind>0</enable_wind>
        <kinematic>0</kinematic>
      </link>
    </model>
    <model name='unit_box_0'>
      <pose>-8.30299 -3.47227 0.5 0 -0 0</pose>
      <link name='link'>
        <inertial>
          <mass>1</mass>
          <inertia>
            <ixx>0.166667</ixx>
            <ixy>0</ixy>
            <ixz>0</ixz>
            <iyy>0.166667</iyy>
            <iyz>0</iyz>
            <izz>0.166667</izz>
          </inertia>
          <pose>0 0 0 0 -0 0</pose>
        </inertial>
        <collision name='collision'>
          <geometry>
            <box>
              <size>1 1 1</size>
            </box>
          </geometry>
          <max_contacts>10</max_contacts>
          <surface>
            <contact>
              <ode/>
            </contact>
            <bounce/>
            <friction>
              <torsional>
                <ode/>
              </torsional>
              <ode/>
            </friction>
          </surface>
        </collision>
        <visual name='visual'>
          <geometry>
            <box>
              <size>1 1 1</size>
            </box>
          </geometry>
          <material>
            <script>
              <name>Gazebo/Grey</name>
              <uri>file://media/materials/scripts/gazebo.material</uri>
            </script>
          </material>
        </visual>
        <self_collide>0</self_collide>
        <enable_wind>0</enable_wind>
        <kinematic>0</kinematic>
      </link>
    </model>
    <model name='unit_box_1'>
      <pose>-7.00966 -3.5914 0.5 0 -0 0</pose>
      <link name='link'>
        <inertial>
          <mass>1</mass>
          <inertia>
            <ixx>0.166667</ixx>
            <ixy>0</ixy>
            <ixz>0</ixz>
            <iyy>0.166667</iyy>
            <iyz>0</iyz>
            <izz>0.166667</izz>
          </inertia>
          <pose>0 0 0 0 -0 0</pose>
        </inertial>
        <collision name='collision'>
          <geometry>
            <box>
              <size>1 1 1</size>
            </box>
          </geometry>
          <max_contacts>10</max_contacts>
          <surface>
            <contact>
              <ode/>
            </contact>
            <bounce/>
            <friction>
              <torsional>
                <ode/>
              </torsional>
              <ode/>
            </friction>
          </surface>
        </collision>
        <visual name='visual'>
          <geometry>
            <box>
              <size>1 1 1</size>
            </box>
          </geometry>
          <material>
            <script>
              <name>Gazebo/Grey</name>
              <uri>file://media/materials/scripts/gazebo.material</uri>
            </script>
          </material>
        </visual>
        <self_collide>0</self_collide>
        <enable_wind>0</enable_wind>
        <kinematic>0</kinematic>
      </link>
    </model>
    <model name='unit_box_2'>
      <pose>-5.90349 -3.68651 0.5 0 -0 0</pose>
      <link name='link'>
        <inertial>
          <mass>1</mass>
          <inertia>
            <ixx>0.166667</ixx>
            <ixy>0</ixy>
            <ixz>0</ixz>
            <iyy>0.166667</iyy>
            <iyz>0</iyz>
            <izz>0.166667</izz>
          </inertia>
          <pose>0 0 0 0 -0 0</pose>
        </inertial>
        <collision name='collision'>
          <geometry>
            <box>
              <size>1 1 1</size>
            </box>
          </geometry>
          <max_contacts>10</max_contacts>
          <surface>
            <contact>
              <ode/>
            </contact>
            <bounce/>
            <friction>
              <torsional>
                <ode/>
              </torsional>
              <ode/>
            </friction>
          </surface>
        </collision>
        <visual name='visual'>
          <geometry>
            <box>
              <size>1 1 1</size>
            </box>
          </geometry>
          <material>
            <script>
              <name>Gazebo/Grey</name>
              <uri>file://media/materials/scripts/gazebo.material</uri>
            </script>
          </material>
        </visual>
        <self_collide>0</self_collide>
        <enable_wind>0</enable_wind>
        <kinematic>0</kinematic>
      </link>
    </model>
    <model name='unit_box_3'>
      <pose>-4.81723 -3.82711 0.5 0 -0 0</pose>
      <link name='link'>
        <inertial>
          <mass>1</mass>
          <inertia>
            <ixx>0.166667</ixx>
            <ixy>0</ixy>
            <ixz>0</ixz>
            <iyy>0.166667</iyy>
            <iyz>0</iyz>
            <izz>0.166667</izz>
          </inertia>
          <pose>0 0 0 0 -0 0</pose>
        </inertial>
        <collision name='collision'>
          <geometry>
            <box>
              <size>1 1 1</size>
            </box>
          </geometry>
          <max_contacts>10</max_contacts>
          <surface>
            <contact>
              <ode/>
            </contact>
            <bounce/>
            <friction>
              <torsional>
                <ode/>
              </torsional>
              <ode/>
            </friction>
          </surface>
        </collision>
        <visual name='visual'>
          <geometry>
            <box>
              <size>1 1 1</size>
            </box>
          </geometry>
          <material>
            <script>
              <name>Gazebo/Grey</name>
              <uri>file://media/materials/scripts/gazebo.material</uri>
            </script>
          </material>
        </visual>
        <self_collide>0</self_collide>
        <enable_wind>0</enable_wind>
        <kinematic>0</kinematic>
      </link>
    </model>
    <model name='unit_box_0_clone'>
      <pose>-7.01702 -3.4792 1.5 0 -5e-06 -9.8e-05</pose>
      <link name='link'>
        <inertial>
          <mass>1</mass>
          <inertia>
            <ixx>0.166667</ixx>
            <ixy>0</ixy>
            <ixz>0</ixz>
            <iyy>0.166667</iyy>
            <iyz>0</iyz>
            <izz>0.166667</izz>
          </inertia>
          <pose>0 0 0 0 -0 0</pose>
        </inertial>
        <collision name='collision'>
          <geometry>
            <box>
              <size>1 1 1</size>
            </box>
          </geometry>
          <max_contacts>10</max_contacts>
          <surface>
            <contact>
              <ode/>
            </contact>
            <bounce/>
            <friction>
              <torsional>
                <ode/>
              </torsional>
              <ode/>
            </friction>
          </surface>
        </collision>
        <visual name='visual'>
          <geometry>
            <box>
              <size>1 1 1</size>
            </box>
          </geometry>
          <material>
            <script>
              <name>Gazebo/Grey</name>
              <uri>file://media/materials/scripts/gazebo.material</uri>
            </script>
          </material>
        </visual>
        <self_collide>0</self_collide>
        <enable_wind>0</enable_wind>
        <kinematic>0</kinematic>
      </link>
    </model>
    <model name='unit_box_0_clone_0'>
      <pose>-5.77466 -3.74213 1.5 0 -5e-06 -9.8e-05</pose>
      <link name='link'>
        <inertial>
          <mass>1</mass>
          <inertia>
            <ixx>0.166667</ixx>
            <ixy>0</ixy>
            <ixz>0</ixz>
            <iyy>0.166667</iyy>
            <iyz>0</iyz>
            <izz>0.166667</izz>
          </inertia>
          <pose>0 0 0 0 -0 0</pose>
        </inertial>
        <collision name='collision'>
          <geometry>
            <box>
              <size>1 1 1</size>
            </box>
          </geometry>
          <max_contacts>10</max_contacts>
          <surface>
            <contact>
              <ode/>
            </contact>
            <bounce/>
            <friction>
              <torsional>
                <ode/>
              </torsional>
              <ode/>
            </friction>
          </surface>
        </collision>
        <visual name='visual'>
          <geometry>
            <box>
              <size>1 1 1</size>
            </box>
          </geometry>
          <material>
            <script>
              <name>Gazebo/Grey</name>
              <uri>file://media/materials/scripts/gazebo.material</uri>
            </script>
          </material>
        </visual>
        <self_collide>0</self_collide>
        <enable_wind>0</enable_wind>
        <kinematic>0</kinematic>
      </link>
    </model>
    <model name='unit_box_0_clone_1'>
      <pose>-4.66771 -3.74221 1.5 0 -5e-06 -9.8e-05</pose>
      <link name='link'>
        <inertial>
          <mass>1</mass>
          <inertia>
            <ixx>0.166667</ixx>
            <ixy>0</ixy>
            <ixz>0</ixz>
            <iyy>0.166667</iyy>
            <iyz>0</iyz>
            <izz>0.166667</izz>
          </inertia>
          <pose>0 0 0 0 -0 0</pose>
        </inertial>
        <collision name='collision'>
          <geometry>
            <box>
              <size>1 1 1</size>
            </box>
          </geometry>
          <max_contacts>10</max_contacts>
          <surface>
            <contact>
              <ode/>
            </contact>
            <bounce/>
            <friction>
              <torsional>
                <ode/>
              </torsional>
              <ode/>
            </friction>
          </surface>
        </collision>
        <visual name='visual'>
          <geometry>
            <box>
              <size>1 1 1</size>
            </box>
          </geometry>
          <material>
            <script>
              <name>Gazebo/Grey</name>
              <uri>file://media/materials/scripts/gazebo.material</uri>
            </script>
          </material>
        </visual>
        <self_collide>0</self_collide>
        <enable_wind>0</enable_wind>
        <kinematic>0</kinematic>
      </link>
    </model>
    <model name='unit_box_0_clone_clone'>
      <pose>-3.50982 -3.79254 1.5 0 -5e-06 -9.8e-05</pose>
      <link name='link'>
        <inertial>
          <mass>1</mass>
          <inertia>
            <ixx>0.166667</ixx>
            <ixy>0</ixy>
            <ixz>0</ixz>
            <iyy>0.166667</iyy>
            <iyz>0</iyz>
            <izz>0.166667</izz>
          </inertia>
          <pose>0 0 0 0 -0 0</pose>
        </inertial>
        <collision name='collision'>
          <geometry>
            <box>
              <size>1 1 1</size>
            </box>
          </geometry>
          <max_contacts>10</max_contacts>
          <surface>
            <contact>
              <ode/>
            </contact>
            <bounce/>
            <friction>
              <torsional>
                <ode/>
              </torsional>
              <ode/>
            </friction>
          </surface>
        </collision>
        <visual name='visual'>
          <geometry>
            <box>
              <size>1 1 1</size>
            </box>
          </geometry>
          <material>
            <script>
              <name>Gazebo/Grey</name>
              <uri>file://media/materials/scripts/gazebo.material</uri>
            </script>
          </material>
        </visual>
        <self_collide>0</self_collide>
        <enable_wind>0</enable_wind>
        <kinematic>0</kinematic>
      </link>
    </model>
    <model name='unit_box_3_clone'>
      <pose>-3.52893 -4.12024 0.5 0 -0 0</pose>
      <link name='link'>
        <inertial>
          <mass>1</mass>
          <inertia>
            <ixx>0.166667</ixx>
            <ixy>0</ixy>
            <ixz>0</ixz>
            <iyy>0.166667</iyy>
            <iyz>0</iyz>
            <izz>0.166667</izz>
          </inertia>
          <pose>0 0 0 0 -0 0</pose>
        </inertial>
        <collision name='collision'>
          <geometry>
            <box>
              <size>1 1 1</size>
            </box>
          </geometry>
          <max_contacts>10</max_contacts>
          <surface>
            <contact>
              <ode/>
            </contact>
            <bounce/>
            <friction>
              <torsional>
                <ode/>
              </torsional>
              <ode/>
            </friction>
          </surface>
        </collision>
        <visual name='visual'>
          <geometry>
            <box>
              <size>1 1 1</size>
            </box>
          </geometry>
          <material>
            <script>
              <name>Gazebo/Grey</name>
              <uri>file://media/materials/scripts/gazebo.material</uri>
            </script>
          </material>
        </visual>
        <self_collide>0</self_collide>
        <enable_wind>0</enable_wind>
        <kinematic>0</kinematic>
      </link>
    </model>
    <model name='unit_box_3_clone_0'>
      <pose>-2.41898 -4.17951 0.5 0 -0 0</pose>
      <link name='link'>
        <inertial>
          <mass>1</mass>
          <inertia>
            <ixx>0.166667</ixx>
            <ixy>0</ixy>
            <ixz>0</ixz>
            <iyy>0.166667</iyy>
            <iyz>0</iyz>
            <izz>0.166667</izz>
          </inertia>
          <pose>0 0 0 0 -0 0</pose>
        </inertial>
        <collision name='collision'>
          <geometry>
            <box>
              <size>1 1 1</size>
            </box>
          </geometry>
          <max_contacts>10</max_contacts>
          <surface>
            <contact>
              <ode/>
            </contact>
            <bounce/>
            <friction>
              <torsional>
                <ode/>
              </torsional>
              <ode/>
            </friction>
          </surface>
        </collision>
        <visual name='visual'>
          <geometry>
            <box>
              <size>1 1 1</size>
            </box>
          </geometry>
          <material>
            <script>
              <name>Gazebo/Grey</name>
              <uri>file://media/materials/scripts/gazebo.material</uri>
            </script>
          </material>
        </visual>
        <self_collide>0</self_collide>
        <enable_wind>0</enable_wind>
        <kinematic>0</kinematic>
      </link>
    </model>
    <model name='unit_box_3_clone_1'>
      <pose>-1.27878 -4.15923 0.5 0 -0 0</pose>
      <link name='link'>
        <inertial>
          <mass>1</mass>
          <inertia>
            <ixx>0.166667</ixx>
            <ixy>0</ixy>
            <ixz>0</ixz>
            <iyy>0.166667</iyy>
            <iyz>0</iyz>
            <izz>0.166667</izz>
          </inertia>
          <pose>0 0 0 0 -0 0</pose>
        </inertial>
        <collision name='collision'>
          <geometry>
            <box>
              <size>1 1 1</size>
            </box>
          </geometry>
          <max_contacts>10</max_contacts>
          <surface>
            <contact>
              <ode/>
            </contact>
            <bounce/>
            <friction>
              <torsional>
                <ode/>
              </torsional>
              <ode/>
            </friction>
          </surface>
        </collision>
        <visual name='visual'>
          <geometry>
            <box>
              <size>1 1 1</size>
            </box>
          </geometry>
          <material>
            <script>
              <name>Gazebo/Grey</name>
              <uri>file://media/materials/scripts/gazebo.material</uri>
            </script>
          </material>
        </visual>
        <self_collide>0</self_collide>
        <enable_wind>0</enable_wind>
        <kinematic>0</kinematic>
      </link>
    </model>
    <model name='unit_box_0_clone_clone_clone'>
      <pose>-2.44108 -3.99656 1.5 0 -5e-06 -9.8e-05</pose>
      <link name='link'>
        <inertial>
          <mass>1</mass>
          <inertia>
            <ixx>0.166667</ixx>
            <ixy>0</ixy>
            <ixz>0</ixz>
            <iyy>0.166667</iyy>
            <iyz>0</iyz>
            <izz>0.166667</izz>
          </inertia>
          <pose>0 0 0 0 -0 0</pose>
        </inertial>
        <collision name='collision'>
          <geometry>
            <box>
              <size>1 1 1</size>
            </box>
          </geometry>
          <max_contacts>10</max_contacts>
          <surface>
            <contact>
              <ode/>
            </contact>
            <bounce/>
            <friction>
              <torsional>
                <ode/>
              </torsional>
              <ode/>
            </friction>
          </surface>
        </collision>
        <visual name='visual'>
          <geometry>
            <box>
              <size>1 1 1</size>
            </box>
          </geometry>
          <material>
            <script>
              <name>Gazebo/Grey</name>
              <uri>file://media/materials/scripts/gazebo.material</uri>
            </script>
          </material>
        </visual>
        <self_collide>0</self_collide>
        <enable_wind>0</enable_wind>
        <kinematic>0</kinematic>
      </link>
    </model>
    <model name='unit_box_0_clone_clone_clone_0'>
      <pose>-1.17969 -3.69133 1.5 0 -5e-06 -9.8e-05</pose>
      <link name='link'>
        <inertial>
          <mass>1</mass>
          <inertia>
            <ixx>0.166667</ixx>
            <ixy>0</ixy>
            <ixz>0</ixz>
            <iyy>0.166667</iyy>
            <iyz>0</iyz>
            <izz>0.166667</izz>
          </inertia>
          <pose>0 0 0 0 -0 0</pose>
        </inertial>
        <collision name='collision'>
          <geometry>
            <box>
              <size>1 1 1</size>
            </box>
          </geometry>
          <max_contacts>10</max_contacts>
          <surface>
            <contact>
              <ode/>
            </contact>
            <bounce/>
            <friction>
              <torsional>
                <ode/>
              </torsional>
              <ode/>
            </friction>
          </surface>
        </collision>
        <visual name='visual'>
          <geometry>
            <box>
              <size>1 1 1</size>
            </box>
          </geometry>
          <material>
            <script>
              <name>Gazebo/Grey</name>
              <uri>file://media/materials/scripts/gazebo.material</uri>
            </script>
          </material>
        </visual>
        <self_collide>0</self_collide>
        <enable_wind>0</enable_wind>
        <kinematic>0</kinematic>
      </link>
    </model>
    <model name='unit_cylinder'>
      <pose>-1.35362 -5.32339 0.5 0 -0 0</pose>
      <link name='link'>
        <inertial>
          <mass>1</mass>
          <inertia>
            <ixx>0.145833</ixx>
            <ixy>0</ixy>
            <ixz>0</ixz>
            <iyy>0.145833</iyy>
            <iyz>0</iyz>
            <izz>0.125</izz>
          </inertia>
          <pose>0 0 0 0 -0 0</pose>
        </inertial>
        <collision name='collision'>
          <geometry>
            <cylinder>
              <radius>0.5</radius>
              <length>0.999999</length>
            </cylinder>
          </geometry>
          <max_contacts>10</max_contacts>
          <surface>
            <contact>
              <ode/>
            </contact>
            <bounce/>
            <friction>
              <torsional>
                <ode/>
              </torsional>
              <ode/>
            </friction>
          </surface>
        </collision>
        <visual name='visual'>
          <geometry>
            <cylinder>
              <radius>0.5</radius>
              <length>0.999999</length>
            </cylinder>
          </geometry>
          <material>
            <script>
              <name>Gazebo/Grey</name>
              <uri>file://media/materials/scripts/gazebo.material</uri>
            </script>
          </material>
        </visual>
        <self_collide>0</self_collide>
        <enable_wind>0</enable_wind>
        <kinematic>0</kinematic>
      </link>
    </model>
    <state world_name='default'>
      <sim_time>30 288000000</sim_time>
      <real_time>27 436033652</real_time>
      <wall_time>1734107372 725385370</wall_time>
      <iterations>27271</iterations>
      <model name='ground_plane'>
        <pose>0 0 0 0 -0 0</pose>
        <scale>1 1 1</scale>
        <link name='link'>
          <pose>0 0 0 0 -0 0</pose>
          <velocity>0 0 0 0 -0 0</velocity>
          <acceleration>0 0 0 0 -0 0</acceleration>
          <wrench>0 0 0 0 -0 0</wrench>
        </link>
      </model>
      <model name='my_bot'>
        <pose>9.2121 -1.01208 0.202385 0.005326 -0.012826 0.38591</pose>
        <scale>1 1 1</scale>
        <link name='base_link'>
          <pose>9.2121 -1.01208 0.202385 0.005326 -0.012826 0.38591</pose>
          <velocity>1.69348 0.690194 -0.005436 -0.0034 -0.003367 0.385449</velocity>
          <acceleration>0.075903 -0.11103 -10.0167 0.828077 0.408326 0.090425</acceleration>
          <wrench>4.18987 -6.12885 -552.921 0 -0 0</wrench>
        </link>
        <link name='cart'>
          <pose>7.51368 -1.70212 0.178869 -0.009543 0.01009 -3.11963</pose>
          <velocity>1.95936 0.035596 -0.008581 0.000343 0.000344 -0.00252</velocity>
          <acceleration>0.42859 -0.253824 -9.50025 0.66168 0.171934 0.370898</acceleration>
          <wrench>21.6009 -12.7927 -478.812 0 -0 0</wrench>
        </link>
        <link name='cart2'>
          <pose>4.28123 -1.77314 0.146245 -0.010094 -0.009535 1.59367</pose>
          <velocity>1.95881 0.043887 -0.007303 0.000311 -0.000614 -0.003271</velocity>
          <acceleration>-0.866698 -0.638017 -8.36439 -2.76412 -0.688703 1.58527</acceleration>
          <wrench>-17.6806 -13.0155 -170.634 0 -0 0</wrench>
        </link>
        <link name='cart2_left_wheel'>
          <pose>3.69481 -0.186155 0.15595 -1.5809 -0.023738 1.59381</pose>
          <velocity>1.96402 0.045757 -0.007208 0.000853 -0.000597 -0.003261</velocity>
          <acceleration>2.0172 0.775573 -8.90154 0.051629 -1.54307 -1.94772</acceleration>
          <wrench>10.086 3.87786 -44.5077 0 -0 0</wrench>
        </link>
        <link name='cart2_right_wheel'>
          <pose>4.79447 -0.161108 0.167052 1.5607 -0.023797 1.59381</pose>
          <velocity>1.964 0.042114 -0.006576 0.001032 -0.000616 -0.003246</velocity>
          <acceleration>1.87793 -1.00843 -7.26867 -3.08868 -1.53759 1.20545</acceleration>
          <wrench>9.38965 -5.04214 -36.3433 0 -0 0</wrench>
        </link>
        <link name='cart3'>
          <pose>4.21873 0.959419 0.172313 -0.009541 0.010087 -3.11962</pose>
          <velocity>1.96588 0.04434 -0.00783 0.000956 -0.000404 -0.003272</velocity>
          <acceleration>-1.19524 0.185073 -10.7923 1.7568 -1.13242 -1.52745</acceleration>
          <wrench>-24.3829 3.77549 -220.164 0 -0 0</wrench>
        </link>
        <link name='cart3_left_wheel'>
          <pose>2.63134 0.374422 0.15093 -1.58027 0.07043 -3.12019</pose>
          <velocity>1.96362 0.049297 -0.009647 -0.265413 0.532958 0.120228</velocity>
          <acceleration>-1.36438 2.8509 -13.6673 -0.372229 0.983798 -2.64675</acceleration>
          <wrench>-6.8219 14.2545 -68.3363 0 -0 0</wrench>
        </link>
        <link name='cart3_right_wheel'>
          <pose>2.60706 1.47411 0.161422 -1.56087 -0.278057 0.019348</pose>
          <velocity>1.96718 0.048234 -0.008103 2.82165 1.22293 -3.00653</velocity>
          <acceleration>0.234348 0.732355 -10.8481 -0.216011 0.008561 -1.66728</acceleration>
          <wrench>1.17174 3.66178 -54.2404 0 -0 0</wrench>
        </link>
        <link name='cart_left_wheel'>
          <pose>5.32756 -2.35027 0.150946 1.6253 1.39447 0.075727</pose>
          <velocity>1.95754 0.041176 -0.007811 -0.28981 0.463744 0.122034</velocity>
          <acceleration>0.150975 0.31352 -9.45546 1.60711 0.032102 0.416229</acceleration>
          <wrench>0.754875 1.5676 -47.2773 0 -0 0</wrench>
        </link>
        <link name='cart_right_wheel'>
          <pose>5.30109 -1.15062 0.162397 1.56126 -0.007861 -3.11945</pose>
          <velocity>1.96057 0.04131 -0.007348 0.000487 0.000593 -0.002512</velocity>
          <acceleration>-0.275233 0.221752 -8.38555 0.910231 0.016295 0.474593</acceleration>
          <wrench>-1.37617 1.10876 -41.9277 0 -0 0</wrench>
        </link>
        <link name='left_wheel'>
          <pose>9.06152 -0.641513 0.204515 -1.56546 -0.059243 0.385663</pose>
          <velocity>1.55064 0.632345 -0.007279 -0.624466 0.16318 -2.70284</velocity>
          <acceleration>0.035846 0.72321 -9.82795 0.589968 0.102083 0.052339</acceleration>
          <wrench>0.179231 3.61605 -49.1397 0 -0 0</wrench>
        </link>
        <link name='right_wheel'>
          <pose>9.36269 -1.38265 0.200259 1.57618 0.160427 0.386834</pose>
          <velocity>1.83651 0.748361 -0.004806 -0.619077 0.160998 -2.70191</velocity>
          <acceleration>0.577866 1.02344 -12.4834 0.321357 1.47871 -0.477095</acceleration>
          <wrench>2.88933 5.1172 -62.4168 0 -0 0</wrench>
        </link>
      </model>
      <model name='unit_box'>
        <pose>-7.82811 -3.52733 0.499978 -6e-06 -0 -0.036705</pose>
        <scale>1 1 1</scale>
        <link name='link'>
          <pose>-7.82811 -3.52733 0.499978 -6e-06 -0 -0.036705</pose>
          <velocity>0 0 0 0 -0 0</velocity>
          <acceleration>-0 0 -9.8 0 -0 0</acceleration>
          <wrench>-0 0 -9.8 0 -0 0</wrench>
        </link>
      </model>
      <model name='unit_box_0'>
        <pose>-8.82639 -3.46237 0.5 0 0 -0.036706</pose>
        <scale>1 1 1</scale>
        <link name='link'>
          <pose>-8.82639 -3.46237 0.5 0 0 -0.036706</pose>
          <velocity>0 0 0 0 -0 0</velocity>
          <acceleration>0.058499 1.46961 5.04504 -2.9373 0.116851 0.000744</acceleration>
          <wrench>0.058499 1.46961 5.04504 0 -0 0</wrench>
        </link>
      </model>
      <model name='unit_box_0_clone'>
        <pose>-7.01764 -3.47851 1.49999 -1.6e-05 -7e-06 -0.000869</pose>
        <scale>1 1 1</scale>
        <link name='link'>
          <pose>-7.01764 -3.47851 1.49999 -1.6e-05 -7e-06 -0.000869</pose>
          <velocity>0 0 0 0 -0 0</velocity>
          <acceleration>3.07204 4.9375 -0.2551 1.15695 0.515716 -1.77034</acceleration>
          <wrench>3.07204 4.9375 -0.2551 0 -0 0</wrench>
        </link>
      </model>
      <model name='unit_box_0_clone_0'>
        <pose>-5.77504 -3.74242 1.5 1.5e-05 -1.4e-05 0.00024</pose>
        <scale>1 1 1</scale>
        <link name='link'>
          <pose>-5.77504 -3.74242 1.5 1.5e-05 -1.4e-05 0.00024</pose>
          <velocity>0 0 0 0 -0 0</velocity>
          <acceleration>-0.927078 -0.613388 -6.60135 -0.186248 0.309407 0.621542</acceleration>
          <wrench>-0.927078 -0.613388 -6.60135 0 -0 0</wrench>
        </link>
      </model>
      <model name='unit_box_0_clone_1'>
        <pose>-4.66232 -3.74007 1.49591 -0.001407 0.002481 -0.003007</pose>
        <scale>1 1 1</scale>
        <link name='link'>
          <pose>-4.66232 -3.74007 1.49591 -0.001407 0.002481 -0.003007</pose>
          <velocity>0 0 0 0 -0 0</velocity>
          <acceleration>0 0 -9.8 0 -0 0</acceleration>
          <wrench>0 0 -9.8 0 -0 0</wrench>
        </link>
      </model>
      <model name='unit_box_0_clone_clone'>
        <pose>-3.50942 -3.78638 1.48345 -0.016626 0.000923 0.001259</pose>
        <scale>1 1 1</scale>
        <link name='link'>
          <pose>-3.50942 -3.78638 1.48345 -0.016626 0.000923 0.001259</pose>
          <velocity>0 0 0 0 -0 0</velocity>
          <acceleration>0 0 -9.8 0 -0 0</acceleration>
          <wrench>0 0 -9.8 0 -0 0</wrench>
        </link>
      </model>
      <model name='unit_box_0_clone_clone_clone'>
        <pose>-2.44164 -3.99105 1.49185 -0.006171 -0.000648 0.001093</pose>
        <scale>1 1 1</scale>
        <link name='link'>
          <pose>-2.44164 -3.99105 1.49185 -0.006171 -0.000648 0.001093</pose>
          <velocity>0 0 0 0 -0 0</velocity>
          <acceleration>0 0 -9.8 0 -0 0</acceleration>
          <wrench>0 0 -9.8 0 -0 0</wrench>
        </link>
      </model>
      <model name='unit_box_0_clone_clone_clone_0'>
        <pose>1.71727 -4.21687 0.499995 0 -1e-05 -0.042658</pose>
        <scale>1 1 1</scale>
        <link name='link'>
          <pose>1.71727 -4.21687 0.499995 0 -1e-05 -0.042658</pose>
          <velocity>0 0 0 0 -0 0</velocity>
          <acceleration>-0.01024 0.006083 -9.78252 -0.012162 -0.020481 2e-06</acceleration>
          <wrench>-0.01024 0.006083 -9.78252 0 -0 0</wrench>
        </link>
      </model>
      <model name='unit_box_1'>
        <pose>-6.83008 -3.59994 0.499995 -1.5e-05 -6e-06 -0.036706</pose>
        <scale>1 1 1</scale>
        <link name='link'>
          <pose>-6.83008 -3.59994 0.499995 -1.5e-05 -6e-06 -0.036706</pose>
          <velocity>0 0 0 0 -0 0</velocity>
          <acceleration>0.614214 4.92798 -5.47534 1.63161 0.248983 -1.02709</acceleration>
          <wrench>0.614214 4.92798 -5.47534 0 -0 0</wrench>
        </link>
      </model>
      <model name='unit_box_2'>
        <pose>-5.83224 -3.6983 0.5 0 0 -0.035365</pose>
        <scale>1 1 1</scale>
        <link name='link'>
          <pose>-5.83224 -3.6983 0.5 0 0 -0.035365</pose>
          <velocity>0 0 0 0 -0 0</velocity>
          <acceleration>-1.77294 0.499084 2.04912 2.14343 0.404286 -3.14159</acceleration>
          <wrench>-1.77294 0.499084 2.04912 0 -0 0</wrench>
        </link>
      </model>
      <model name='unit_box_3'>
        <pose>-4.81985 -3.82981 0.496452 -0.001393 0.002465 -0.001822</pose>
        <scale>1 1 1</scale>
        <link name='link'>
          <pose>-4.81985 -3.82981 0.496452 -0.001393 0.002465 -0.001822</pose>
          <velocity>0 0 0 0 -0 0</velocity>
          <acceleration>-0.004807 -0.002736 -29.3981 2.03603 -0.36388 2e-06</acceleration>
          <wrench>-0.004807 -0.002736 -29.3981 0 -0 0</wrench>
        </link>
      </model>
      <model name='unit_box_3_clone'>
        <pose>-3.53025 -4.14936 0.489393 -0.016584 0.000902 0.000153</pose>
        <scale>1 1 1</scale>
        <link name='link'>
          <pose>-3.53025 -4.14936 0.489393 -0.016584 0.000902 0.000153</pose>
          <velocity>0 0 0 0 -0 0</velocity>
          <acceleration>-0.000583 -0.010163 -29.3923 -1.74659 0.698183 3.14159</acceleration>
          <wrench>-0.000583 -0.010163 -29.3923 0 -0 0</wrench>
        </link>
      </model>
      <model name='unit_box_3_clone_0'>
        <pose>-2.4177 -4.19119 0.493115 -0.006148 -0.000645 0.000999</pose>
        <scale>1 1 1</scale>
        <link name='link'>
          <pose>-2.4177 -4.19119 0.493115 -0.006148 -0.000645 0.000999</pose>
          <velocity>0 0 0 0 -0 0</velocity>
          <acceleration>0.000718 -0.006007 -29.3976 -1.49495 -0.332173 -3.14159</acceleration>
          <wrench>0.000718 -0.006007 -29.3976 0 -0 0</wrench>
        </link>
      </model>
      <model name='unit_box_3_clone_1'>
        <pose>-1.27891 -4.15903 0.499995 0 1e-05 -0.000416</pose>
        <scale>1 1 1</scale>
        <link name='link'>
          <pose>-1.27891 -4.15903 0.499995 0 1e-05 -0.000416</pose>
          <velocity>0 0 0 0 -0 0</velocity>
          <acceleration>0.010617 0.006191 -9.78231 -0.012425 0.021231 -1.9e-05</acceleration>
          <wrench>0.010617 0.006191 -9.78231 0 -0 0</wrench>
        </link>
      </model>
      <model name='unit_cylinder'>
        <pose>10.802 -2.56826 0.712669 -1.5708 -0.605796 -2.7242</pose>
        <scale>1.42534 1.42534 1.4984</scale>
        <link name='link'>
          <pose>10.802 -2.56826 0.712669 -1.5708 -0.605796 -2.7242</pose>
          <velocity>1.22483 0.548035 0.004709 2.3726 1.42294 -3.14158</velocity>
          <acceleration>-3.69108 8.31974 9.42498 0.887069 1.11544 -7.5e-05</acceleration>
          <wrench>-3.69108 8.31974 9.42498 0 -0 0</wrench>
        </link>
      </model>
      <light name='sun'>
        <pose>0 0 10 0 -0 0</pose>
      </light>
    </state>
    <gui fullscreen='0'>
      <camera name='user_camera'>
        <pose>18.4821 -9.94703 11.6139 0 0.623643 2.45619</pose>
        <view_controller>orbit</view_controller>
        <projection_type>perspective</projection_type>
      </camera>
    </gui>
  </world>
</sdf>
