<sdf version='1.7'>
  <world name='default'>
    <light name='sun' type='directional'>
      <cast_shadows>1</cast_shadows>
      <pose>0 0 10 0 -0 0</pose>
      <diffuse>0.8 0.8 0.8 1</diffuse>
      <specular>0.2 0.2 0.2 1</specular>
      <attenuation>
        <range>1000</range>
        <constant>0.9</constant>
        <linear>0.01</linear>
        <quadratic>0.001</quadratic>
      </attenuation>
      <direction>-0.5 0.1 -0.9</direction>
      <spot>
        <inner_angle>0</inner_angle>
        <outer_angle>0</outer_angle>
        <falloff>0</falloff>
      </spot>
    </light>
    <model name='ground_plane'>
      <static>1</static>
      <link name='link'>
        <collision name='collision'>
          <geometry>
            <plane>
              <normal>0 0 1</normal>
              <size>100 100</size>
            </plane>
          </geometry>
          <surface>
            <friction>
              <ode>
                <mu>100</mu>
                <mu2>50</mu2>
              </ode>
              <torsional>
                <ode/>
              </torsional>
            </friction>
            <contact>
              <ode/>
            </contact>
            <bounce/>
          </surface>
          <max_contacts>10</max_contacts>
        </collision>
        <visual name='visual'>
          <cast_shadows>0</cast_shadows>
          <geometry>
            <plane>
              <normal>0 0 1</normal>
              <size>100 100</size>
            </plane>
          </geometry>
          <material>
            <script>
              <uri>file://media/materials/scripts/gazebo.material</uri>
              <name>Gazebo/Grey</name>
            </script>
          </material>
        </visual>
        <self_collide>0</self_collide>
        <enable_wind>0</enable_wind>
        <kinematic>0</kinematic>
      </link>
    </model>
    <gravity>0 0 -9.8</gravity>
    <magnetic_field>6e-06 2.3e-05 -4.2e-05</magnetic_field>
    <atmosphere type='adiabatic'/>
    <physics type='ode'>
      <max_step_size>0.001</max_step_size>
      <real_time_factor>1</real_time_factor>
      <real_time_update_rate>1000</real_time_update_rate>
    </physics>
    <scene>
      <ambient>0.4 0.4 0.4 1</ambient>
      <background>0.7 0.7 0.7 1</background>
      <shadows>1</shadows>
    </scene>
    <audio>
      <device>default</device>
    </audio>
    <wind/>
    <spherical_coordinates>
      <surface_model>EARTH_WGS84</surface_model>
      <latitude_deg>0</latitude_deg>
      <longitude_deg>0</longitude_deg>
      <elevation>0</elevation>
      <heading_deg>0</heading_deg>
    </spherical_coordinates>
    <model name='my_bot'>
      <link name='base_link'>
        <inertial>
          <pose>0.579204 0 0.764919 0 -0 0</pose>
          <mass>55.3</mass>
          <inertia>
            <ixx>20.3378</ixx>
            <ixy>0</ixy>
            <ixz>2.43909</ixz>
            <iyy>30.6094</iyy>
            <iyz>0</iyz>
            <izz>15.6893</izz>
          </inertia>
        </inertial>
        <collision name='base_link_fixed_joint_lump__chassis_collision'>
          <pose>0.5225 0 0.85 0 -0 0</pose>
          <geometry>
            <box>
              <size>1.645 0.8 1.8</size>
            </box>
          </geometry>
          <surface>
            <contact>
              <ode/>
            </contact>
            <friction>
              <ode/>
              <torsional>
                <ode/>
              </torsional>
            </friction>
            <bounce/>
          </surface>
          <max_contacts>10</max_contacts>
        </collision>
        <collision name='base_link_fixed_joint_lump__camera_ray_collision_1'>
          <pose>1.35 0 1 0 -0 0</pose>
          <geometry>
            <cylinder>
              <length>0.04</length>
              <radius>0.05</radius>
            </cylinder>
          </geometry>
          <surface>
            <contact>
              <ode/>
            </contact>
            <friction>
              <ode/>
              <torsional>
                <ode/>
              </torsional>
            </friction>
            <bounce/>
          </surface>
          <max_contacts>10</max_contacts>
        </collision>
        <collision name='base_link_fixed_joint_lump__caster_wheel_collision_2'>
          <pose>1.1 0 -0.1 0 -0 0</pose>
          <geometry>
            <sphere>
              <radius>0.1</radius>
            </sphere>
          </geometry>
          <surface>
            <contact>
              <ode/>
            </contact>
            <friction>
              <ode>
                <mu>0.15</mu>
                <mu2>0.15</mu2>
              </ode>
              <torsional>
                <ode/>
              </torsional>
            </friction>
            <bounce/>
          </surface>
          <max_contacts>10</max_contacts>
        </collision>
        <collision name='base_link_fixed_joint_lump__lidar_l_collision_3'>
          <pose>1.35 0.4 1 0 -0 0</pose>
          <geometry>
            <cylinder>
              <length>0.04</length>
              <radius>0.05</radius>
            </cylinder>
          </geometry>
          <surface>
            <contact>
              <ode/>
            </contact>
            <friction>
              <ode/>
              <torsional>
                <ode/>
              </torsional>
            </friction>
            <bounce/>
          </surface>
          <max_contacts>10</max_contacts>
        </collision>
        <collision name='base_link_fixed_joint_lump__lidar_r_collision_4'>
          <pose>1.35 -0.4 1 0 -0 0</pose>
          <geometry>
            <cylinder>
              <length>0.04</length>
              <radius>0.05</radius>
            </cylinder>
          </geometry>
          <surface>
            <contact>
              <ode/>
            </contact>
            <friction>
              <ode/>
              <torsional>
                <ode/>
              </torsional>
            </friction>
            <bounce/>
          </surface>
          <max_contacts>10</max_contacts>
        </collision>
        <visual name='base_link_fixed_joint_lump__chassis_visual'>
          <pose>0.5225 0 0.85 0 -0 0</pose>
          <geometry>
            <box>
              <size>1.645 0.8 1.8</size>
            </box>
          </geometry>
          <material>
            <script>
              <name>Gazebo/White</name>
              <uri>file://media/materials/scripts/gazebo.material</uri>
            </script>
          </material>
        </visual>
        <visual name='base_link_fixed_joint_lump__camera_ray_visual_1'>
          <pose>1.35 0 1 0 -0 0</pose>
          <geometry>
            <cylinder>
              <length>0.04</length>
              <radius>0.05</radius>
            </cylinder>
          </geometry>
          <material>
            <script>
              <name>ambient</name>
              <uri>file://media/materials/scripts/gazebo.material</uri>
            </script>
          </material>
        </visual>
        <visual name='base_link_fixed_joint_lump__caster_wheel_visual_2'>
          <pose>1.1 0 -0.1 0 -0 0</pose>
          <geometry>
            <sphere>
              <radius>0.1</radius>
            </sphere>
          </geometry>
          <material>
            <script>
              <name>Gazebo/Black</name>
              <uri>file://media/materials/scripts/gazebo.material</uri>
            </script>
          </material>
        </visual>
        <visual name='base_link_fixed_joint_lump__lidar_l_visual_3'>
          <pose>1.35 0.4 1 0 -0 0</pose>
          <geometry>
            <cylinder>
              <length>0.04</length>
              <radius>0.05</radius>
            </cylinder>
          </geometry>
          <material>
            <script>
              <name>Gazebo/Red</name>
              <uri>file://media/materials/scripts/gazebo.material</uri>
            </script>
          </material>
        </visual>
        <visual name='base_link_fixed_joint_lump__lidar_r_visual_4'>
          <pose>1.35 -0.4 1 0 -0 0</pose>
          <geometry>
            <cylinder>
              <length>0.04</length>
              <radius>0.05</radius>
            </cylinder>
          </geometry>
          <material>
            <script>
              <name>Gazebo/Yellow</name>
              <uri>file://media/materials/scripts/gazebo.material</uri>
            </script>
          </material>
        </visual>
        <sensor name='camera_ray' type='ray'>
          <visualize>1</visualize>
          <update_rate>10</update_rate>
          <ray>
            <scan>
              <horizontal>
                <samples>86</samples>
                <min_angle>-0.75</min_angle>
                <max_angle>0.75</max_angle>
                <resolution>1</resolution>
              </horizontal>
              <vertical>
                <samples>1</samples>
                <min_angle>0</min_angle>
                <max_angle>0</max_angle>
              </vertical>
            </scan>
            <range>
              <min>0.3</min>
              <max>5</max>
            </range>
          </ray>
          <plugin name='camera_ray_controller' filename='libgazebo_ros_ray_sensor.so'>
            <ros>
              <argument>~/out:=scan</argument>
            </ros>
            <output_type>sensor_msgs/LaserScan</output_type>
            <frame_name>camera_ray</frame_name>
          </plugin>
          <pose>1.35 0 1 0 -0 0</pose>
        </sensor>
        <sensor name='lidar_l' type='ray'>
          <visualize>1</visualize>
          <update_rate>10</update_rate>
          <ray>
            <scan>
              <horizontal>
                <samples>360</samples>
                <min_angle>-3.14</min_angle>
                <max_angle>3.14</max_angle>
                <resolution>1</resolution>
              </horizontal>
              <vertical>
                <samples>1</samples>
                <min_angle>0</min_angle>
                <max_angle>0</max_angle>
              </vertical>
            </scan>
            <range>
              <min>0.3</min>
              <max>12</max>
            </range>
          </ray>
          <plugin name='lidar_l_controller' filename='libgazebo_ros_ray_sensor.so'>
            <ros>
              <argument>~/out:=scan</argument>
            </ros>
            <output_type>sensor_msgs/LaserScan</output_type>
            <frame_name>lidar_l</frame_name>
          </plugin>
          <pose>1.35 0.4 1 0 -0 0</pose>
        </sensor>
        <sensor name='lidar_r' type='ray'>
          <visualize>1</visualize>
          <update_rate>10</update_rate>
          <ray>
            <scan>
              <horizontal>
                <samples>360</samples>
                <min_angle>-3.14</min_angle>
                <max_angle>3.14</max_angle>
                <resolution>1</resolution>
              </horizontal>
              <vertical>
                <samples>1</samples>
                <min_angle>0</min_angle>
                <max_angle>0</max_angle>
              </vertical>
            </scan>
            <range>
              <min>0.3</min>
              <max>12</max>
            </range>
          </ray>
          <plugin name='lidar_r_controller' filename='libgazebo_ros_ray_sensor.so'>
            <ros>
              <argument>~/out:=scan</argument>
            </ros>
            <output_type>sensor_msgs/LaserScan</output_type>
            <frame_name>lidar_r</frame_name>
          </plugin>
          <pose>1.35 -0.4 1 0 -0 0</pose>
        </sensor>
        <self_collide>0</self_collide>
        <enable_wind>0</enable_wind>
        <kinematic>0</kinematic>
      </link>
      <joint name='cart_joint' type='revolute'>
        <pose relative_to='base_link'>-1.8334 0 0 0 -0 3.14159</pose>
        <parent>base_link</parent>
        <child>cart</child>
        <axis>
          <xyz>0 0 1</xyz>
          <limit>
            <lower>-1.57</lower>
            <upper>1.57</upper>
            <effort>10</effort>
            <velocity>1</velocity>
          </limit>
          <dynamics>
            <spring_reference>0</spring_reference>
            <spring_stiffness>0</spring_stiffness>
          </dynamics>
        </axis>
      </joint>
      <link name='cart'>
        <pose relative_to='cart_joint'>0 0 0 0 -0 0</pose>
        <inertial>
          <pose>0.896937 0 1.12144 0 -0 0</pose>
          <mass>50.6</mass>
          <inertia>
            <ixx>16.8543</ixx>
            <ixy>0.10725</ixy>
            <ixz>-0.0260736</ixz>
            <iyy>56.6273</iyy>
            <iyz>0.0942592</iyz>
            <izz>54.3634</izz>
          </inertia>
        </inertial>
        <collision name='cart_collision'>
          <pose>0.9 0 1.12 0 -0 0</pose>
          <geometry>
            <box>
              <size>3.315 1.3 1.5</size>
            </box>
          </geometry>
          <max_contacts>10</max_contacts>
          <surface>
            <contact>
              <ode/>
            </contact>
            <bounce/>
            <friction>
              <torsional>
                <ode/>
              </torsional>
              <ode/>
            </friction>
          </surface>
        </collision>
        <collision name='cart_fixed_joint_lump__ultrasonic_t1l1_collision_1'>
          <pose>-0.7 -0.65 1 0 0 -1.5708</pose>
          <geometry>
            <cylinder>
              <length>0.05</length>
              <radius>0.01</radius>
            </cylinder>
          </geometry>
          <surface>
            <contact>
              <ode/>
            </contact>
            <friction>
              <ode/>
              <torsional>
                <ode/>
              </torsional>
            </friction>
            <bounce/>
          </surface>
          <max_contacts>10</max_contacts>
        </collision>
        <collision name='cart_fixed_joint_lump__ultrasonic_t1l2_collision_2'>
          <pose>2.5 -0.65 1 0 0 -1.5708</pose>
          <geometry>
            <cylinder>
              <length>0.05</length>
              <radius>0.01</radius>
            </cylinder>
          </geometry>
          <surface>
            <contact>
              <ode/>
            </contact>
            <friction>
              <ode/>
              <torsional>
                <ode/>
              </torsional>
            </friction>
            <bounce/>
          </surface>
          <max_contacts>10</max_contacts>
        </collision>
        <collision name='cart_fixed_joint_lump__ultrasonic_t1l3_collision_3'>
          <pose>0.95 -0.65 2.45 0 0.785398 -1.5708</pose>
          <geometry>
            <cylinder>
              <length>0.05</length>
              <radius>0.01</radius>
            </cylinder>
          </geometry>
          <surface>
            <contact>
              <ode/>
            </contact>
            <friction>
              <ode/>
              <torsional>
                <ode/>
              </torsional>
            </friction>
            <bounce/>
          </surface>
          <max_contacts>10</max_contacts>
        </collision>
        <collision name='cart_fixed_joint_lump__ultrasonic_t1r1_collision_4'>
          <pose>-0.7 0.65 1 0 -0 1.5708</pose>
          <geometry>
            <cylinder>
              <length>0.05</length>
              <radius>0.01</radius>
            </cylinder>
          </geometry>
          <surface>
            <contact>
              <ode/>
            </contact>
            <friction>
              <ode/>
              <torsional>
                <ode/>
              </torsional>
            </friction>
            <bounce/>
          </surface>
          <max_contacts>10</max_contacts>
        </collision>
        <collision name='cart_fixed_joint_lump__ultrasonic_t1r2_collision_5'>
          <pose>2.5 0.65 1 0 -0 1.5708</pose>
          <geometry>
            <cylinder>
              <length>0.05</length>
              <radius>0.01</radius>
            </cylinder>
          </geometry>
          <surface>
            <contact>
              <ode/>
            </contact>
            <friction>
              <ode/>
              <torsional>
                <ode/>
              </torsional>
            </friction>
            <bounce/>
          </surface>
          <max_contacts>10</max_contacts>
        </collision>
        <collision name='cart_fixed_joint_lump__ultrasonic_t1r3_collision_6'>
          <pose>-0.7 0.65 1 0 -0 1.5708</pose>
          <geometry>
            <cylinder>
              <length>0.05</length>
              <radius>0.01</radius>
            </cylinder>
          </geometry>
          <surface>
            <contact>
              <ode/>
            </contact>
            <friction>
              <ode/>
              <torsional>
                <ode/>
              </torsional>
            </friction>
            <bounce/>
          </surface>
          <max_contacts>10</max_contacts>
        </collision>
        <visual name='cart_visual'>
          <pose>0.9 0 0.7 0 -0 0</pose>
          <geometry>
            <box>
              <size>3.315 1.3 1.5</size>
            </box>
          </geometry>
        </visual>
        <visual name='cart_fixed_joint_lump__ultrasonic_t1l1_visual_1'>
          <pose>-0.7 -0.65 1 0 0 -1.5708</pose>
          <geometry>
            <cylinder>
              <length>0.05</length>
              <radius>0.01</radius>
            </cylinder>
          </geometry>
          <material>
            <script>
              <name>Gazebo/Green</name>
              <uri>file://media/materials/scripts/gazebo.material</uri>
            </script>
          </material>
        </visual>
        <visual name='cart_fixed_joint_lump__ultrasonic_t1l2_visual_2'>
          <pose>2.5 -0.65 1 0 0 -1.5708</pose>
          <geometry>
            <cylinder>
              <length>0.05</length>
              <radius>0.01</radius>
            </cylinder>
          </geometry>
          <material>
            <script>
              <name>Gazebo/LightGrey</name>
              <uri>file://media/materials/scripts/gazebo.material</uri>
            </script>
          </material>
        </visual>
        <visual name='cart_fixed_joint_lump__ultrasonic_t1l3_visual_3'>
          <pose>0.95 -0.65 2.45 0 0.785398 -1.5708</pose>
          <geometry>
            <cylinder>
              <length>0.05</length>
              <radius>0.01</radius>
            </cylinder>
          </geometry>
          <material>
            <script>
              <name>ambient</name>
              <uri>file://media/materials/scripts/gazebo.material</uri>
            </script>
          </material>
        </visual>
        <visual name='cart_fixed_joint_lump__ultrasonic_t1r1_visual_4'>
          <pose>-0.7 0.65 1 0 -0 1.5708</pose>
          <geometry>
            <cylinder>
              <length>0.05</length>
              <radius>0.01</radius>
            </cylinder>
          </geometry>
          <material>
            <script>
              <name>Gazebo/Brown</name>
              <uri>file://media/materials/scripts/gazebo.material</uri>
            </script>
          </material>
        </visual>
        <visual name='cart_fixed_joint_lump__ultrasonic_t1r2_visual_5'>
          <pose>2.5 0.65 1 0 -0 1.5708</pose>
          <geometry>
            <cylinder>
              <length>0.05</length>
              <radius>0.01</radius>
            </cylinder>
          </geometry>
          <material>
            <script>
              <name>Gazebo/DarkGrey</name>
              <uri>file://media/materials/scripts/gazebo.material</uri>
            </script>
          </material>
        </visual>
        <visual name='cart_fixed_joint_lump__ultrasonic_t1r3_visual_6'>
          <pose>-0.7 0.65 1 0 -0 1.5708</pose>
          <geometry>
            <cylinder>
              <length>0.05</length>
              <radius>0.01</radius>
            </cylinder>
          </geometry>
          <material>
            <script>
              <name>ambient</name>
              <uri>file://media/materials/scripts/gazebo.material</uri>
            </script>
          </material>
        </visual>
        <sensor name='ultrasonic_t1l1' type='ray'>
          <visualize>1</visualize>
          <update_rate>10</update_rate>
          <ray>
            <scan>
              <horizontal>
                <samples>15</samples>
                <min_angle>-0.4363</min_angle>
                <max_angle>0.4363</max_angle>
                <resolution>1</resolution>
              </horizontal>
              <vertical>
                <samples>1</samples>
                <min_angle>0</min_angle>
                <max_angle>0</max_angle>
              </vertical>
            </scan>
            <range>
              <min>0.3</min>
              <max>3.6</max>
            </range>
          </ray>
          <plugin name='ultrasonic_t1l1_controller' filename='libgazebo_ros_ray_sensor.so'>
            <ros>
              <argument>~/out:=scan</argument>
            </ros>
            <output_type>sensor_msgs/LaserScan</output_type>
            <frame_name>ultrasonic_t1l1</frame_name>
          </plugin>
          <pose>-0.7 -0.65 1 0 0 -1.5708</pose>
        </sensor>
        <sensor name='ultrasonic_t1l2' type='ray'>
          <visualize>1</visualize>
          <update_rate>10</update_rate>
          <ray>
            <scan>
              <horizontal>
                <samples>15</samples>
                <min_angle>-0.4363</min_angle>
                <max_angle>0.4363</max_angle>
                <resolution>1</resolution>
              </horizontal>
              <vertical>
                <samples>1</samples>
                <min_angle>0</min_angle>
                <max_angle>0</max_angle>
              </vertical>
            </scan>
            <range>
              <min>0.3</min>
              <max>3.6</max>
            </range>
          </ray>
          <plugin name='ultrasonic_t1l2_controller' filename='libgazebo_ros_ray_sensor.so'>
            <ros>
              <argument>~/out:=scan</argument>
            </ros>
            <output_type>sensor_msgs/LaserScan</output_type>
            <frame_name>ultrasonic_t1l2</frame_name>
          </plugin>
          <pose>2.5 -0.65 1 0 0 -1.5708</pose>
        </sensor>
        <sensor name='ultrasonic_t1l3' type='ray'>
          <visualize>1</visualize>
          <update_rate>10</update_rate>
          <ray>
            <scan>
              <horizontal>
                <samples>15</samples>
                <min_angle>-0.4363</min_angle>
                <max_angle>0.4363</max_angle>
                <resolution>1</resolution>
              </horizontal>
              <vertical>
                <samples>1</samples>
                <min_angle>0</min_angle>
                <max_angle>0</max_angle>
              </vertical>
            </scan>
            <range>
              <min>0.3</min>
              <max>3.6</max>
            </range>
          </ray>
          <plugin name='ultrasonic_t1l3_controller' filename='libgazebo_ros_ray_sensor.so'>
            <ros>
              <argument>~/out:=scan</argument>
            </ros>
            <output_type>sensor_msgs/LaserScan</output_type>
            <frame_name>ultrasonic_t1l3</frame_name>
          </plugin>
          <pose>0.95 -0.65 2.45 0 0.785398 -1.5708</pose>
        </sensor>
        <sensor name='ultrasonic_t1r1' type='ray'>
          <visualize>1</visualize>
          <update_rate>10</update_rate>
          <ray>
            <scan>
              <horizontal>
                <samples>15</samples>
                <min_angle>-0.4363</min_angle>
                <max_angle>0.4363</max_angle>
                <resolution>1</resolution>
              </horizontal>
              <vertical>
                <samples>1</samples>
                <min_angle>0</min_angle>
                <max_angle>0</max_angle>
              </vertical>
            </scan>
            <range>
              <min>0.3</min>
              <max>3.6</max>
            </range>
          </ray>
          <plugin name='ultrasonic_t1r1_controller' filename='libgazebo_ros_ray_sensor.so'>
            <ros>
              <argument>~/out:=scan</argument>
            </ros>
            <output_type>sensor_msgs/LaserScan</output_type>
            <frame_name>ultrasonic_t1r1</frame_name>
          </plugin>
          <pose>-0.7 0.65 1 0 -0 1.5708</pose>
        </sensor>
        <sensor name='ultrasonic_t1r2' type='ray'>
          <visualize>1</visualize>
          <update_rate>10</update_rate>
          <ray>
            <scan>
              <horizontal>
                <samples>15</samples>
                <min_angle>-0.4363</min_angle>
                <max_angle>0.4363</max_angle>
                <resolution>1</resolution>
              </horizontal>
              <vertical>
                <samples>1</samples>
                <min_angle>0</min_angle>
                <max_angle>0</max_angle>
              </vertical>
            </scan>
            <range>
              <min>0.3</min>
              <max>3.6</max>
            </range>
          </ray>
          <plugin name='ultrasonic_t1r2_controller' filename='libgazebo_ros_ray_sensor.so'>
            <ros>
              <argument>~/out:=scan</argument>
            </ros>
            <output_type>sensor_msgs/LaserScan</output_type>
            <frame_name>ultrasonic_t1r2</frame_name>
          </plugin>
          <pose>2.5 0.65 1 0 -0 1.5708</pose>
        </sensor>
        <sensor name='ultrasonic_t1r3' type='ray'>
          <visualize>1</visualize>
          <update_rate>10</update_rate>
          <ray>
            <scan>
              <horizontal>
                <samples>15</samples>
                <min_angle>-0.4363</min_angle>
                <max_angle>0.4363</max_angle>
                <resolution>1</resolution>
              </horizontal>
              <vertical>
                <samples>1</samples>
                <min_angle>0</min_angle>
                <max_angle>0</max_angle>
              </vertical>
            </scan>
            <range>
              <min>0.3</min>
              <max>3.6</max>
            </range>
          </ray>
          <plugin name='ultrasonic_t1r3_controller' filename='libgazebo_ros_ray_sensor.so'>
            <ros>
              <argument>~/out:=scan</argument>
            </ros>
            <output_type>sensor_msgs/LaserScan</output_type>
            <frame_name>ultrasonic_t1r3</frame_name>
          </plugin>
          <pose>-0.7 0.65 1 0 -0 1.5708</pose>
        </sensor>
        <self_collide>0</self_collide>
        <enable_wind>0</enable_wind>
        <kinematic>0</kinematic>
      </link>
      <joint name='cart2_joint' type='revolute'>
        <pose relative_to='cart'>3.2334 0 0 0 -0 0</pose>
        <parent>cart</parent>
        <child>cart2</child>
        <axis>
          <xyz>0 0 1</xyz>
          <limit>
            <lower>-1.57</lower>
            <upper>1.57</upper>
            <effort>10</effort>
            <velocity>1</velocity>
          </limit>
          <dynamics>
            <spring_reference>0</spring_reference>
            <spring_stiffness>0</spring_stiffness>
          </dynamics>
        </axis>
      </joint>
      <link name='cart2'>
        <pose relative_to='cart2_joint'>0 0 0 0 -0 0</pose>
        <inertial>
          <pose>0.9 -0 1.11765 0 -0 0</pose>
          <mass>20.4</mass>
          <inertia>
            <ixx>5.93024</ixx>
            <ixy>-2.63678e-17</ixy>
            <ixz>0</ixz>
            <iyy>9.41174</iyy>
            <iyz>-1.55105e-17</iyz>
            <izz>7.83052</izz>
          </inertia>
        </inertial>
        <collision name='cart2_collision'>
          <pose>0.9 0 1.12 0 -0 0</pose>
          <geometry>
            <box>
              <size>1.8 1.11 1.5</size>
            </box>
          </geometry>
          <max_contacts>10</max_contacts>
          <surface>
            <contact>
              <ode/>
            </contact>
            <bounce/>
            <friction>
              <torsional>
                <ode/>
              </torsional>
              <ode/>
            </friction>
          </surface>
        </collision>
        <collision name='cart2_fixed_joint_lump__ultrasonic_t2l1_collision_1'>
          <pose>0.1 -0.55 1 0 0 -1.5708</pose>
          <geometry>
            <cylinder>
              <length>0.05</length>
              <radius>0.01</radius>
            </cylinder>
          </geometry>
          <surface>
            <contact>
              <ode/>
            </contact>
            <friction>
              <ode/>
              <torsional>
                <ode/>
              </torsional>
            </friction>
            <bounce/>
          </surface>
          <max_contacts>10</max_contacts>
        </collision>
        <collision name='cart2_fixed_joint_lump__ultrasonic_t2l2_collision_2'>
          <pose>1.7 -0.55 1 0 0 -1.5708</pose>
          <geometry>
            <cylinder>
              <length>0.05</length>
              <radius>0.01</radius>
            </cylinder>
          </geometry>
          <surface>
            <contact>
              <ode/>
            </contact>
            <friction>
              <ode/>
              <torsional>
                <ode/>
              </torsional>
            </friction>
            <bounce/>
          </surface>
          <max_contacts>10</max_contacts>
        </collision>
        <collision name='cart2_fixed_joint_lump__ultrasonic_t2r1_collision_3'>
          <pose>0.1 0.55 1 0 -0 1.5708</pose>
          <geometry>
            <cylinder>
              <length>0.05</length>
              <radius>0.01</radius>
            </cylinder>
          </geometry>
          <surface>
            <contact>
              <ode/>
            </contact>
            <friction>
              <ode/>
              <torsional>
                <ode/>
              </torsional>
            </friction>
            <bounce/>
          </surface>
          <max_contacts>10</max_contacts>
        </collision>
        <collision name='cart2_fixed_joint_lump__ultrasonic_t2r2_collision_4'>
          <pose>1.7 0.55 1 0 -0 1.5708</pose>
          <geometry>
            <cylinder>
              <length>0.05</length>
              <radius>0.01</radius>
            </cylinder>
          </geometry>
          <surface>
            <contact>
              <ode/>
            </contact>
            <friction>
              <ode/>
              <torsional>
                <ode/>
              </torsional>
            </friction>
            <bounce/>
          </surface>
          <max_contacts>10</max_contacts>
        </collision>
        <visual name='cart2_visual'>
          <pose>0.9 0 0.7 0 -0 0</pose>
          <geometry>
            <box>
              <size>1.8 1.11 1.5</size>
            </box>
          </geometry>
        </visual>
        <visual name='cart2_fixed_joint_lump__ultrasonic_t2l1_visual_1'>
          <pose>0.1 -0.55 1 0 0 -1.5708</pose>
          <geometry>
            <cylinder>
              <length>0.05</length>
              <radius>0.01</radius>
            </cylinder>
          </geometry>
          <material>
            <script>
              <name>ambient</name>
              <uri>file://media/materials/scripts/gazebo.material</uri>
            </script>
          </material>
        </visual>
        <visual name='cart2_fixed_joint_lump__ultrasonic_t2l2_visual_2'>
          <pose>1.7 -0.55 1 0 0 -1.5708</pose>
          <geometry>
            <cylinder>
              <length>0.05</length>
              <radius>0.01</radius>
            </cylinder>
          </geometry>
          <material>
            <script>
              <name>ambient</name>
              <uri>file://media/materials/scripts/gazebo.material</uri>
            </script>
          </material>
        </visual>
        <visual name='cart2_fixed_joint_lump__ultrasonic_t2r1_visual_3'>
          <pose>0.1 0.55 1 0 -0 1.5708</pose>
          <geometry>
            <cylinder>
              <length>0.05</length>
              <radius>0.01</radius>
            </cylinder>
          </geometry>
          <material>
            <script>
              <name>ambient</name>
              <uri>file://media/materials/scripts/gazebo.material</uri>
            </script>
          </material>
        </visual>
        <visual name='cart2_fixed_joint_lump__ultrasonic_t2r2_visual_4'>
          <pose>1.7 0.55 1 0 -0 1.5708</pose>
          <geometry>
            <cylinder>
              <length>0.05</length>
              <radius>0.01</radius>
            </cylinder>
          </geometry>
          <material>
            <script>
              <name>ambient</name>
              <uri>file://media/materials/scripts/gazebo.material</uri>
            </script>
          </material>
        </visual>
        <sensor name='ultrasonic_t2l1' type='ray'>
          <visualize>1</visualize>
          <update_rate>10</update_rate>
          <ray>
            <scan>
              <horizontal>
                <samples>15</samples>
                <min_angle>-0.4363</min_angle>
                <max_angle>0.4363</max_angle>
                <resolution>1</resolution>
              </horizontal>
              <vertical>
                <samples>1</samples>
                <min_angle>0</min_angle>
                <max_angle>0</max_angle>
              </vertical>
            </scan>
            <range>
              <min>0.3</min>
              <max>3.6</max>
            </range>
          </ray>
          <plugin name='ultrasonic_t2l1_controller' filename='libgazebo_ros_ray_sensor.so'>
            <ros>
              <argument>~/out:=scan</argument>
            </ros>
            <output_type>sensor_msgs/LaserScan</output_type>
            <frame_name>ultrasonic_t2l1</frame_name>
          </plugin>
          <pose>0.1 -0.55 1 0 0 -1.5708</pose>
        </sensor>
        <sensor name='ultrasonic_t2l2' type='ray'>
          <visualize>1</visualize>
          <update_rate>10</update_rate>
          <ray>
            <scan>
              <horizontal>
                <samples>15</samples>
                <min_angle>-0.4363</min_angle>
                <max_angle>0.4363</max_angle>
                <resolution>1</resolution>
              </horizontal>
              <vertical>
                <samples>1</samples>
                <min_angle>0</min_angle>
                <max_angle>0</max_angle>
              </vertical>
            </scan>
            <range>
              <min>0.3</min>
              <max>3.6</max>
            </range>
          </ray>
          <plugin name='ultrasonic_t2l2_controller' filename='libgazebo_ros_ray_sensor.so'>
            <ros>
              <argument>~/out:=scan</argument>
            </ros>
            <output_type>sensor_msgs/LaserScan</output_type>
            <frame_name>ultrasonic_t2l2</frame_name>
          </plugin>
          <pose>1.7 -0.55 1 0 0 -1.5708</pose>
        </sensor>
        <sensor name='ultrasonic_t2r1' type='ray'>
          <visualize>1</visualize>
          <update_rate>10</update_rate>
          <ray>
            <scan>
              <horizontal>
                <samples>15</samples>
                <min_angle>-0.4363</min_angle>
                <max_angle>0.4363</max_angle>
                <resolution>1</resolution>
              </horizontal>
              <vertical>
                <samples>1</samples>
                <min_angle>0</min_angle>
                <max_angle>0</max_angle>
              </vertical>
            </scan>
            <range>
              <min>0.3</min>
              <max>3.6</max>
            </range>
          </ray>
          <plugin name='ultrasonic_t2r1_controller' filename='libgazebo_ros_ray_sensor.so'>
            <ros>
              <argument>~/out:=scan</argument>
            </ros>
            <output_type>sensor_msgs/LaserScan</output_type>
            <frame_name>ultrasonic_t2r1</frame_name>
          </plugin>
          <pose>0.1 0.55 1 0 -0 1.5708</pose>
        </sensor>
        <sensor name='ultrasonic_t2r2' type='ray'>
          <visualize>1</visualize>
          <update_rate>10</update_rate>
          <ray>
            <scan>
              <horizontal>
                <samples>15</samples>
                <min_angle>-0.4363</min_angle>
                <max_angle>0.4363</max_angle>
                <resolution>1</resolution>
              </horizontal>
              <vertical>
                <samples>1</samples>
                <min_angle>0</min_angle>
                <max_angle>0</max_angle>
              </vertical>
            </scan>
            <range>
              <min>0.3</min>
              <max>3.6</max>
            </range>
          </ray>
          <plugin name='ultrasonic_t2r2_controller' filename='libgazebo_ros_ray_sensor.so'>
            <ros>
              <argument>~/out:=scan</argument>
            </ros>
            <output_type>sensor_msgs/LaserScan</output_type>
            <frame_name>ultrasonic_t2r2</frame_name>
          </plugin>
          <pose>1.7 0.55 1 0 -0 1.5708</pose>
        </sensor>
        <self_collide>0</self_collide>
        <enable_wind>0</enable_wind>
        <kinematic>0</kinematic>
      </link>
      <joint name='cart2_left_wheel_joint' type='revolute'>
        <pose relative_to='cart2'>1.6 0.7 0 -1.5708 0 0</pose>
        <parent>cart2</parent>
        <child>cart2_left_wheel</child>
        <axis>
          <xyz>0 0 1</xyz>
          <limit>
            <lower>-1e+16</lower>
            <upper>1e+16</upper>
          </limit>
          <dynamics>
            <spring_reference>0</spring_reference>
            <spring_stiffness>0</spring_stiffness>
          </dynamics>
        </axis>
      </joint>
      <link name='cart2_left_wheel'>
        <pose relative_to='cart2_left_wheel_joint'>0 0 0 0 -0 0</pose>
        <inertial>
          <pose>0 0 0 0 -0 0</pose>
          <mass>5</mass>
          <inertia>
            <ixx>0.0447917</ixx>
            <ixy>0</ixy>
            <ixz>0</ixz>
            <iyy>0.0447917</iyy>
            <iyz>0</iyz>
            <izz>0.05625</izz>
          </inertia>
        </inertial>
        <collision name='cart2_left_wheel_collision'>
          <pose>0 0 0 0 -0 0</pose>
          <geometry>
            <cylinder>
              <length>0.2</length>
              <radius>0.15</radius>
            </cylinder>
          </geometry>
          <surface>
            <contact>
              <ode/>
            </contact>
            <friction>
              <ode/>
              <torsional>
                <ode/>
              </torsional>
            </friction>
            <bounce/>
          </surface>
          <max_contacts>10</max_contacts>
        </collision>
        <visual name='cart2_left_wheel_visual'>
          <pose>0 0 0 0 -0 0</pose>
          <geometry>
            <cylinder>
              <length>0.2</length>
              <radius>0.15</radius>
            </cylinder>
          </geometry>
          <material>
            <script>
              <name>Gazebo/Blue</name>
              <uri>file://media/materials/scripts/gazebo.material</uri>
            </script>
          </material>
        </visual>
        <self_collide>0</self_collide>
        <enable_wind>0</enable_wind>
        <kinematic>0</kinematic>
      </link>
      <joint name='cart2_right_wheel_joint' type='revolute'>
        <pose relative_to='cart2'>1.6 -0.7 0 1.5708 -0 0</pose>
        <parent>cart2</parent>
        <child>cart2_right_wheel</child>
        <axis>
          <xyz>0 0 -1</xyz>
          <limit>
            <lower>-1e+16</lower>
            <upper>1e+16</upper>
          </limit>
          <dynamics>
            <spring_reference>0</spring_reference>
            <spring_stiffness>0</spring_stiffness>
          </dynamics>
        </axis>
      </joint>
      <link name='cart2_right_wheel'>
        <pose relative_to='cart2_right_wheel_joint'>0 0 0 0 -0 0</pose>
        <inertial>
          <pose>0 0 0 0 -0 0</pose>
          <mass>5</mass>
          <inertia>
            <ixx>0.0447917</ixx>
            <ixy>0</ixy>
            <ixz>0</ixz>
            <iyy>0.0447917</iyy>
            <iyz>0</iyz>
            <izz>0.05625</izz>
          </inertia>
        </inertial>
        <collision name='cart2_right_wheel_collision'>
          <pose>0 0 0 0 -0 0</pose>
          <geometry>
            <cylinder>
              <length>0.2</length>
              <radius>0.15</radius>
            </cylinder>
          </geometry>
          <surface>
            <contact>
              <ode/>
            </contact>
            <friction>
              <ode/>
              <torsional>
                <ode/>
              </torsional>
            </friction>
            <bounce/>
          </surface>
          <max_contacts>10</max_contacts>
        </collision>
        <visual name='cart2_right_wheel_visual'>
          <pose>0 0 0 0 -0 0</pose>
          <geometry>
            <cylinder>
              <length>0.2</length>
              <radius>0.15</radius>
            </cylinder>
          </geometry>
          <material>
            <script>
              <name>Gazebo/Blue</name>
              <uri>file://media/materials/scripts/gazebo.material</uri>
            </script>
          </material>
        </visual>
        <self_collide>0</self_collide>
        <enable_wind>0</enable_wind>
        <kinematic>0</kinematic>
      </link>
      <joint name='cart3_joint' type='revolute'>
        <pose relative_to='cart2'>2.7334 0 0 0 -0 0</pose>
        <parent>cart2</parent>
        <child>cart3</child>
        <axis>
          <xyz>0 0 1</xyz>
          <limit>
            <lower>-1.57</lower>
            <upper>1.57</upper>
            <effort>10</effort>
            <velocity>1</velocity>
          </limit>
          <dynamics>
            <spring_reference>0</spring_reference>
            <spring_stiffness>0</spring_stiffness>
          </dynamics>
        </axis>
      </joint>
      <link name='cart3'>
        <pose relative_to='cart3_joint'>0 0 0 0 -0 0</pose>
        <inertial>
          <pose>0.899755 0 1.11765 0 -0 0</pose>
          <mass>20.4</mass>
          <inertia>
            <ixx>4.78888</ixx>
            <ixy>1.38778e-17</ixy>
            <ixz>-0.000588235</ixz>
            <iyy>10.957</iyy>
            <iyz>0</iyz>
            <izz>8.23445</izz>
          </inertia>
        </inertial>
        <collision name='cart3_collision'>
          <pose>0.9 0 1.12 0 -0 0</pose>
          <geometry>
            <box>
              <size>2.03 0.765 1.5</size>
            </box>
          </geometry>
          <max_contacts>10</max_contacts>
          <surface>
            <contact>
              <ode/>
            </contact>
            <bounce/>
            <friction>
              <torsional>
                <ode/>
              </torsional>
              <ode/>
            </friction>
          </surface>
        </collision>
        <collision name='cart3_fixed_joint_lump__ultrasonic_t3l1_collision_1'>
          <pose>-0.025 -0.38 1 0 0 -1.5708</pose>
          <geometry>
            <cylinder>
              <length>0.05</length>
              <radius>0.01</radius>
            </cylinder>
          </geometry>
          <surface>
            <contact>
              <ode/>
            </contact>
            <friction>
              <ode/>
              <torsional>
                <ode/>
              </torsional>
            </friction>
            <bounce/>
          </surface>
          <max_contacts>10</max_contacts>
        </collision>
        <collision name='cart3_fixed_joint_lump__ultrasonic_t3l2_collision_2'>
          <pose>1.8 -0.38 1 0 0 -1.5708</pose>
          <geometry>
            <cylinder>
              <length>0.05</length>
              <radius>0.01</radius>
            </cylinder>
          </geometry>
          <surface>
            <contact>
              <ode/>
            </contact>
            <friction>
              <ode/>
              <torsional>
                <ode/>
              </torsional>
            </friction>
            <bounce/>
          </surface>
          <max_contacts>10</max_contacts>
        </collision>
        <collision name='cart3_fixed_joint_lump__ultrasonic_t3r1_collision_3'>
          <pose>-0.025 0.38 1 0 -0 1.5708</pose>
          <geometry>
            <cylinder>
              <length>0.05</length>
              <radius>0.01</radius>
            </cylinder>
          </geometry>
          <surface>
            <contact>
              <ode/>
            </contact>
            <friction>
              <ode/>
              <torsional>
                <ode/>
              </torsional>
            </friction>
            <bounce/>
          </surface>
          <max_contacts>10</max_contacts>
        </collision>
        <collision name='cart3_fixed_joint_lump__ultrasonic_t3r2_collision_4'>
          <pose>1.8 0.38 1 0 -0 1.5708</pose>
          <geometry>
            <cylinder>
              <length>0.05</length>
              <radius>0.01</radius>
            </cylinder>
          </geometry>
          <surface>
            <contact>
              <ode/>
            </contact>
            <friction>
              <ode/>
              <torsional>
                <ode/>
              </torsional>
            </friction>
            <bounce/>
          </surface>
          <max_contacts>10</max_contacts>
        </collision>
        <visual name='cart3_visual'>
          <pose>0.9 0 0.7 0 -0 0</pose>
          <geometry>
            <box>
              <size>2.03 0.765 1.5</size>
            </box>
          </geometry>
        </visual>
        <visual name='cart3_fixed_joint_lump__ultrasonic_t3l1_visual_1'>
          <pose>-0.025 -0.38 1 0 0 -1.5708</pose>
          <geometry>
            <cylinder>
              <length>0.05</length>
              <radius>0.01</radius>
            </cylinder>
          </geometry>
          <material>
            <script>
              <name>ambient</name>
              <uri>file://media/materials/scripts/gazebo.material</uri>
            </script>
          </material>
        </visual>
        <visual name='cart3_fixed_joint_lump__ultrasonic_t3l2_visual_2'>
          <pose>1.8 -0.38 1 0 0 -1.5708</pose>
          <geometry>
            <cylinder>
              <length>0.05</length>
              <radius>0.01</radius>
            </cylinder>
          </geometry>
          <material>
            <script>
              <name>ambient</name>
              <uri>file://media/materials/scripts/gazebo.material</uri>
            </script>
          </material>
        </visual>
        <visual name='cart3_fixed_joint_lump__ultrasonic_t3r1_visual_3'>
          <pose>-0.025 0.38 1 0 -0 1.5708</pose>
          <geometry>
            <cylinder>
              <length>0.05</length>
              <radius>0.01</radius>
            </cylinder>
          </geometry>
          <material>
            <script>
              <name>ambient</name>
              <uri>file://media/materials/scripts/gazebo.material</uri>
            </script>
          </material>
        </visual>
        <visual name='cart3_fixed_joint_lump__ultrasonic_t3r2_visual_4'>
          <pose>1.8 0.38 1 0 -0 1.5708</pose>
          <geometry>
            <cylinder>
              <length>0.05</length>
              <radius>0.01</radius>
            </cylinder>
          </geometry>
          <material>
            <script>
              <name>ambient</name>
              <uri>file://media/materials/scripts/gazebo.material</uri>
            </script>
          </material>
        </visual>
        <sensor name='ultrasonic_t3l1' type='ray'>
          <visualize>1</visualize>
          <update_rate>10</update_rate>
          <ray>
            <scan>
              <horizontal>
                <samples>15</samples>
                <min_angle>-0.4363</min_angle>
                <max_angle>0.4363</max_angle>
                <resolution>1</resolution>
              </horizontal>
              <vertical>
                <samples>1</samples>
                <min_angle>0</min_angle>
                <max_angle>0</max_angle>
              </vertical>
            </scan>
            <range>
              <min>0.3</min>
              <max>3.6</max>
            </range>
          </ray>
          <plugin name='ultrasonic_t3l1_controller' filename='libgazebo_ros_ray_sensor.so'>
            <ros>
              <argument>~/out:=scan</argument>
            </ros>
            <output_type>sensor_msgs/LaserScan</output_type>
            <frame_name>ultrasonic_t3l1</frame_name>
          </plugin>
          <pose>-0.025 -0.38 1 0 0 -1.5708</pose>
        </sensor>
        <sensor name='ultrasonic_t3l2' type='ray'>
          <visualize>1</visualize>
          <update_rate>10</update_rate>
          <ray>
            <scan>
              <horizontal>
                <samples>15</samples>
                <min_angle>-0.4363</min_angle>
                <max_angle>0.4363</max_angle>
                <resolution>1</resolution>
              </horizontal>
              <vertical>
                <samples>1</samples>
                <min_angle>0</min_angle>
                <max_angle>0</max_angle>
              </vertical>
            </scan>
            <range>
              <min>0.3</min>
              <max>3.6</max>
            </range>
          </ray>
          <plugin name='ultrasonic_t3l2_controller' filename='libgazebo_ros_ray_sensor.so'>
            <ros>
              <argument>~/out:=scan</argument>
            </ros>
            <output_type>sensor_msgs/LaserScan</output_type>
            <frame_name>ultrasonic_t3l2</frame_name>
          </plugin>
          <pose>1.8 -0.38 1 0 0 -1.5708</pose>
        </sensor>
        <sensor name='ultrasonic_t3r1' type='ray'>
          <visualize>1</visualize>
          <update_rate>10</update_rate>
          <ray>
            <scan>
              <horizontal>
                <samples>15</samples>
                <min_angle>-0.4363</min_angle>
                <max_angle>0.4363</max_angle>
                <resolution>1</resolution>
              </horizontal>
              <vertical>
                <samples>1</samples>
                <min_angle>0</min_angle>
                <max_angle>0</max_angle>
              </vertical>
            </scan>
            <range>
              <min>0.3</min>
              <max>3.6</max>
            </range>
          </ray>
          <plugin name='ultrasonic_t3r1_controller' filename='libgazebo_ros_ray_sensor.so'>
            <ros>
              <argument>~/out:=scan</argument>
            </ros>
            <output_type>sensor_msgs/LaserScan</output_type>
            <frame_name>ultrasonic_t3r1</frame_name>
          </plugin>
          <pose>-0.025 0.38 1 0 -0 1.5708</pose>
        </sensor>
        <sensor name='ultrasonic_t3r2' type='ray'>
          <visualize>1</visualize>
          <update_rate>10</update_rate>
          <ray>
            <scan>
              <horizontal>
                <samples>15</samples>
                <min_angle>-0.4363</min_angle>
                <max_angle>0.4363</max_angle>
                <resolution>1</resolution>
              </horizontal>
              <vertical>
                <samples>1</samples>
                <min_angle>0</min_angle>
                <max_angle>0</max_angle>
              </vertical>
            </scan>
            <range>
              <min>0.3</min>
              <max>3.6</max>
            </range>
          </ray>
          <plugin name='ultrasonic_t3r2_controller' filename='libgazebo_ros_ray_sensor.so'>
            <ros>
              <argument>~/out:=scan</argument>
            </ros>
            <output_type>sensor_msgs/LaserScan</output_type>
            <frame_name>ultrasonic_t3r2</frame_name>
          </plugin>
          <pose>1.8 0.38 1 0 -0 1.5708</pose>
        </sensor>
        <self_collide>0</self_collide>
        <enable_wind>0</enable_wind>
        <kinematic>0</kinematic>
      </link>
      <joint name='cart3_left_wheel_joint' type='revolute'>
        <pose relative_to='cart3'>1.6 0.55 0 -1.5708 0 0</pose>
        <parent>cart3</parent>
        <child>cart3_left_wheel</child>
        <axis>
          <xyz>0 0 1</xyz>
          <limit>
            <lower>-1e+16</lower>
            <upper>1e+16</upper>
          </limit>
          <dynamics>
            <spring_reference>0</spring_reference>
            <spring_stiffness>0</spring_stiffness>
          </dynamics>
        </axis>
      </joint>
      <link name='cart3_left_wheel'>
        <pose relative_to='cart3_left_wheel_joint'>0 0 0 0 -0 0</pose>
        <inertial>
          <pose>0 0 0 0 -0 0</pose>
          <mass>5</mass>
          <inertia>
            <ixx>0.0447917</ixx>
            <ixy>0</ixy>
            <ixz>0</ixz>
            <iyy>0.0447917</iyy>
            <iyz>0</iyz>
            <izz>0.05625</izz>
          </inertia>
        </inertial>
        <collision name='cart3_left_wheel_collision'>
          <pose>0 0 0 0 -0 0</pose>
          <geometry>
            <cylinder>
              <length>0.2</length>
              <radius>0.15</radius>
            </cylinder>
          </geometry>
          <surface>
            <contact>
              <ode/>
            </contact>
            <friction>
              <ode/>
              <torsional>
                <ode/>
              </torsional>
            </friction>
            <bounce/>
          </surface>
          <max_contacts>10</max_contacts>
        </collision>
        <visual name='cart3_left_wheel_visual'>
          <pose>0 0 0 0 -0 0</pose>
          <geometry>
            <cylinder>
              <length>0.2</length>
              <radius>0.15</radius>
            </cylinder>
          </geometry>
          <material>
            <script>
              <name>Gazebo/Blue</name>
              <uri>file://media/materials/scripts/gazebo.material</uri>
            </script>
          </material>
        </visual>
        <self_collide>0</self_collide>
        <enable_wind>0</enable_wind>
        <kinematic>0</kinematic>
      </link>
      <joint name='cart3_right_wheel_joint' type='revolute'>
        <pose relative_to='cart3'>1.6 -0.55 0 1.5708 -0 0</pose>
        <parent>cart3</parent>
        <child>cart3_right_wheel</child>
        <axis>
          <xyz>0 0 -1</xyz>
          <limit>
            <lower>-1e+16</lower>
            <upper>1e+16</upper>
          </limit>
          <dynamics>
            <spring_reference>0</spring_reference>
            <spring_stiffness>0</spring_stiffness>
          </dynamics>
        </axis>
      </joint>
      <link name='cart3_right_wheel'>
        <pose relative_to='cart3_right_wheel_joint'>0 0 0 0 -0 0</pose>
        <inertial>
          <pose>0 0 0 0 -0 0</pose>
          <mass>5</mass>
          <inertia>
            <ixx>0.0447917</ixx>
            <ixy>0</ixy>
            <ixz>0</ixz>
            <iyy>0.0447917</iyy>
            <iyz>0</iyz>
            <izz>0.05625</izz>
          </inertia>
        </inertial>
        <collision name='cart3_right_wheel_collision'>
          <pose>0 0 0 0 -0 0</pose>
          <geometry>
            <cylinder>
              <length>0.2</length>
              <radius>0.15</radius>
            </cylinder>
          </geometry>
          <surface>
            <contact>
              <ode/>
            </contact>
            <friction>
              <ode/>
              <torsional>
                <ode/>
              </torsional>
            </friction>
            <bounce/>
          </surface>
          <max_contacts>10</max_contacts>
        </collision>
        <visual name='cart3_right_wheel_visual'>
          <pose>0 0 0 0 -0 0</pose>
          <geometry>
            <cylinder>
              <length>0.2</length>
              <radius>0.15</radius>
            </cylinder>
          </geometry>
          <material>
            <script>
              <name>Gazebo/Blue</name>
              <uri>file://media/materials/scripts/gazebo.material</uri>
            </script>
          </material>
        </visual>
        <self_collide>0</self_collide>
        <enable_wind>0</enable_wind>
        <kinematic>0</kinematic>
      </link>
      <joint name='cart_left_wheel_joint' type='revolute'>
        <pose relative_to='cart'>2.2 0.8 0 -1.5708 0 0</pose>
        <parent>cart</parent>
        <child>cart_left_wheel</child>
        <axis>
          <xyz>0 0 1</xyz>
          <limit>
            <lower>-1e+16</lower>
            <upper>1e+16</upper>
          </limit>
          <dynamics>
            <spring_reference>0</spring_reference>
            <spring_stiffness>0</spring_stiffness>
          </dynamics>
        </axis>
      </joint>
      <link name='cart_left_wheel'>
        <pose relative_to='cart_left_wheel_joint'>0 0 0 0 -0 0</pose>
        <inertial>
          <pose>0 0 0 0 -0 0</pose>
          <mass>5</mass>
          <inertia>
            <ixx>0.0447917</ixx>
            <ixy>0</ixy>
            <ixz>0</ixz>
            <iyy>0.0447917</iyy>
            <iyz>0</iyz>
            <izz>0.05625</izz>
          </inertia>
        </inertial>
        <collision name='cart_left_wheel_collision'>
          <pose>0 0 0 0 -0 0</pose>
          <geometry>
            <cylinder>
              <length>0.2</length>
              <radius>0.15</radius>
            </cylinder>
          </geometry>
          <surface>
            <contact>
              <ode/>
            </contact>
            <friction>
              <ode/>
              <torsional>
                <ode/>
              </torsional>
            </friction>
            <bounce/>
          </surface>
          <max_contacts>10</max_contacts>
        </collision>
        <visual name='cart_left_wheel_visual'>
          <pose>0 0 0 0 -0 0</pose>
          <geometry>
            <cylinder>
              <length>0.2</length>
              <radius>0.15</radius>
            </cylinder>
          </geometry>
          <material>
            <script>
              <name>Gazebo/Blue</name>
              <uri>file://media/materials/scripts/gazebo.material</uri>
            </script>
          </material>
        </visual>
        <self_collide>0</self_collide>
        <enable_wind>0</enable_wind>
        <kinematic>0</kinematic>
      </link>
      <joint name='cart_right_wheel_joint' type='revolute'>
        <pose relative_to='cart'>2.2 -0.8 0 1.5708 -0 0</pose>
        <parent>cart</parent>
        <child>cart_right_wheel</child>
        <axis>
          <xyz>0 0 -1</xyz>
          <limit>
            <lower>-1e+16</lower>
            <upper>1e+16</upper>
          </limit>
          <dynamics>
            <spring_reference>0</spring_reference>
            <spring_stiffness>0</spring_stiffness>
          </dynamics>
        </axis>
      </joint>
      <link name='cart_right_wheel'>
        <pose relative_to='cart_right_wheel_joint'>0 0 0 0 -0 0</pose>
        <inertial>
          <pose>0 0 0 0 -0 0</pose>
          <mass>5</mass>
          <inertia>
            <ixx>0.0447917</ixx>
            <ixy>0</ixy>
            <ixz>0</ixz>
            <iyy>0.0447917</iyy>
            <iyz>0</iyz>
            <izz>0.05625</izz>
          </inertia>
        </inertial>
        <collision name='cart_right_wheel_collision'>
          <pose>0 0 0 0 -0 0</pose>
          <geometry>
            <cylinder>
              <length>0.2</length>
              <radius>0.15</radius>
            </cylinder>
          </geometry>
          <surface>
            <contact>
              <ode/>
            </contact>
            <friction>
              <ode/>
              <torsional>
                <ode/>
              </torsional>
            </friction>
            <bounce/>
          </surface>
          <max_contacts>10</max_contacts>
        </collision>
        <visual name='cart_right_wheel_visual'>
          <pose>0 0 0 0 -0 0</pose>
          <geometry>
            <cylinder>
              <length>0.2</length>
              <radius>0.15</radius>
            </cylinder>
          </geometry>
          <material>
            <script>
              <name>Gazebo/Blue</name>
              <uri>file://media/materials/scripts/gazebo.material</uri>
            </script>
          </material>
        </visual>
        <self_collide>0</self_collide>
        <enable_wind>0</enable_wind>
        <kinematic>0</kinematic>
      </link>
      <joint name='left_wheel_joint' type='revolute'>
        <pose relative_to='base_link'>0 0.5 0 -1.5708 0 0</pose>
        <parent>base_link</parent>
        <child>left_wheel</child>
        <axis>
          <xyz>0 0 1</xyz>
          <limit>
            <lower>-1e+16</lower>
            <upper>1e+16</upper>
          </limit>
          <dynamics>
            <spring_reference>0</spring_reference>
            <spring_stiffness>0</spring_stiffness>
          </dynamics>
        </axis>
      </joint>
      <link name='left_wheel'>
        <pose relative_to='left_wheel_joint'>0 0 0 0 -0 0</pose>
        <inertial>
          <pose>0 0 0 0 -0 0</pose>
          <mass>5</mass>
          <inertia>
            <ixx>0.0541667</ixx>
            <ixy>0</ixy>
            <ixz>0</ixz>
            <iyy>0.0541667</iyy>
            <iyz>0</iyz>
            <izz>0.1</izz>
          </inertia>
        </inertial>
        <collision name='left_wheel_collision'>
          <pose>0 0 0 0 -0 0</pose>
          <geometry>
            <cylinder>
              <length>0.1</length>
              <radius>0.2</radius>
            </cylinder>
          </geometry>
          <surface>
            <contact>
              <ode/>
            </contact>
            <friction>
              <ode/>
              <torsional>
                <ode/>
              </torsional>
            </friction>
            <bounce/>
          </surface>
          <max_contacts>10</max_contacts>
        </collision>
        <visual name='left_wheel_visual'>
          <pose>0 0 0 0 -0 0</pose>
          <geometry>
            <cylinder>
              <length>0.1</length>
              <radius>0.2</radius>
            </cylinder>
          </geometry>
          <material>
            <script>
              <name>Gazebo/Blue</name>
              <uri>file://media/materials/scripts/gazebo.material</uri>
            </script>
          </material>
        </visual>
        <self_collide>0</self_collide>
        <enable_wind>0</enable_wind>
        <kinematic>0</kinematic>
      </link>
      <joint name='right_wheel_joint' type='revolute'>
        <pose relative_to='base_link'>0 -0.5 0 1.5708 -0 0</pose>
        <parent>base_link</parent>
        <child>right_wheel</child>
        <axis>
          <xyz>0 0 -1</xyz>
          <limit>
            <lower>-1e+16</lower>
            <upper>1e+16</upper>
          </limit>
          <dynamics>
            <spring_reference>0</spring_reference>
            <spring_stiffness>0</spring_stiffness>
          </dynamics>
        </axis>
      </joint>
      <link name='right_wheel'>
        <pose relative_to='right_wheel_joint'>0 0 0 0 -0 0</pose>
        <inertial>
          <pose>0 0 0 0 -0 0</pose>
          <mass>5</mass>
          <inertia>
            <ixx>0.0541667</ixx>
            <ixy>0</ixy>
            <ixz>0</ixz>
            <iyy>0.0541667</iyy>
            <iyz>0</iyz>
            <izz>0.1</izz>
          </inertia>
        </inertial>
        <collision name='right_wheel_collision'>
          <pose>0 0 0 0 -0 0</pose>
          <geometry>
            <cylinder>
              <length>0.1</length>
              <radius>0.2</radius>
            </cylinder>
          </geometry>
          <surface>
            <contact>
              <ode/>
            </contact>
            <friction>
              <ode/>
              <torsional>
                <ode/>
              </torsional>
            </friction>
            <bounce/>
          </surface>
          <max_contacts>10</max_contacts>
        </collision>
        <visual name='right_wheel_visual'>
          <pose>0 0 0 0 -0 0</pose>
          <geometry>
            <cylinder>
              <length>0.1</length>
              <radius>0.2</radius>
            </cylinder>
          </geometry>
          <material>
            <script>
              <name>Gazebo/Blue</name>
              <uri>file://media/materials/scripts/gazebo.material</uri>
            </script>
          </material>
        </visual>
        <self_collide>0</self_collide>
        <enable_wind>0</enable_wind>
        <kinematic>0</kinematic>
      </link>
      <static>0</static>
      <plugin name='diff_drive' filename='libgazebo_ros_diff_drive.so'>
        <left_joint>left_wheel_joint</left_joint>
        <right_joint>right_wheel_joint</right_joint>
        <wheel_separation>0.35</wheel_separation>
        <wheel_diameter>0.1</wheel_diameter>
        <max_wheel_torque>200</max_wheel_torque>
        <max_wheel_acceleration>10.0</max_wheel_acceleration>
        <odometry_frame>odom</odometry_frame>
        <robot_base_frame>base_link</robot_base_frame>
        <publish_odom>1</publish_odom>
        <publish_odom_tf>1</publish_odom_tf>
        <publish_wheel_tf>1</publish_wheel_tf>
      </plugin>
      <pose>0 0 0 0 -0 0</pose>
    </model>
    <model name='unit_cylinder'>
      <pose>-2.87667 -1.92986 0.5 0 -0 0</pose>
      <link name='link'>
        <inertial>
          <mass>1</mass>
          <inertia>
            <ixx>0.145833</ixx>
            <ixy>0</ixy>
            <ixz>0</ixz>
            <iyy>0.145833</iyy>
            <iyz>0</iyz>
            <izz>0.125</izz>
          </inertia>
          <pose>0 0 0 0 -0 0</pose>
        </inertial>
        <collision name='collision'>
          <geometry>
            <cylinder>
              <radius>0.5</radius>
              <length>0.999999</length>
            </cylinder>
          </geometry>
          <max_contacts>10</max_contacts>
          <surface>
            <contact>
              <ode/>
            </contact>
            <bounce/>
            <friction>
              <torsional>
                <ode/>
              </torsional>
              <ode/>
            </friction>
          </surface>
        </collision>
        <visual name='visual'>
          <geometry>
            <cylinder>
              <radius>0.5</radius>
              <length>0.999999</length>
            </cylinder>
          </geometry>
          <material>
            <script>
              <name>Gazebo/Grey</name>
              <uri>file://media/materials/scripts/gazebo.material</uri>
            </script>
          </material>
        </visual>
        <self_collide>0</self_collide>
        <enable_wind>0</enable_wind>
        <kinematic>0</kinematic>
      </link>
    </model>
    <model name='unit_box'>
      <pose>0.091978 -4.13445 0.5 0 -0 0</pose>
      <link name='link'>
        <inertial>
          <mass>1</mass>
          <inertia>
            <ixx>0.166667</ixx>
            <ixy>0</ixy>
            <ixz>0</ixz>
            <iyy>0.166667</iyy>
            <iyz>0</iyz>
            <izz>0.166667</izz>
          </inertia>
          <pose>0 0 0 0 -0 0</pose>
        </inertial>
        <collision name='collision'>
          <geometry>
            <box>
              <size>1 1 1</size>
            </box>
          </geometry>
          <max_contacts>10</max_contacts>
          <surface>
            <contact>
              <ode/>
            </contact>
            <bounce/>
            <friction>
              <torsional>
                <ode/>
              </torsional>
              <ode/>
            </friction>
          </surface>
        </collision>
        <visual name='visual'>
          <geometry>
            <box>
              <size>1 1 1</size>
            </box>
          </geometry>
          <material>
            <script>
              <name>Gazebo/Grey</name>
              <uri>file://media/materials/scripts/gazebo.material</uri>
            </script>
          </material>
        </visual>
        <self_collide>0</self_collide>
        <enable_wind>0</enable_wind>
        <kinematic>0</kinematic>
      </link>
    </model>
    <model name='unit_box_0'>
      <pose>-1.05842 -4.12413 0.5 0 -0 0</pose>
      <link name='link'>
        <inertial>
          <mass>1</mass>
          <inertia>
            <ixx>0.166667</ixx>
            <ixy>0</ixy>
            <ixz>0</ixz>
            <iyy>0.166667</iyy>
            <iyz>0</iyz>
            <izz>0.166667</izz>
          </inertia>
          <pose>0 0 0 0 -0 0</pose>
        </inertial>
        <collision name='collision'>
          <geometry>
            <box>
              <size>1 1 1</size>
            </box>
          </geometry>
          <max_contacts>10</max_contacts>
          <surface>
            <contact>
              <ode/>
            </contact>
            <bounce/>
            <friction>
              <torsional>
                <ode/>
              </torsional>
              <ode/>
            </friction>
          </surface>
        </collision>
        <visual name='visual'>
          <geometry>
            <box>
              <size>1 1 1</size>
            </box>
          </geometry>
          <material>
            <script>
              <name>Gazebo/Grey</name>
              <uri>file://media/materials/scripts/gazebo.material</uri>
            </script>
          </material>
        </visual>
        <self_collide>0</self_collide>
        <enable_wind>0</enable_wind>
        <kinematic>0</kinematic>
      </link>
    </model>
    <model name='unit_box_0_clone'>
      <pose>-2.26574 -4.13191 0.5 0 -0 0</pose>
      <link name='link'>
        <inertial>
          <mass>1</mass>
          <inertia>
            <ixx>0.166667</ixx>
            <ixy>0</ixy>
            <ixz>0</ixz>
            <iyy>0.166667</iyy>
            <iyz>0</iyz>
            <izz>0.166667</izz>
          </inertia>
          <pose>0 0 0 0 -0 0</pose>
        </inertial>
        <collision name='collision'>
          <geometry>
            <box>
              <size>1 1 1</size>
            </box>
          </geometry>
          <max_contacts>10</max_contacts>
          <surface>
            <contact>
              <ode/>
            </contact>
            <bounce/>
            <friction>
              <torsional>
                <ode/>
              </torsional>
              <ode/>
            </friction>
          </surface>
        </collision>
        <visual name='visual'>
          <geometry>
            <box>
              <size>1 1 1</size>
            </box>
          </geometry>
          <material>
            <script>
              <name>Gazebo/Grey</name>
              <uri>file://media/materials/scripts/gazebo.material</uri>
            </script>
          </material>
        </visual>
        <self_collide>0</self_collide>
        <enable_wind>0</enable_wind>
        <kinematic>0</kinematic>
      </link>
    </model>
    <model name='unit_box_0_clone_0'>
      <pose>-3.43042 -4.16438 0.5 0 -0 0</pose>
      <link name='link'>
        <inertial>
          <mass>1</mass>
          <inertia>
            <ixx>0.166667</ixx>
            <ixy>0</ixy>
            <ixz>0</ixz>
            <iyy>0.166667</iyy>
            <iyz>0</iyz>
            <izz>0.166667</izz>
          </inertia>
          <pose>0 0 0 0 -0 0</pose>
        </inertial>
        <collision name='collision'>
          <geometry>
            <box>
              <size>1 1 1</size>
            </box>
          </geometry>
          <max_contacts>10</max_contacts>
          <surface>
            <contact>
              <ode/>
            </contact>
            <bounce/>
            <friction>
              <torsional>
                <ode/>
              </torsional>
              <ode/>
            </friction>
          </surface>
        </collision>
        <visual name='visual'>
          <geometry>
            <box>
              <size>1 1 1</size>
            </box>
          </geometry>
          <material>
            <script>
              <name>Gazebo/Grey</name>
              <uri>file://media/materials/scripts/gazebo.material</uri>
            </script>
          </material>
        </visual>
        <self_collide>0</self_collide>
        <enable_wind>0</enable_wind>
        <kinematic>0</kinematic>
      </link>
    </model>
    <model name='unit_box_0_clone_1'>
      <pose>-4.54748 -4.087 0.5 0 -0 0</pose>
      <link name='link'>
        <inertial>
          <mass>1</mass>
          <inertia>
            <ixx>0.166667</ixx>
            <ixy>0</ixy>
            <ixz>0</ixz>
            <iyy>0.166667</iyy>
            <iyz>0</iyz>
            <izz>0.166667</izz>
          </inertia>
          <pose>0 0 0 0 -0 0</pose>
        </inertial>
        <collision name='collision'>
          <geometry>
            <box>
              <size>1 1 1</size>
            </box>
          </geometry>
          <max_contacts>10</max_contacts>
          <surface>
            <contact>
              <ode/>
            </contact>
            <bounce/>
            <friction>
              <torsional>
                <ode/>
              </torsional>
              <ode/>
            </friction>
          </surface>
        </collision>
        <visual name='visual'>
          <geometry>
            <box>
              <size>1 1 1</size>
            </box>
          </geometry>
          <material>
            <script>
              <name>Gazebo/Grey</name>
              <uri>file://media/materials/scripts/gazebo.material</uri>
            </script>
          </material>
        </visual>
        <self_collide>0</self_collide>
        <enable_wind>0</enable_wind>
        <kinematic>0</kinematic>
      </link>
    </model>
    <model name='unit_box_0_clone_2'>
      <pose>-5.69301 -4.02041 0.5 0 -0 0</pose>
      <link name='link'>
        <inertial>
          <mass>1</mass>
          <inertia>
            <ixx>0.166667</ixx>
            <ixy>0</ixy>
            <ixz>0</ixz>
            <iyy>0.166667</iyy>
            <iyz>0</iyz>
            <izz>0.166667</izz>
          </inertia>
          <pose>0 0 0 0 -0 0</pose>
        </inertial>
        <collision name='collision'>
          <geometry>
            <box>
              <size>1 1 1</size>
            </box>
          </geometry>
          <max_contacts>10</max_contacts>
          <surface>
            <contact>
              <ode/>
            </contact>
            <bounce/>
            <friction>
              <torsional>
                <ode/>
              </torsional>
              <ode/>
            </friction>
          </surface>
        </collision>
        <visual name='visual'>
          <geometry>
            <box>
              <size>1 1 1</size>
            </box>
          </geometry>
          <material>
            <script>
              <name>Gazebo/Grey</name>
              <uri>file://media/materials/scripts/gazebo.material</uri>
            </script>
          </material>
        </visual>
        <self_collide>0</self_collide>
        <enable_wind>0</enable_wind>
        <kinematic>0</kinematic>
      </link>
    </model>
    <model name='unit_box_0_clone_3'>
      <pose>0.07835 -3.33462 0.5 0 -0 0</pose>
      <link name='link'>
        <inertial>
          <mass>1</mass>
          <inertia>
            <ixx>0.166667</ixx>
            <ixy>0</ixy>
            <ixz>0</ixz>
            <iyy>0.166667</iyy>
            <iyz>0</iyz>
            <izz>0.166667</izz>
          </inertia>
          <pose>0 0 0 0 -0 0</pose>
        </inertial>
        <collision name='collision'>
          <geometry>
            <box>
              <size>1 1 1</size>
            </box>
          </geometry>
          <max_contacts>10</max_contacts>
          <surface>
            <contact>
              <ode/>
            </contact>
            <bounce/>
            <friction>
              <torsional>
                <ode/>
              </torsional>
              <ode/>
            </friction>
          </surface>
        </collision>
        <visual name='visual'>
          <geometry>
            <box>
              <size>1 1 1</size>
            </box>
          </geometry>
          <material>
            <script>
              <name>Gazebo/Grey</name>
              <uri>file://media/materials/scripts/gazebo.material</uri>
            </script>
          </material>
        </visual>
        <self_collide>0</self_collide>
        <enable_wind>0</enable_wind>
        <kinematic>0</kinematic>
      </link>
    </model>
    <model name='unit_box_0_clone_3_clone'>
      <pose>-1.18476 -3.24425 1.8218 0 -0 0</pose>
      <link name='link'>
        <inertial>
          <mass>1</mass>
          <inertia>
            <ixx>0.166667</ixx>
            <ixy>0</ixy>
            <ixz>0</ixz>
            <iyy>0.166667</iyy>
            <iyz>0</iyz>
            <izz>0.166667</izz>
          </inertia>
          <pose>0 0 0 0 -0 0</pose>
        </inertial>
        <collision name='collision'>
          <geometry>
            <box>
              <size>1 1 1</size>
            </box>
          </geometry>
          <max_contacts>10</max_contacts>
          <surface>
            <contact>
              <ode/>
            </contact>
            <bounce/>
            <friction>
              <torsional>
                <ode/>
              </torsional>
              <ode/>
            </friction>
          </surface>
        </collision>
        <visual name='visual'>
          <geometry>
            <box>
              <size>1 1 1</size>
            </box>
          </geometry>
          <material>
            <script>
              <name>Gazebo/Grey</name>
              <uri>file://media/materials/scripts/gazebo.material</uri>
            </script>
          </material>
        </visual>
        <self_collide>0</self_collide>
        <enable_wind>0</enable_wind>
        <kinematic>0</kinematic>
      </link>
    </model>
    <model name='unit_box_0_clone_3_clone_0'>
      <pose>-2.34752 -2.99083 1.8218 0 -0 0</pose>
      <link name='link'>
        <inertial>
          <mass>1</mass>
          <inertia>
            <ixx>0.166667</ixx>
            <ixy>0</ixy>
            <ixz>0</ixz>
            <iyy>0.166667</iyy>
            <iyz>0</iyz>
            <izz>0.166667</izz>
          </inertia>
          <pose>0 0 0 0 -0 0</pose>
        </inertial>
        <collision name='collision'>
          <geometry>
            <box>
              <size>1 1 1</size>
            </box>
          </geometry>
          <max_contacts>10</max_contacts>
          <surface>
            <contact>
              <ode/>
            </contact>
            <bounce/>
            <friction>
              <torsional>
                <ode/>
              </torsional>
              <ode/>
            </friction>
          </surface>
        </collision>
        <visual name='visual'>
          <geometry>
            <box>
              <size>1 1 1</size>
            </box>
          </geometry>
          <material>
            <script>
              <name>Gazebo/Grey</name>
              <uri>file://media/materials/scripts/gazebo.material</uri>
            </script>
          </material>
        </visual>
        <self_collide>0</self_collide>
        <enable_wind>0</enable_wind>
        <kinematic>0</kinematic>
      </link>
    </model>
    <model name='unit_box_0_clone_3_clone_1'>
      <pose>-3.40257 -2.89381 1.8218 0 -0 0</pose>
      <link name='link'>
        <inertial>
          <mass>1</mass>
          <inertia>
            <ixx>0.166667</ixx>
            <ixy>0</ixy>
            <ixz>0</ixz>
            <iyy>0.166667</iyy>
            <iyz>0</iyz>
            <izz>0.166667</izz>
          </inertia>
          <pose>0 0 0 0 -0 0</pose>
        </inertial>
        <collision name='collision'>
          <geometry>
            <box>
              <size>1 1 1</size>
            </box>
          </geometry>
          <max_contacts>10</max_contacts>
          <surface>
            <contact>
              <ode/>
            </contact>
            <bounce/>
            <friction>
              <torsional>
                <ode/>
              </torsional>
              <ode/>
            </friction>
          </surface>
        </collision>
        <visual name='visual'>
          <geometry>
            <box>
              <size>1 1 1</size>
            </box>
          </geometry>
          <material>
            <script>
              <name>Gazebo/Grey</name>
              <uri>file://media/materials/scripts/gazebo.material</uri>
            </script>
          </material>
        </visual>
        <self_collide>0</self_collide>
        <enable_wind>0</enable_wind>
        <kinematic>0</kinematic>
      </link>
    </model>
    <model name='unit_box_0_clone_3_clone_2'>
      <pose>-4.54526 -3.04534 1.8218 0 -0 0</pose>
      <link name='link'>
        <inertial>
          <mass>1</mass>
          <inertia>
            <ixx>0.166667</ixx>
            <ixy>0</ixy>
            <ixz>0</ixz>
            <iyy>0.166667</iyy>
            <iyz>0</iyz>
            <izz>0.166667</izz>
          </inertia>
          <pose>0 0 0 0 -0 0</pose>
        </inertial>
        <collision name='collision'>
          <geometry>
            <box>
              <size>1 1 1</size>
            </box>
          </geometry>
          <max_contacts>10</max_contacts>
          <surface>
            <contact>
              <ode/>
            </contact>
            <bounce/>
            <friction>
              <torsional>
                <ode/>
              </torsional>
              <ode/>
            </friction>
          </surface>
        </collision>
        <visual name='visual'>
          <geometry>
            <box>
              <size>1 1 1</size>
            </box>
          </geometry>
          <material>
            <script>
              <name>Gazebo/Grey</name>
              <uri>file://media/materials/scripts/gazebo.material</uri>
            </script>
          </material>
        </visual>
        <self_collide>0</self_collide>
        <enable_wind>0</enable_wind>
        <kinematic>0</kinematic>
      </link>
    </model>
    <model name='unit_box_0_clone_3_clone_3'>
      <pose>-5.79924 -2.92543 1.8218 0 -0 0</pose>
      <link name='link'>
        <inertial>
          <mass>1</mass>
          <inertia>
            <ixx>0.166667</ixx>
            <ixy>0</ixy>
            <ixz>0</ixz>
            <iyy>0.166667</iyy>
            <iyz>0</iyz>
            <izz>0.166667</izz>
          </inertia>
          <pose>0 0 0 0 -0 0</pose>
        </inertial>
        <collision name='collision'>
          <geometry>
            <box>
              <size>1 1 1</size>
            </box>
          </geometry>
          <max_contacts>10</max_contacts>
          <surface>
            <contact>
              <ode/>
            </contact>
            <bounce/>
            <friction>
              <torsional>
                <ode/>
              </torsional>
              <ode/>
            </friction>
          </surface>
        </collision>
        <visual name='visual'>
          <geometry>
            <box>
              <size>1 1 1</size>
            </box>
          </geometry>
          <material>
            <script>
              <name>Gazebo/Grey</name>
              <uri>file://media/materials/scripts/gazebo.material</uri>
            </script>
          </material>
        </visual>
        <self_collide>0</self_collide>
        <enable_wind>0</enable_wind>
        <kinematic>0</kinematic>
      </link>
    </model>
    <state world_name='default'>
      <sim_time>2 330000000</sim_time>
      <real_time>2 333870026</real_time>
      <wall_time>1734145301 7049123</wall_time>
      <iterations>2330</iterations>
      <model name='ground_plane'>
        <pose>0 0 0 0 -0 0</pose>
        <scale>1 1 1</scale>
        <link name='link'>
          <pose>0 0 0 0 -0 0</pose>
          <velocity>0 0 0 0 -0 0</velocity>
          <acceleration>0 0 0 0 -0 0</acceleration>
          <wrench>0 0 0 0 -0 0</wrench>
        </link>
      </model>
      <model name='my_bot'>
        <pose>-0.036764 0.0215 0.200001 1e-06 -0.005321 -0.011256</pose>
        <scale>1 1 1</scale>
        <link name='base_link'>
          <pose>-0.036764 0.0215 0.200001 1e-06 -0.005321 -0.011256</pose>
          <velocity>-0.000103 -1.4e-05 -1.4e-05 -2.8e-05 -1.1e-05 2e-06</velocity>
          <acceleration>-0.042108 0.016097 -0.014963 -0.026511 0.001618 0.006191</acceleration>
          <wrench>-2.32859 0.890171 -0.827427 0 -0 0</wrench>
        </link>
        <link name='cart'>
          <pose>-1.87002 0.042137 0.190242 0.00011 0.00532 -3.13197</pose>
          <velocity>-0.000102 -1.2e-05 -5.3e-05 -1.9e-05 -7e-06 -0.001885</velocity>
          <acceleration>-0.03333 0.012455 -0.031483 -0.027907 0.004884 0.002511</acceleration>
          <wrench>-1.68649 0.630229 -1.59304 0 -0 0</wrench>
        </link>
        <link name='cart2'>
          <pose>-5.10322 0.011012 0.173041 0.000237 0.005314 -3.10801</pose>
          <velocity>-0.00014 0.006086 -8.2e-05 -4.7e-05 2.2e-05 0.002881</velocity>
          <acceleration>0.030856 0.007777 0.00779 -0.031584 0.024291 0.006604</acceleration>
          <wrench>0.629456 0.158648 0.158918 0 -0 0</wrench>
        </link>
        <link name='cart2_left_wheel'>
          <pose>-6.67879 -0.742321 0.164704 -1.57056 0.00665 -3.10801</pose>
          <velocity>0.002029 0.001544 -1.2e-05 -6.4e-05 0.000543 0.002881</velocity>
          <acceleration>0.007824 -0.034211 0.048351 -0.031316 -0.00105 0.008501</acceleration>
          <wrench>0.039121 -0.171054 0.241755 0 -0 0</wrench>
        </link>
        <link name='cart2_right_wheel'>
          <pose>-6.7258 0.65689 0.164372 1.57104 0.011086 -3.108</pose>
          <velocity>-0.002003 0.001413 -7.5e-05 -8.1e-05 0.001029 0.002881</velocity>
          <acceleration>-0.00248 -0.034808 0.003899 -0.032891 -0.001103 0.009188</acceleration>
          <wrench>-0.012398 -0.174042 0.019493 0 -0 0</wrench>
        </link>
        <link name='cart3'>
          <pose>-7.83504 -0.080776 0.158512 1e-06 0.00532 3.13087</pose>
          <velocity>0.000185 -0.001777 -5.9e-05 -2.3e-05 1.9e-05 -0.00106</velocity>
          <acceleration>0.09504 0.018338 0.018628 -0.039744 0.012283 -0.010658</acceleration>
          <wrench>1.93881 0.374096 0.380007 0 -0 0</wrench>
        </link>
        <link name='cart3_left_wheel'>
          <pose>-9.44082 -0.613588 0.15 1.571 -1.54149 -0.010925</pose>
          <velocity>-0.000364 -2.7e-05 3e-06 0.000128 -0.003068 -0.001008</velocity>
          <acceleration>0.089696 0.008664 0.062021 -0.063504 0.514108 0.084352</acceleration>
          <wrench>0.44848 0.043321 0.310106 0 -0 0</wrench>
        </link>
        <link name='cart3_right_wheel'>
          <pose>-9.42902 0.486347 0.15 -1.5708 -0.825953 -0.010725</pose>
          <velocity>0.000799 -9.5e-05 -4.9e-05 0.000679 0.006373 -0.001527</velocity>
          <acceleration>0.094234 0.001575 0.006132 -0.014012 0.476788 0.058819</acceleration>
          <wrench>0.471171 0.007877 0.030659 0 -0 0</wrench>
        </link>
        <link name='cart_left_wheel'>
          <pose>-4.06219 -0.779003 0.178626 -1.57069 -0.000277 -3.13197</pose>
          <velocity>-0.001642 0.004121 -6.5e-05 -2.2e-05 0.000585 -0.001884</velocity>
          <acceleration>-0.030914 -0.02101 -0.015375 -0.025565 -0.000246 0.003401</acceleration>
          <wrench>-0.154571 -0.10505 -0.076874 0 -0 0</wrench>
        </link>
        <link name='cart_right_wheel'>
          <pose>-4.07759 0.820923 0.178449 1.57091 0.007463 -3.13197</pose>
          <velocity>0.001373 0.004152 -9.1e-05 -2.1e-05 0.000428 -0.001885</velocity>
          <acceleration>-0.035549 -0.019877 -0.056116 -0.026473 -0.000255 0.003469</acceleration>
          <wrench>-0.177744 -0.099386 -0.280581 0 -0 0</wrench>
        </link>
        <link name='left_wheel'>
          <pose>-0.031136 0.521466 0.200002 -1.57084 -0.01051 -0.011257</pose>
          <velocity>-9.3e-05 -7e-06 -2e-06 0.000208 -0.000441 -4.6e-05</velocity>
          <acceleration>-0.032013 -0.009661 -0.003608 0.049106 -0.076339 -0.12003</acceleration>
          <wrench>-0.160064 -0.048307 -0.018039 0 -0 0</wrench>
        </link>
        <link name='right_wheel'>
          <pose>-0.042392 -0.478465 0.200002 1.57084 -0.012171 -0.011256</pose>
          <velocity>-9.7e-05 -1.9e-05 -4e-06 -7.9e-05 -0.000468 2.6e-05</velocity>
          <acceleration>-0.027449 -0.003383 0.007499 0.016855 -0.063614 0.127038</acceleration>
          <wrench>-0.137247 -0.016916 0.037493 0 -0 0</wrench>
        </link>
      </model>
      <model name='unit_box'>
        <pose>-0.007548 -3.33068 0.499998 -1e-06 3e-06 0.000171</pose>
        <scale>1 1 1</scale>
        <link name='link'>
          <pose>-0.007548 -3.33068 0.499998 -1e-06 3e-06 0.000171</pose>
          <velocity>0.002228 0.002205 -0.004405 -0.004333 0.004556 9e-05</velocity>
          <acceleration>-1.53541 -2.33637 -4.01867 1.59324 0.064429 3.04092</acceleration>
          <wrench>-1.53541 -2.33637 -4.01867 0 -0 0</wrench>
        </link>
      </model>
      <model name='unit_box_0'>
        <pose>-1.16949 -3.38948 0.500003 -0 6e-06 -0.000167</pose>
        <scale>1 1 1</scale>
        <link name='link'>
          <pose>-1.16949 -3.38948 0.500003 -0 6e-06 -0.000167</pose>
          <velocity>-0.002762 -0.000492 0.006979 0.000839 -0.005535 0.000102</velocity>
          <acceleration>-7.07702 1.3509 12.8149 2.19716 -0.373398 -1.1282</acceleration>
          <wrench>-7.07702 1.3509 12.8149 0 -0 0</wrench>
        </link>
      </model>
      <model name='unit_box_0_clone'>
        <pose>-2.29557 -3.34952 0.500002 0 -3e-06 -0.00191</pose>
        <scale>1 1 1</scale>
        <link name='link'>
          <pose>-2.29557 -3.34952 0.500002 0 -3e-06 -0.00191</pose>
          <velocity>0.001456 0.000344 0.0047 -0.000606 0.002916 5.8e-05</velocity>
          <acceleration>6.29892 -2.04075 10.047 -2.1081 -0.107344 0.095668</acceleration>
          <wrench>6.29892 -2.04075 10.047 0 -0 0</wrench>
        </link>
      </model>
      <model name='unit_box_0_clone_0'>
        <pose>-3.42982 -3.3138 0.499997 -1.2e-05 6e-06 -0.003724</pose>
        <scale>1 1 1</scale>
        <link name='link'>
          <pose>-3.42982 -3.3138 0.499997 -1.2e-05 6e-06 -0.003724</pose>
          <velocity>-0.00151 0.007749 -0.008983 -0.012389 -0.006161 -0.003127</velocity>
          <acceleration>1.70013 2.02979 -9.30387 -1.5225 -0.881467 -2.52736</acceleration>
          <wrench>1.70013 2.02979 -9.30387 0 -0 0</wrench>
        </link>
      </model>
      <model name='unit_box_0_clone_1'>
        <pose>-4.55882 -3.38347 0.5 0 -1e-06 -0.003512</pose>
        <scale>1 1 1</scale>
        <link name='link'>
          <pose>-4.55882 -3.38347 0.5 0 -1e-06 -0.003512</pose>
          <velocity>0.004503 -0.004284 0.000783 0.008518 0.00925 -0.000122</velocity>
          <acceleration>7.53882 -3.22079 4.08631 -2.19975 0.425863 2.19532</acceleration>
          <wrench>7.53882 -3.22079 4.08631 0 -0 0</wrench>
        </link>
      </model>
      <model name='unit_box_0_clone_2'>
        <pose>-5.71669 -3.35268 0.5 0 0 -0.003472</pose>
        <scale>1 1 1</scale>
        <link name='link'>
          <pose>-5.71669 -3.35268 0.5 0 0 -0.003472</pose>
          <velocity>-0.000996 0.002513 0.003522 -0.005026 -0.001992 0</velocity>
          <acceleration>-3.56271 5.14718 8.52608 2.20996 -0.781473 -0.061301</acceleration>
          <wrench>-3.56271 5.14718 8.52608 0 -0 0</wrench>
        </link>
      </model>
      <model name='unit_box_0_clone_3'>
        <pose>0.078392 -3.33451 1.50001 4e-06 -1e-05 0.000289</pose>
        <scale>1 1 1</scale>
        <link name='link'>
          <pose>0.078392 -3.33451 1.50001 4e-06 -1e-05 0.000289</pose>
          <velocity>0.006239 0.010065 0.002367 -0.010405 0.004444 0.001068</velocity>
          <acceleration>5.13751 4.8487 1.19068 0.672842 -1.30069 0.754629</acceleration>
          <wrench>5.13751 4.8487 1.19068 0 -0 0</wrench>
        </link>
      </model>
      <model name='unit_box_0_clone_3_clone'>
        <pose>-1.18925 -3.32822 1.49999 -1.5e-05 -1e-06 -0.000122</pose>
        <scale>1 1 1</scale>
        <link name='link'>
          <pose>-1.18925 -3.32822 1.49999 -1.5e-05 -1e-06 -0.000122</pose>
          <velocity>-0.001721 0.003663 0.008783 -0.009146 0.007666 0.00017</velocity>
          <acceleration>-12.4894 6.78137 14.4967 2.49656 -0.496715 2.08512</acceleration>
          <wrench>-12.4894 6.78137 14.4967 0 -0 0</wrench>
        </link>
      </model>
      <model name='unit_box_0_clone_3_clone_0'>
        <pose>-2.36069 -3.25262 1.5 -4e-06 -3e-06 -0.001664</pose>
        <scale>1 1 1</scale>
        <link name='link'>
          <pose>-2.36069 -3.25262 1.5 -4e-06 -3e-06 -0.001664</pose>
          <velocity>0.00248 0.000727 0.006684 -0.000165 -0.000808 9.2e-05</velocity>
          <acceleration>9.21954 2.81902 11.0179 -3.0774 -0.944446 -0.709841</acceleration>
          <wrench>9.21954 2.81902 11.0179 0 -0 0</wrench>
        </link>
      </model>
      <model name='unit_box_0_clone_3_clone_1'>
        <pose>-3.40545 -3.26138 1.50425 -0.071162 -2.1e-05 -0.004186</pose>
        <scale>1 1 1</scale>
        <link name='link'>
          <pose>-3.40545 -3.26138 1.50425 -0.071162 -2.1e-05 -0.004186</pose>
          <velocity>-0.004221 -0.039476 -0.010782 0.106658 -0.002115 -0.003091</velocity>
          <acceleration>-1.75034 3.11464 -5.14205 1.13521 -1.4849 -0.147433</acceleration>
          <wrench>-1.75034 3.11464 -5.14205 0 -0 0</wrench>
        </link>
      </model>
      <model name='unit_box_0_clone_3_clone_2'>
        <pose>-4.57303 -3.24772 1.5 -8e-06 -6e-06 -0.002917</pose>
        <scale>1 1 1</scale>
        <link name='link'>
          <pose>-4.57303 -3.24772 1.5 -8e-06 -6e-06 -0.002917</pose>
          <velocity>-0.004084 -0.001538 -0.004373 -0.004623 -0.023541 -0.00979</velocity>
          <acceleration>3.51822 -1.49923 -3.48467 -1.64944 0.803858 1.6905</acceleration>
          <wrench>3.51822 -1.49923 -3.48467 0 -0 0</wrench>
        </link>
      </model>
      <model name='unit_box_0_clone_3_clone_3'>
        <pose>-5.7536 -3.24429 1.50069 -0.01034 3.1e-05 -0.003355</pose>
        <scale>1 1 1</scale>
        <link name='link'>
          <pose>-5.7536 -3.24429 1.50069 -0.01034 3.1e-05 -0.003355</pose>
          <velocity>0.002417 -0.146134 -0.032004 0.289526 0.006255 -0.003592</velocity>
          <acceleration>0 0 -9.8 0 -0 0</acceleration>
          <wrench>0 0 -9.8 0 -0 0</wrench>
        </link>
      </model>
      <model name='unit_cylinder'>
        <pose>-2.87647 -1.92986 1.79971 2e-06 0.000116 1.9e-05</pose>
        <scale>0.313172 0.313172 3.59938</scale>
        <link name='link'>
          <pose>-2.87647 -1.92986 1.79971 2e-06 0.000116 1.9e-05</pose>
          <velocity>0.130887 -0.001444 0.021382 0.000803 0.072727 -3e-06</velocity>
          <acceleration>-4.17008 -3.3e-05 40.3117 -3.14142 -0.824254 -3.14158</acceleration>
          <wrench>-4.17008 -3.3e-05 40.3117 0 -0 0</wrench>
        </link>
      </model>
      <light name='sun'>
        <pose>0 0 10 0 -0 0</pose>
      </light>
    </state>
    <gui fullscreen='0'>
      <camera name='user_camera'>
        <pose>-9.94559 -13.4507 16.2197 0 0.793795 1.05221</pose>
        <view_controller>orbit</view_controller>
        <projection_type>perspective</projection_type>
      </camera>
    </gui>
  </world>
</sdf>
