<sdf version='1.7'>
  <world name='default'>
    <light name='sun' type='directional'>
      <cast_shadows>1</cast_shadows>
      <pose>0 0 10 0 -0 0</pose>
      <diffuse>0.8 0.8 0.8 1</diffuse>
      <specular>0.2 0.2 0.2 1</specular>
      <attenuation>
        <range>1000</range>
        <constant>0.9</constant>
        <linear>0.01</linear>
        <quadratic>0.001</quadratic>
      </attenuation>
      <direction>-0.5 0.1 -0.9</direction>
      <spot>
        <inner_angle>0</inner_angle>
        <outer_angle>0</outer_angle>
        <falloff>0</falloff>
      </spot>
    </light>
    <model name='ground_plane'>
      <static>1</static>
      <link name='link'>
        <collision name='collision'>
          <geometry>
            <plane>
              <normal>0 0 1</normal>
              <size>100 100</size>
            </plane>
          </geometry>
          <surface>
            <friction>
              <ode>
                <mu>100</mu>
                <mu2>50</mu2>
              </ode>
              <torsional>
                <ode/>
              </torsional>
            </friction>
            <contact>
              <ode/>
            </contact>
            <bounce/>
          </surface>
          <max_contacts>10</max_contacts>
        </collision>
        <visual name='visual'>
          <cast_shadows>0</cast_shadows>
          <geometry>
            <plane>
              <normal>0 0 1</normal>
              <size>100 100</size>
            </plane>
          </geometry>
          <material>
            <script>
              <uri>file://media/materials/scripts/gazebo.material</uri>
              <name>Gazebo/Grey</name>
            </script>
          </material>
        </visual>
        <self_collide>0</self_collide>
        <enable_wind>0</enable_wind>
        <kinematic>0</kinematic>
      </link>
    </model>
    <gravity>0 0 -9.8</gravity>
    <magnetic_field>6e-06 2.3e-05 -4.2e-05</magnetic_field>
    <atmosphere type='adiabatic'/>
    <physics type='ode'>
      <max_step_size>0.001</max_step_size>
      <real_time_factor>1</real_time_factor>
      <real_time_update_rate>1000</real_time_update_rate>
    </physics>
    <scene>
      <ambient>0.4 0.4 0.4 1</ambient>
      <background>0.7 0.7 0.7 1</background>
      <shadows>1</shadows>
    </scene>
    <audio>
      <device>default</device>
    </audio>
    <wind/>
    <spherical_coordinates>
      <surface_model>EARTH_WGS84</surface_model>
      <latitude_deg>0</latitude_deg>
      <longitude_deg>0</longitude_deg>
      <elevation>0</elevation>
      <heading_deg>0</heading_deg>
    </spherical_coordinates>
    <model name='my_bot'>
      <link name='base_link'>
        <inertial>
          <pose>0.579204 0 0.764919 0 -0 0</pose>
          <mass>55.3</mass>
          <inertia>
            <ixx>20.3378</ixx>
            <ixy>0</ixy>
            <ixz>2.43909</ixz>
            <iyy>30.6094</iyy>
            <iyz>0</iyz>
            <izz>15.6893</izz>
          </inertia>
        </inertial>
        <collision name='base_link_fixed_joint_lump__chassis_collision'>
          <pose>0.5225 0 0.85 0 -0 0</pose>
          <geometry>
            <box>
              <size>1.645 0.8 1.8</size>
            </box>
          </geometry>
          <surface>
            <contact>
              <ode/>
            </contact>
            <friction>
              <ode/>
              <torsional>
                <ode/>
              </torsional>
            </friction>
            <bounce/>
          </surface>
          <max_contacts>10</max_contacts>
        </collision>
        <collision name='base_link_fixed_joint_lump__camera_ray_collision_1'>
          <pose>1.35 0 1 0 -0 0</pose>
          <geometry>
            <cylinder>
              <length>0.04</length>
              <radius>0.05</radius>
            </cylinder>
          </geometry>
          <surface>
            <contact>
              <ode/>
            </contact>
            <friction>
              <ode/>
              <torsional>
                <ode/>
              </torsional>
            </friction>
            <bounce/>
          </surface>
          <max_contacts>10</max_contacts>
        </collision>
        <collision name='base_link_fixed_joint_lump__caster_wheel_collision_2'>
          <pose>1.1 0 -0.1 0 -0 0</pose>
          <geometry>
            <sphere>
              <radius>0.1</radius>
            </sphere>
          </geometry>
          <surface>
            <contact>
              <ode/>
            </contact>
            <friction>
              <ode>
                <mu>0.15</mu>
                <mu2>0.15</mu2>
              </ode>
              <torsional>
                <ode/>
              </torsional>
            </friction>
            <bounce/>
          </surface>
          <max_contacts>10</max_contacts>
        </collision>
        <collision name='base_link_fixed_joint_lump__lidar_l_collision_3'>
          <pose>1.35 0.4 1 0 -0 0</pose>
          <geometry>
            <cylinder>
              <length>0.04</length>
              <radius>0.05</radius>
            </cylinder>
          </geometry>
          <surface>
            <contact>
              <ode/>
            </contact>
            <friction>
              <ode/>
              <torsional>
                <ode/>
              </torsional>
            </friction>
            <bounce/>
          </surface>
          <max_contacts>10</max_contacts>
        </collision>
        <collision name='base_link_fixed_joint_lump__lidar_r_collision_4'>
          <pose>1.35 -0.4 1 0 -0 0</pose>
          <geometry>
            <cylinder>
              <length>0.04</length>
              <radius>0.05</radius>
            </cylinder>
          </geometry>
          <surface>
            <contact>
              <ode/>
            </contact>
            <friction>
              <ode/>
              <torsional>
                <ode/>
              </torsional>
            </friction>
            <bounce/>
          </surface>
          <max_contacts>10</max_contacts>
        </collision>
        <visual name='base_link_fixed_joint_lump__chassis_visual'>
          <pose>0.5225 0 0.85 0 -0 0</pose>
          <geometry>
            <box>
              <size>1.645 0.8 1.8</size>
            </box>
          </geometry>
          <material>
            <script>
              <name>Gazebo/White</name>
              <uri>file://media/materials/scripts/gazebo.material</uri>
            </script>
          </material>
        </visual>
        <visual name='base_link_fixed_joint_lump__camera_ray_visual_1'>
          <pose>1.35 0 1 0 -0 0</pose>
          <geometry>
            <cylinder>
              <length>0.04</length>
              <radius>0.05</radius>
            </cylinder>
          </geometry>
          <material>
            <script>
              <name>ambient</name>
              <uri>file://media/materials/scripts/gazebo.material</uri>
            </script>
          </material>
        </visual>
        <visual name='base_link_fixed_joint_lump__caster_wheel_visual_2'>
          <pose>1.1 0 -0.1 0 -0 0</pose>
          <geometry>
            <sphere>
              <radius>0.1</radius>
            </sphere>
          </geometry>
          <material>
            <script>
              <name>Gazebo/Black</name>
              <uri>file://media/materials/scripts/gazebo.material</uri>
            </script>
          </material>
        </visual>
        <visual name='base_link_fixed_joint_lump__lidar_l_visual_3'>
          <pose>1.35 0.4 1 0 -0 0</pose>
          <geometry>
            <cylinder>
              <length>0.04</length>
              <radius>0.05</radius>
            </cylinder>
          </geometry>
          <material>
            <script>
              <name>Gazebo/Red</name>
              <uri>file://media/materials/scripts/gazebo.material</uri>
            </script>
          </material>
        </visual>
        <visual name='base_link_fixed_joint_lump__lidar_r_visual_4'>
          <pose>1.35 -0.4 1 0 -0 0</pose>
          <geometry>
            <cylinder>
              <length>0.04</length>
              <radius>0.05</radius>
            </cylinder>
          </geometry>
          <material>
            <script>
              <name>Gazebo/Yellow</name>
              <uri>file://media/materials/scripts/gazebo.material</uri>
            </script>
          </material>
        </visual>
        <sensor name='camera_ray' type='ray'>
          <visualize>1</visualize>
          <update_rate>10</update_rate>
          <ray>
            <scan>
              <horizontal>
                <samples>86</samples>
                <min_angle>-0.75</min_angle>
                <max_angle>0.75</max_angle>
                <resolution>1</resolution>
              </horizontal>
              <vertical>
                <samples>1</samples>
                <min_angle>0</min_angle>
                <max_angle>0</max_angle>
              </vertical>
            </scan>
            <range>
              <min>0.3</min>
              <max>5</max>
            </range>
          </ray>
          <plugin name='camera_ray_controller' filename='libgazebo_ros_ray_sensor.so'>
            <ros>
              <argument>~/out:=scan</argument>
            </ros>
            <output_type>sensor_msgs/LaserScan</output_type>
            <frame_name>camera_ray</frame_name>
          </plugin>
          <pose>1.35 0 1 0 -0 0</pose>
        </sensor>
        <sensor name='lidar_l' type='ray'>
          <visualize>1</visualize>
          <update_rate>10</update_rate>
          <ray>
            <scan>
              <horizontal>
                <samples>360</samples>
                <min_angle>-3.14</min_angle>
                <max_angle>3.14</max_angle>
                <resolution>1</resolution>
              </horizontal>
              <vertical>
                <samples>1</samples>
                <min_angle>0</min_angle>
                <max_angle>0</max_angle>
              </vertical>
            </scan>
            <range>
              <min>0.3</min>
              <max>5</max>
            </range>
          </ray>
          <plugin name='lidar_l_controller' filename='libgazebo_ros_ray_sensor.so'>
            <ros>
              <argument>~/out:=scan</argument>
            </ros>
            <output_type>sensor_msgs/LaserScan</output_type>
            <frame_name>lidar_l</frame_name>
          </plugin>
          <pose>1.35 0.4 1 0 -0 0</pose>
        </sensor>
        <sensor name='lidar_r' type='ray'>
          <visualize>1</visualize>
          <update_rate>10</update_rate>
          <ray>
            <scan>
              <horizontal>
                <samples>360</samples>
                <min_angle>-3.14</min_angle>
                <max_angle>3.14</max_angle>
                <resolution>1</resolution>
              </horizontal>
              <vertical>
                <samples>1</samples>
                <min_angle>0</min_angle>
                <max_angle>0</max_angle>
              </vertical>
            </scan>
            <range>
              <min>0.3</min>
              <max>5</max>
            </range>
          </ray>
          <plugin name='lidar_r_controller' filename='libgazebo_ros_ray_sensor.so'>
            <ros>
              <argument>~/out:=scan</argument>
            </ros>
            <output_type>sensor_msgs/LaserScan</output_type>
            <frame_name>lidar_r</frame_name>
          </plugin>
          <pose>1.35 -0.4 1 0 -0 0</pose>
        </sensor>
        <self_collide>0</self_collide>
        <enable_wind>0</enable_wind>
        <kinematic>0</kinematic>
      </link>
      <joint name='cart_joint' type='revolute'>
        <pose relative_to='base_link'>-1.8334 0 0 0 -0 3.14159</pose>
        <parent>base_link</parent>
        <child>cart</child>
        <axis>
          <xyz>0 0 1</xyz>
          <limit>
            <lower>-1.57</lower>
            <upper>1.57</upper>
            <effort>10</effort>
            <velocity>1</velocity>
          </limit>
          <dynamics>
            <spring_reference>0</spring_reference>
            <spring_stiffness>0</spring_stiffness>
          </dynamics>
        </axis>
      </joint>
      <link name='cart'>
        <pose relative_to='cart_joint'>0 0 0 0 -0 0</pose>
        <inertial>
          <pose>0.9 0 1.12 0 -0 0</pose>
          <mass>50</mass>
          <inertia>
            <ixx>16.4167</ixx>
            <ixy>0</ixy>
            <ixz>0</ixz>
            <iyy>55.1634</iyy>
            <iyz>0</iyz>
            <izz>52.8301</izz>
          </inertia>
        </inertial>
        <collision name='cart_collision'>
          <pose>0.9 0 1.12 0 -0 0</pose>
          <geometry>
            <box>
              <size>3.315 1.3 1.5</size>
            </box>
          </geometry>
          <max_contacts>10</max_contacts>
          <surface>
            <contact>
              <ode/>
            </contact>
            <bounce/>
            <friction>
              <torsional>
                <ode/>
              </torsional>
              <ode/>
            </friction>
          </surface>
        </collision>
        <visual name='cart_visual'>
          <pose>0.9 0 0.7 0 -0 0</pose>
          <geometry>
            <box>
              <size>3.315 1.3 1.5</size>
            </box>
          </geometry>
        </visual>
        <self_collide>0</self_collide>
        <enable_wind>0</enable_wind>
        <kinematic>0</kinematic>
      </link>
      <joint name='cart2_joint' type='revolute'>
        <pose relative_to='cart'>3.2334 0 0 0 -0 0</pose>
        <parent>cart</parent>
        <child>cart2</child>
        <axis>
          <xyz>0 0 1</xyz>
          <limit>
            <lower>-1.57</lower>
            <upper>1.57</upper>
            <effort>10</effort>
            <velocity>1</velocity>
          </limit>
          <dynamics>
            <spring_reference>0</spring_reference>
            <spring_stiffness>0</spring_stiffness>
          </dynamics>
        </axis>
      </joint>
      <link name='cart2'>
        <pose relative_to='cart2_joint'>0 0 0 0 -0 0</pose>
        <inertial>
          <pose>0.9 0 1.12 0 -0 0</pose>
          <mass>20</mass>
          <inertia>
            <ixx>5.8035</ixx>
            <ixy>0</ixy>
            <ixz>0</ixz>
            <iyy>9.15</iyy>
            <iyz>0</iyz>
            <izz>7.4535</izz>
          </inertia>
        </inertial>
        <collision name='cart2_collision'>
          <pose>0.9 0 1.12 0 -0 0</pose>
          <geometry>
            <box>
              <size>1.8 1.11 1.5</size>
            </box>
          </geometry>
          <max_contacts>10</max_contacts>
          <surface>
            <contact>
              <ode/>
            </contact>
            <bounce/>
            <friction>
              <torsional>
                <ode/>
              </torsional>
              <ode/>
            </friction>
          </surface>
        </collision>
        <visual name='cart2_visual'>
          <pose>0.9 0 0.7 0 -0 0</pose>
          <geometry>
            <box>
              <size>1.8 1.11 1.5</size>
            </box>
          </geometry>
        </visual>
        <self_collide>0</self_collide>
        <enable_wind>0</enable_wind>
        <kinematic>0</kinematic>
      </link>
      <joint name='cart2_left_wheel_joint' type='revolute'>
        <pose relative_to='cart2'>1.6 0.7 0 -1.5708 0 0</pose>
        <parent>cart2</parent>
        <child>cart2_left_wheel</child>
        <axis>
          <xyz>0 0 1</xyz>
          <limit>
            <lower>-1e+16</lower>
            <upper>1e+16</upper>
          </limit>
          <dynamics>
            <spring_reference>0</spring_reference>
            <spring_stiffness>0</spring_stiffness>
          </dynamics>
        </axis>
      </joint>
      <link name='cart2_left_wheel'>
        <pose relative_to='cart2_left_wheel_joint'>0 0 0 0 -0 0</pose>
        <inertial>
          <pose>0 0 0 0 -0 0</pose>
          <mass>5</mass>
          <inertia>
            <ixx>0.0447917</ixx>
            <ixy>0</ixy>
            <ixz>0</ixz>
            <iyy>0.0447917</iyy>
            <iyz>0</iyz>
            <izz>0.05625</izz>
          </inertia>
        </inertial>
        <collision name='cart2_left_wheel_collision'>
          <pose>0 0 0 0 -0 0</pose>
          <geometry>
            <cylinder>
              <length>0.2</length>
              <radius>0.15</radius>
            </cylinder>
          </geometry>
          <surface>
            <contact>
              <ode/>
            </contact>
            <friction>
              <ode/>
              <torsional>
                <ode/>
              </torsional>
            </friction>
            <bounce/>
          </surface>
          <max_contacts>10</max_contacts>
        </collision>
        <visual name='cart2_left_wheel_visual'>
          <pose>0 0 0 0 -0 0</pose>
          <geometry>
            <cylinder>
              <length>0.2</length>
              <radius>0.15</radius>
            </cylinder>
          </geometry>
          <material>
            <script>
              <name>Gazebo/Blue</name>
              <uri>file://media/materials/scripts/gazebo.material</uri>
            </script>
          </material>
        </visual>
        <self_collide>0</self_collide>
        <enable_wind>0</enable_wind>
        <kinematic>0</kinematic>
      </link>
      <joint name='cart2_right_wheel_joint' type='revolute'>
        <pose relative_to='cart2'>1.6 -0.7 0 1.5708 -0 0</pose>
        <parent>cart2</parent>
        <child>cart2_right_wheel</child>
        <axis>
          <xyz>0 0 -1</xyz>
          <limit>
            <lower>-1e+16</lower>
            <upper>1e+16</upper>
          </limit>
          <dynamics>
            <spring_reference>0</spring_reference>
            <spring_stiffness>0</spring_stiffness>
          </dynamics>
        </axis>
      </joint>
      <link name='cart2_right_wheel'>
        <pose relative_to='cart2_right_wheel_joint'>0 0 0 0 -0 0</pose>
        <inertial>
          <pose>0 0 0 0 -0 0</pose>
          <mass>5</mass>
          <inertia>
            <ixx>0.0447917</ixx>
            <ixy>0</ixy>
            <ixz>0</ixz>
            <iyy>0.0447917</iyy>
            <iyz>0</iyz>
            <izz>0.05625</izz>
          </inertia>
        </inertial>
        <collision name='cart2_right_wheel_collision'>
          <pose>0 0 0 0 -0 0</pose>
          <geometry>
            <cylinder>
              <length>0.2</length>
              <radius>0.15</radius>
            </cylinder>
          </geometry>
          <surface>
            <contact>
              <ode/>
            </contact>
            <friction>
              <ode/>
              <torsional>
                <ode/>
              </torsional>
            </friction>
            <bounce/>
          </surface>
          <max_contacts>10</max_contacts>
        </collision>
        <visual name='cart2_right_wheel_visual'>
          <pose>0 0 0 0 -0 0</pose>
          <geometry>
            <cylinder>
              <length>0.2</length>
              <radius>0.15</radius>
            </cylinder>
          </geometry>
          <material>
            <script>
              <name>Gazebo/Blue</name>
              <uri>file://media/materials/scripts/gazebo.material</uri>
            </script>
          </material>
        </visual>
        <self_collide>0</self_collide>
        <enable_wind>0</enable_wind>
        <kinematic>0</kinematic>
      </link>
      <joint name='cart3_joint' type='revolute'>
        <pose relative_to='cart2'>2.7334 0 0 0 -0 0</pose>
        <parent>cart2</parent>
        <child>cart3</child>
        <axis>
          <xyz>0 0 1</xyz>
          <limit>
            <lower>-1.57</lower>
            <upper>1.57</upper>
            <effort>10</effort>
            <velocity>1</velocity>
          </limit>
          <dynamics>
            <spring_reference>0</spring_reference>
            <spring_stiffness>0</spring_stiffness>
          </dynamics>
        </axis>
      </joint>
      <link name='cart3'>
        <pose relative_to='cart3_joint'>0 0 0 0 -0 0</pose>
        <inertial>
          <pose>0.9 0 1.12 0 -0 0</pose>
          <mass>20</mass>
          <inertia>
            <ixx>4.72537</ixx>
            <ixy>0</ixy>
            <ixz>0</ixz>
            <iyy>10.6182</iyy>
            <iyz>0</iyz>
            <izz>7.84354</izz>
          </inertia>
        </inertial>
        <collision name='cart3_collision'>
          <pose>0.9 0 1.12 0 -0 0</pose>
          <geometry>
            <box>
              <size>2.03 0.765 1.5</size>
            </box>
          </geometry>
          <max_contacts>10</max_contacts>
          <surface>
            <contact>
              <ode/>
            </contact>
            <bounce/>
            <friction>
              <torsional>
                <ode/>
              </torsional>
              <ode/>
            </friction>
          </surface>
        </collision>
        <visual name='cart3_visual'>
          <pose>0.9 0 0.7 0 -0 0</pose>
          <geometry>
            <box>
              <size>2.03 0.765 1.5</size>
            </box>
          </geometry>
        </visual>
        <self_collide>0</self_collide>
        <enable_wind>0</enable_wind>
        <kinematic>0</kinematic>
      </link>
      <joint name='cart3_left_wheel_joint' type='revolute'>
        <pose relative_to='cart3'>1.6 0.55 0 -1.5708 0 0</pose>
        <parent>cart3</parent>
        <child>cart3_left_wheel</child>
        <axis>
          <xyz>0 0 1</xyz>
          <limit>
            <lower>-1e+16</lower>
            <upper>1e+16</upper>
          </limit>
          <dynamics>
            <spring_reference>0</spring_reference>
            <spring_stiffness>0</spring_stiffness>
          </dynamics>
        </axis>
      </joint>
      <link name='cart3_left_wheel'>
        <pose relative_to='cart3_left_wheel_joint'>0 0 0 0 -0 0</pose>
        <inertial>
          <pose>0 0 0 0 -0 0</pose>
          <mass>5</mass>
          <inertia>
            <ixx>0.0447917</ixx>
            <ixy>0</ixy>
            <ixz>0</ixz>
            <iyy>0.0447917</iyy>
            <iyz>0</iyz>
            <izz>0.05625</izz>
          </inertia>
        </inertial>
        <collision name='cart3_left_wheel_collision'>
          <pose>0 0 0 0 -0 0</pose>
          <geometry>
            <cylinder>
              <length>0.2</length>
              <radius>0.15</radius>
            </cylinder>
          </geometry>
          <surface>
            <contact>
              <ode/>
            </contact>
            <friction>
              <ode/>
              <torsional>
                <ode/>
              </torsional>
            </friction>
            <bounce/>
          </surface>
          <max_contacts>10</max_contacts>
        </collision>
        <visual name='cart3_left_wheel_visual'>
          <pose>0 0 0 0 -0 0</pose>
          <geometry>
            <cylinder>
              <length>0.2</length>
              <radius>0.15</radius>
            </cylinder>
          </geometry>
          <material>
            <script>
              <name>Gazebo/Blue</name>
              <uri>file://media/materials/scripts/gazebo.material</uri>
            </script>
          </material>
        </visual>
        <self_collide>0</self_collide>
        <enable_wind>0</enable_wind>
        <kinematic>0</kinematic>
      </link>
      <joint name='cart3_right_wheel_joint' type='revolute'>
        <pose relative_to='cart3'>1.6 -0.55 0 1.5708 -0 0</pose>
        <parent>cart3</parent>
        <child>cart3_right_wheel</child>
        <axis>
          <xyz>0 0 -1</xyz>
          <limit>
            <lower>-1e+16</lower>
            <upper>1e+16</upper>
          </limit>
          <dynamics>
            <spring_reference>0</spring_reference>
            <spring_stiffness>0</spring_stiffness>
          </dynamics>
        </axis>
      </joint>
      <link name='cart3_right_wheel'>
        <pose relative_to='cart3_right_wheel_joint'>0 0 0 0 -0 0</pose>
        <inertial>
          <pose>0 0 0 0 -0 0</pose>
          <mass>5</mass>
          <inertia>
            <ixx>0.0447917</ixx>
            <ixy>0</ixy>
            <ixz>0</ixz>
            <iyy>0.0447917</iyy>
            <iyz>0</iyz>
            <izz>0.05625</izz>
          </inertia>
        </inertial>
        <collision name='cart3_right_wheel_collision'>
          <pose>0 0 0 0 -0 0</pose>
          <geometry>
            <cylinder>
              <length>0.2</length>
              <radius>0.15</radius>
            </cylinder>
          </geometry>
          <surface>
            <contact>
              <ode/>
            </contact>
            <friction>
              <ode/>
              <torsional>
                <ode/>
              </torsional>
            </friction>
            <bounce/>
          </surface>
          <max_contacts>10</max_contacts>
        </collision>
        <visual name='cart3_right_wheel_visual'>
          <pose>0 0 0 0 -0 0</pose>
          <geometry>
            <cylinder>
              <length>0.2</length>
              <radius>0.15</radius>
            </cylinder>
          </geometry>
          <material>
            <script>
              <name>Gazebo/Blue</name>
              <uri>file://media/materials/scripts/gazebo.material</uri>
            </script>
          </material>
        </visual>
        <self_collide>0</self_collide>
        <enable_wind>0</enable_wind>
        <kinematic>0</kinematic>
      </link>
      <joint name='cart_left_wheel_joint' type='revolute'>
        <pose relative_to='cart'>2.2 0.8 0 -1.5708 0 0</pose>
        <parent>cart</parent>
        <child>cart_left_wheel</child>
        <axis>
          <xyz>0 0 1</xyz>
          <limit>
            <lower>-1e+16</lower>
            <upper>1e+16</upper>
          </limit>
          <dynamics>
            <spring_reference>0</spring_reference>
            <spring_stiffness>0</spring_stiffness>
          </dynamics>
        </axis>
      </joint>
      <link name='cart_left_wheel'>
        <pose relative_to='cart_left_wheel_joint'>0 0 0 0 -0 0</pose>
        <inertial>
          <pose>0 0 0 0 -0 0</pose>
          <mass>5</mass>
          <inertia>
            <ixx>0.0447917</ixx>
            <ixy>0</ixy>
            <ixz>0</ixz>
            <iyy>0.0447917</iyy>
            <iyz>0</iyz>
            <izz>0.05625</izz>
          </inertia>
        </inertial>
        <collision name='cart_left_wheel_collision'>
          <pose>0 0 0 0 -0 0</pose>
          <geometry>
            <cylinder>
              <length>0.2</length>
              <radius>0.15</radius>
            </cylinder>
          </geometry>
          <surface>
            <contact>
              <ode/>
            </contact>
            <friction>
              <ode/>
              <torsional>
                <ode/>
              </torsional>
            </friction>
            <bounce/>
          </surface>
          <max_contacts>10</max_contacts>
        </collision>
        <visual name='cart_left_wheel_visual'>
          <pose>0 0 0 0 -0 0</pose>
          <geometry>
            <cylinder>
              <length>0.2</length>
              <radius>0.15</radius>
            </cylinder>
          </geometry>
          <material>
            <script>
              <name>Gazebo/Blue</name>
              <uri>file://media/materials/scripts/gazebo.material</uri>
            </script>
          </material>
        </visual>
        <self_collide>0</self_collide>
        <enable_wind>0</enable_wind>
        <kinematic>0</kinematic>
      </link>
      <joint name='cart_right_wheel_joint' type='revolute'>
        <pose relative_to='cart'>2.2 -0.8 0 1.5708 -0 0</pose>
        <parent>cart</parent>
        <child>cart_right_wheel</child>
        <axis>
          <xyz>0 0 -1</xyz>
          <limit>
            <lower>-1e+16</lower>
            <upper>1e+16</upper>
          </limit>
          <dynamics>
            <spring_reference>0</spring_reference>
            <spring_stiffness>0</spring_stiffness>
          </dynamics>
        </axis>
      </joint>
      <link name='cart_right_wheel'>
        <pose relative_to='cart_right_wheel_joint'>0 0 0 0 -0 0</pose>
        <inertial>
          <pose>0 0 0 0 -0 0</pose>
          <mass>5</mass>
          <inertia>
            <ixx>0.0447917</ixx>
            <ixy>0</ixy>
            <ixz>0</ixz>
            <iyy>0.0447917</iyy>
            <iyz>0</iyz>
            <izz>0.05625</izz>
          </inertia>
        </inertial>
        <collision name='cart_right_wheel_collision'>
          <pose>0 0 0 0 -0 0</pose>
          <geometry>
            <cylinder>
              <length>0.2</length>
              <radius>0.15</radius>
            </cylinder>
          </geometry>
          <surface>
            <contact>
              <ode/>
            </contact>
            <friction>
              <ode/>
              <torsional>
                <ode/>
              </torsional>
            </friction>
            <bounce/>
          </surface>
          <max_contacts>10</max_contacts>
        </collision>
        <visual name='cart_right_wheel_visual'>
          <pose>0 0 0 0 -0 0</pose>
          <geometry>
            <cylinder>
              <length>0.2</length>
              <radius>0.15</radius>
            </cylinder>
          </geometry>
          <material>
            <script>
              <name>Gazebo/Blue</name>
              <uri>file://media/materials/scripts/gazebo.material</uri>
            </script>
          </material>
        </visual>
        <self_collide>0</self_collide>
        <enable_wind>0</enable_wind>
        <kinematic>0</kinematic>
      </link>
      <joint name='left_wheel_joint' type='revolute'>
        <pose relative_to='base_link'>0 0.5 0 -1.5708 0 0</pose>
        <parent>base_link</parent>
        <child>left_wheel</child>
        <axis>
          <xyz>0 0 1</xyz>
          <limit>
            <lower>-1e+16</lower>
            <upper>1e+16</upper>
          </limit>
          <dynamics>
            <spring_reference>0</spring_reference>
            <spring_stiffness>0</spring_stiffness>
          </dynamics>
        </axis>
      </joint>
      <link name='left_wheel'>
        <pose relative_to='left_wheel_joint'>0 0 0 0 -0 0</pose>
        <inertial>
          <pose>0 0 0 0 -0 0</pose>
          <mass>5</mass>
          <inertia>
            <ixx>0.0541667</ixx>
            <ixy>0</ixy>
            <ixz>0</ixz>
            <iyy>0.0541667</iyy>
            <iyz>0</iyz>
            <izz>0.1</izz>
          </inertia>
        </inertial>
        <collision name='left_wheel_collision'>
          <pose>0 0 0 0 -0 0</pose>
          <geometry>
            <cylinder>
              <length>0.1</length>
              <radius>0.2</radius>
            </cylinder>
          </geometry>
          <surface>
            <contact>
              <ode/>
            </contact>
            <friction>
              <ode/>
              <torsional>
                <ode/>
              </torsional>
            </friction>
            <bounce/>
          </surface>
          <max_contacts>10</max_contacts>
        </collision>
        <visual name='left_wheel_visual'>
          <pose>0 0 0 0 -0 0</pose>
          <geometry>
            <cylinder>
              <length>0.1</length>
              <radius>0.2</radius>
            </cylinder>
          </geometry>
          <material>
            <script>
              <name>Gazebo/Blue</name>
              <uri>file://media/materials/scripts/gazebo.material</uri>
            </script>
          </material>
        </visual>
        <self_collide>0</self_collide>
        <enable_wind>0</enable_wind>
        <kinematic>0</kinematic>
      </link>
      <joint name='right_wheel_joint' type='revolute'>
        <pose relative_to='base_link'>0 -0.5 0 1.5708 -0 0</pose>
        <parent>base_link</parent>
        <child>right_wheel</child>
        <axis>
          <xyz>0 0 -1</xyz>
          <limit>
            <lower>-1e+16</lower>
            <upper>1e+16</upper>
          </limit>
          <dynamics>
            <spring_reference>0</spring_reference>
            <spring_stiffness>0</spring_stiffness>
          </dynamics>
        </axis>
      </joint>
      <link name='right_wheel'>
        <pose relative_to='right_wheel_joint'>0 0 0 0 -0 0</pose>
        <inertial>
          <pose>0 0 0 0 -0 0</pose>
          <mass>5</mass>
          <inertia>
            <ixx>0.0541667</ixx>
            <ixy>0</ixy>
            <ixz>0</ixz>
            <iyy>0.0541667</iyy>
            <iyz>0</iyz>
            <izz>0.1</izz>
          </inertia>
        </inertial>
        <collision name='right_wheel_collision'>
          <pose>0 0 0 0 -0 0</pose>
          <geometry>
            <cylinder>
              <length>0.1</length>
              <radius>0.2</radius>
            </cylinder>
          </geometry>
          <surface>
            <contact>
              <ode/>
            </contact>
            <friction>
              <ode/>
              <torsional>
                <ode/>
              </torsional>
            </friction>
            <bounce/>
          </surface>
          <max_contacts>10</max_contacts>
        </collision>
        <visual name='right_wheel_visual'>
          <pose>0 0 0 0 -0 0</pose>
          <geometry>
            <cylinder>
              <length>0.1</length>
              <radius>0.2</radius>
            </cylinder>
          </geometry>
          <material>
            <script>
              <name>Gazebo/Blue</name>
              <uri>file://media/materials/scripts/gazebo.material</uri>
            </script>
          </material>
        </visual>
        <self_collide>0</self_collide>
        <enable_wind>0</enable_wind>
        <kinematic>0</kinematic>
      </link>
      <static>0</static>
      <plugin name='diff_drive' filename='libgazebo_ros_diff_drive.so'>
        <left_joint>left_wheel_joint</left_joint>
        <right_joint>right_wheel_joint</right_joint>
        <wheel_separation>0.35</wheel_separation>
        <wheel_diameter>0.1</wheel_diameter>
        <max_wheel_torque>200</max_wheel_torque>
        <max_wheel_acceleration>10.0</max_wheel_acceleration>
        <odometry_frame>odom</odometry_frame>
        <robot_base_frame>base_link</robot_base_frame>
        <publish_odom>1</publish_odom>
        <publish_odom_tf>1</publish_odom_tf>
        <publish_wheel_tf>1</publish_wheel_tf>
      </plugin>
      <pose>0 0 0 0 -0 0</pose>
    </model>
    <model name='unit_box'>
      <pose>5.88793 -2.63769 0.5 0 -0 0</pose>
      <link name='link'>
        <inertial>
          <mass>1</mass>
          <inertia>
            <ixx>0.166667</ixx>
            <ixy>0</ixy>
            <ixz>0</ixz>
            <iyy>0.166667</iyy>
            <iyz>0</iyz>
            <izz>0.166667</izz>
          </inertia>
          <pose>0 0 0 0 -0 0</pose>
        </inertial>
        <collision name='collision'>
          <geometry>
            <box>
              <size>1 1 1</size>
            </box>
          </geometry>
          <max_contacts>10</max_contacts>
          <surface>
            <contact>
              <ode/>
            </contact>
            <bounce/>
            <friction>
              <torsional>
                <ode/>
              </torsional>
              <ode/>
            </friction>
          </surface>
        </collision>
        <visual name='visual'>
          <geometry>
            <box>
              <size>1 1 1</size>
            </box>
          </geometry>
          <material>
            <script>
              <name>Gazebo/Grey</name>
              <uri>file://media/materials/scripts/gazebo.material</uri>
            </script>
          </material>
        </visual>
        <self_collide>0</self_collide>
        <enable_wind>0</enable_wind>
        <kinematic>0</kinematic>
      </link>
    </model>
    <model name='unit_box_0'>
      <pose>5.90525 -3.67736 0.5 0 -0 0</pose>
      <link name='link'>
        <inertial>
          <mass>1</mass>
          <inertia>
            <ixx>0.166667</ixx>
            <ixy>0</ixy>
            <ixz>0</ixz>
            <iyy>0.166667</iyy>
            <iyz>0</iyz>
            <izz>0.166667</izz>
          </inertia>
          <pose>0 0 0 0 -0 0</pose>
        </inertial>
        <collision name='collision'>
          <geometry>
            <box>
              <size>1 1 1</size>
            </box>
          </geometry>
          <max_contacts>10</max_contacts>
          <surface>
            <contact>
              <ode/>
            </contact>
            <bounce/>
            <friction>
              <torsional>
                <ode/>
              </torsional>
              <ode/>
            </friction>
          </surface>
        </collision>
        <visual name='visual'>
          <geometry>
            <box>
              <size>1 1 1</size>
            </box>
          </geometry>
          <material>
            <script>
              <name>Gazebo/Grey</name>
              <uri>file://media/materials/scripts/gazebo.material</uri>
            </script>
          </material>
        </visual>
        <self_collide>0</self_collide>
        <enable_wind>0</enable_wind>
        <kinematic>0</kinematic>
      </link>
    </model>
    <model name='unit_box_0_clone'>
      <pose>5.89899 -4.70964 0.5 0 -0 0</pose>
      <link name='link'>
        <inertial>
          <mass>1</mass>
          <inertia>
            <ixx>0.166667</ixx>
            <ixy>0</ixy>
            <ixz>0</ixz>
            <iyy>0.166667</iyy>
            <iyz>0</iyz>
            <izz>0.166667</izz>
          </inertia>
          <pose>0 0 0 0 -0 0</pose>
        </inertial>
        <collision name='collision'>
          <geometry>
            <box>
              <size>1 1 1</size>
            </box>
          </geometry>
          <max_contacts>10</max_contacts>
          <surface>
            <contact>
              <ode/>
            </contact>
            <bounce/>
            <friction>
              <torsional>
                <ode/>
              </torsional>
              <ode/>
            </friction>
          </surface>
        </collision>
        <visual name='visual'>
          <geometry>
            <box>
              <size>1 1 1</size>
            </box>
          </geometry>
          <material>
            <script>
              <name>Gazebo/Grey</name>
              <uri>file://media/materials/scripts/gazebo.material</uri>
            </script>
          </material>
        </visual>
        <self_collide>0</self_collide>
        <enable_wind>0</enable_wind>
        <kinematic>0</kinematic>
      </link>
    </model>
    <model name='unit_box_0_clone_0'>
      <pose>5.86279 -5.77739 0.5 0 -0 0</pose>
      <link name='link'>
        <inertial>
          <mass>1</mass>
          <inertia>
            <ixx>0.166667</ixx>
            <ixy>0</ixy>
            <ixz>0</ixz>
            <iyy>0.166667</iyy>
            <iyz>0</iyz>
            <izz>0.166667</izz>
          </inertia>
          <pose>0 0 0 0 -0 0</pose>
        </inertial>
        <collision name='collision'>
          <geometry>
            <box>
              <size>1 1 1</size>
            </box>
          </geometry>
          <max_contacts>10</max_contacts>
          <surface>
            <contact>
              <ode/>
            </contact>
            <bounce/>
            <friction>
              <torsional>
                <ode/>
              </torsional>
              <ode/>
            </friction>
          </surface>
        </collision>
        <visual name='visual'>
          <geometry>
            <box>
              <size>1 1 1</size>
            </box>
          </geometry>
          <material>
            <script>
              <name>Gazebo/Grey</name>
              <uri>file://media/materials/scripts/gazebo.material</uri>
            </script>
          </material>
        </visual>
        <self_collide>0</self_collide>
        <enable_wind>0</enable_wind>
        <kinematic>0</kinematic>
      </link>
    </model>
    <model name='unit_box_0_clone_1'>
      <pose>5.82059 -6.87033 0.5 0 -0 0</pose>
      <link name='link'>
        <inertial>
          <mass>1</mass>
          <inertia>
            <ixx>0.166667</ixx>
            <ixy>0</ixy>
            <ixz>0</ixz>
            <iyy>0.166667</iyy>
            <iyz>0</iyz>
            <izz>0.166667</izz>
          </inertia>
          <pose>0 0 0 0 -0 0</pose>
        </inertial>
        <collision name='collision'>
          <geometry>
            <box>
              <size>1 1 1</size>
            </box>
          </geometry>
          <max_contacts>10</max_contacts>
          <surface>
            <contact>
              <ode/>
            </contact>
            <bounce/>
            <friction>
              <torsional>
                <ode/>
              </torsional>
              <ode/>
            </friction>
          </surface>
        </collision>
        <visual name='visual'>
          <geometry>
            <box>
              <size>1 1 1</size>
            </box>
          </geometry>
          <material>
            <script>
              <name>Gazebo/Grey</name>
              <uri>file://media/materials/scripts/gazebo.material</uri>
            </script>
          </material>
        </visual>
        <self_collide>0</self_collide>
        <enable_wind>0</enable_wind>
        <kinematic>0</kinematic>
      </link>
    </model>
    <model name='unit_box_0_clone_2'>
      <pose>5.77115 -7.92569 0.5 0 -0 0</pose>
      <link name='link'>
        <inertial>
          <mass>1</mass>
          <inertia>
            <ixx>0.166667</ixx>
            <ixy>0</ixy>
            <ixz>0</ixz>
            <iyy>0.166667</iyy>
            <iyz>0</iyz>
            <izz>0.166667</izz>
          </inertia>
          <pose>0 0 0 0 -0 0</pose>
        </inertial>
        <collision name='collision'>
          <geometry>
            <box>
              <size>1 1 1</size>
            </box>
          </geometry>
          <max_contacts>10</max_contacts>
          <surface>
            <contact>
              <ode/>
            </contact>
            <bounce/>
            <friction>
              <torsional>
                <ode/>
              </torsional>
              <ode/>
            </friction>
          </surface>
        </collision>
        <visual name='visual'>
          <geometry>
            <box>
              <size>1 1 1</size>
            </box>
          </geometry>
          <material>
            <script>
              <name>Gazebo/Grey</name>
              <uri>file://media/materials/scripts/gazebo.material</uri>
            </script>
          </material>
        </visual>
        <self_collide>0</self_collide>
        <enable_wind>0</enable_wind>
        <kinematic>0</kinematic>
      </link>
    </model>
    <model name='unit_box_0_clone_3'>
      <pose>12.2713 -3.12447 0.5 0 -0 0</pose>
      <link name='link'>
        <inertial>
          <mass>1</mass>
          <inertia>
            <ixx>0.166667</ixx>
            <ixy>0</ixy>
            <ixz>0</ixz>
            <iyy>0.166667</iyy>
            <iyz>0</iyz>
            <izz>0.166667</izz>
          </inertia>
          <pose>0 0 0 0 -0 0</pose>
        </inertial>
        <collision name='collision'>
          <geometry>
            <box>
              <size>1 1 1</size>
            </box>
          </geometry>
          <max_contacts>10</max_contacts>
          <surface>
            <contact>
              <ode/>
            </contact>
            <bounce/>
            <friction>
              <torsional>
                <ode/>
              </torsional>
              <ode/>
            </friction>
          </surface>
        </collision>
        <visual name='visual'>
          <geometry>
            <box>
              <size>1 1 1</size>
            </box>
          </geometry>
          <material>
            <script>
              <name>Gazebo/Grey</name>
              <uri>file://media/materials/scripts/gazebo.material</uri>
            </script>
          </material>
        </visual>
        <self_collide>0</self_collide>
        <enable_wind>0</enable_wind>
        <kinematic>0</kinematic>
      </link>
    </model>
    <model name='unit_box_0_clone_4'>
      <pose>12.278 -4.14062 0.5 0 -0 0</pose>
      <link name='link'>
        <inertial>
          <mass>1</mass>
          <inertia>
            <ixx>0.166667</ixx>
            <ixy>0</ixy>
            <ixz>0</ixz>
            <iyy>0.166667</iyy>
            <iyz>0</iyz>
            <izz>0.166667</izz>
          </inertia>
          <pose>0 0 0 0 -0 0</pose>
        </inertial>
        <collision name='collision'>
          <geometry>
            <box>
              <size>1 1 1</size>
            </box>
          </geometry>
          <max_contacts>10</max_contacts>
          <surface>
            <contact>
              <ode/>
            </contact>
            <bounce/>
            <friction>
              <torsional>
                <ode/>
              </torsional>
              <ode/>
            </friction>
          </surface>
        </collision>
        <visual name='visual'>
          <geometry>
            <box>
              <size>1 1 1</size>
            </box>
          </geometry>
          <material>
            <script>
              <name>Gazebo/Grey</name>
              <uri>file://media/materials/scripts/gazebo.material</uri>
            </script>
          </material>
        </visual>
        <self_collide>0</self_collide>
        <enable_wind>0</enable_wind>
        <kinematic>0</kinematic>
      </link>
    </model>
    <model name='unit_box_0_clone_5'>
      <pose>12.2897 -5.17848 0.5 0 -0 0</pose>
      <link name='link'>
        <inertial>
          <mass>1</mass>
          <inertia>
            <ixx>0.166667</ixx>
            <ixy>0</ixy>
            <ixz>0</ixz>
            <iyy>0.166667</iyy>
            <iyz>0</iyz>
            <izz>0.166667</izz>
          </inertia>
          <pose>0 0 0 0 -0 0</pose>
        </inertial>
        <collision name='collision'>
          <geometry>
            <box>
              <size>1 1 1</size>
            </box>
          </geometry>
          <max_contacts>10</max_contacts>
          <surface>
            <contact>
              <ode/>
            </contact>
            <bounce/>
            <friction>
              <torsional>
                <ode/>
              </torsional>
              <ode/>
            </friction>
          </surface>
        </collision>
        <visual name='visual'>
          <geometry>
            <box>
              <size>1 1 1</size>
            </box>
          </geometry>
          <material>
            <script>
              <name>Gazebo/Grey</name>
              <uri>file://media/materials/scripts/gazebo.material</uri>
            </script>
          </material>
        </visual>
        <self_collide>0</self_collide>
        <enable_wind>0</enable_wind>
        <kinematic>0</kinematic>
      </link>
    </model>
    <model name='unit_box_0_clone_6'>
      <pose>12.2614 -6.21878 0.5 0 -0 0</pose>
      <link name='link'>
        <inertial>
          <mass>1</mass>
          <inertia>
            <ixx>0.166667</ixx>
            <ixy>0</ixy>
            <ixz>0</ixz>
            <iyy>0.166667</iyy>
            <iyz>0</iyz>
            <izz>0.166667</izz>
          </inertia>
          <pose>0 0 0 0 -0 0</pose>
        </inertial>
        <collision name='collision'>
          <geometry>
            <box>
              <size>1 1 1</size>
            </box>
          </geometry>
          <max_contacts>10</max_contacts>
          <surface>
            <contact>
              <ode/>
            </contact>
            <bounce/>
            <friction>
              <torsional>
                <ode/>
              </torsional>
              <ode/>
            </friction>
          </surface>
        </collision>
        <visual name='visual'>
          <geometry>
            <box>
              <size>1 1 1</size>
            </box>
          </geometry>
          <material>
            <script>
              <name>Gazebo/Grey</name>
              <uri>file://media/materials/scripts/gazebo.material</uri>
            </script>
          </material>
        </visual>
        <self_collide>0</self_collide>
        <enable_wind>0</enable_wind>
        <kinematic>0</kinematic>
      </link>
    </model>
    <model name='unit_box_0_clone_7'>
      <pose>12.18 -7.30325 0.5 0 -0 0</pose>
      <link name='link'>
        <inertial>
          <mass>1</mass>
          <inertia>
            <ixx>0.166667</ixx>
            <ixy>0</ixy>
            <ixz>0</ixz>
            <iyy>0.166667</iyy>
            <iyz>0</iyz>
            <izz>0.166667</izz>
          </inertia>
          <pose>0 0 0 0 -0 0</pose>
        </inertial>
        <collision name='collision'>
          <geometry>
            <box>
              <size>1 1 1</size>
            </box>
          </geometry>
          <max_contacts>10</max_contacts>
          <surface>
            <contact>
              <ode/>
            </contact>
            <bounce/>
            <friction>
              <torsional>
                <ode/>
              </torsional>
              <ode/>
            </friction>
          </surface>
        </collision>
        <visual name='visual'>
          <geometry>
            <box>
              <size>1 1 1</size>
            </box>
          </geometry>
          <material>
            <script>
              <name>Gazebo/Grey</name>
              <uri>file://media/materials/scripts/gazebo.material</uri>
            </script>
          </material>
        </visual>
        <self_collide>0</self_collide>
        <enable_wind>0</enable_wind>
        <kinematic>0</kinematic>
      </link>
    </model>
    <model name='unit_box_0_clone_8'>
      <pose>12.0953 -8.42307 0.5 0 -0 0</pose>
      <link name='link'>
        <inertial>
          <mass>1</mass>
          <inertia>
            <ixx>0.166667</ixx>
            <ixy>0</ixy>
            <ixz>0</ixz>
            <iyy>0.166667</iyy>
            <iyz>0</iyz>
            <izz>0.166667</izz>
          </inertia>
          <pose>0 0 0 0 -0 0</pose>
        </inertial>
        <collision name='collision'>
          <geometry>
            <box>
              <size>1 1 1</size>
            </box>
          </geometry>
          <max_contacts>10</max_contacts>
          <surface>
            <contact>
              <ode/>
            </contact>
            <bounce/>
            <friction>
              <torsional>
                <ode/>
              </torsional>
              <ode/>
            </friction>
          </surface>
        </collision>
        <visual name='visual'>
          <geometry>
            <box>
              <size>1 1 1</size>
            </box>
          </geometry>
          <material>
            <script>
              <name>Gazebo/Grey</name>
              <uri>file://media/materials/scripts/gazebo.material</uri>
            </script>
          </material>
        </visual>
        <self_collide>0</self_collide>
        <enable_wind>0</enable_wind>
        <kinematic>0</kinematic>
      </link>
    </model>
    <model name='unit_box_0_clone_9'>
      <pose>5.84144 -2.63183 0.5 0 -0 0</pose>
      <link name='link'>
        <inertial>
          <mass>1</mass>
          <inertia>
            <ixx>0.166667</ixx>
            <ixy>0</ixy>
            <ixz>0</ixz>
            <iyy>0.166667</iyy>
            <iyz>0</iyz>
            <izz>0.166667</izz>
          </inertia>
          <pose>0 0 0 0 -0 0</pose>
        </inertial>
        <collision name='collision'>
          <geometry>
            <box>
              <size>1 1 1</size>
            </box>
          </geometry>
          <max_contacts>10</max_contacts>
          <surface>
            <contact>
              <ode/>
            </contact>
            <bounce/>
            <friction>
              <torsional>
                <ode/>
              </torsional>
              <ode/>
            </friction>
          </surface>
        </collision>
        <visual name='visual'>
          <geometry>
            <box>
              <size>1 1 1</size>
            </box>
          </geometry>
          <material>
            <script>
              <name>Gazebo/Grey</name>
              <uri>file://media/materials/scripts/gazebo.material</uri>
            </script>
          </material>
        </visual>
        <self_collide>0</self_collide>
        <enable_wind>0</enable_wind>
        <kinematic>0</kinematic>
      </link>
    </model>
    <model name='unit_box_0_clone_10'>
      <pose>5.92704 -3.70628 0.5 0 -0 0</pose>
      <link name='link'>
        <inertial>
          <mass>1</mass>
          <inertia>
            <ixx>0.166667</ixx>
            <ixy>0</ixy>
            <ixz>0</ixz>
            <iyy>0.166667</iyy>
            <iyz>0</iyz>
            <izz>0.166667</izz>
          </inertia>
          <pose>0 0 0 0 -0 0</pose>
        </inertial>
        <collision name='collision'>
          <geometry>
            <box>
              <size>1 1 1</size>
            </box>
          </geometry>
          <max_contacts>10</max_contacts>
          <surface>
            <contact>
              <ode/>
            </contact>
            <bounce/>
            <friction>
              <torsional>
                <ode/>
              </torsional>
              <ode/>
            </friction>
          </surface>
        </collision>
        <visual name='visual'>
          <geometry>
            <box>
              <size>1 1 1</size>
            </box>
          </geometry>
          <material>
            <script>
              <name>Gazebo/Grey</name>
              <uri>file://media/materials/scripts/gazebo.material</uri>
            </script>
          </material>
        </visual>
        <self_collide>0</self_collide>
        <enable_wind>0</enable_wind>
        <kinematic>0</kinematic>
      </link>
    </model>
    <model name='unit_box_0_clone_11'>
      <pose>5.86593 -4.72821 0.5 0 -0 0</pose>
      <link name='link'>
        <inertial>
          <mass>1</mass>
          <inertia>
            <ixx>0.166667</ixx>
            <ixy>0</ixy>
            <ixz>0</ixz>
            <iyy>0.166667</iyy>
            <iyz>0</iyz>
            <izz>0.166667</izz>
          </inertia>
          <pose>0 0 0 0 -0 0</pose>
        </inertial>
        <collision name='collision'>
          <geometry>
            <box>
              <size>1 1 1</size>
            </box>
          </geometry>
          <max_contacts>10</max_contacts>
          <surface>
            <contact>
              <ode/>
            </contact>
            <bounce/>
            <friction>
              <torsional>
                <ode/>
              </torsional>
              <ode/>
            </friction>
          </surface>
        </collision>
        <visual name='visual'>
          <geometry>
            <box>
              <size>1 1 1</size>
            </box>
          </geometry>
          <material>
            <script>
              <name>Gazebo/Grey</name>
              <uri>file://media/materials/scripts/gazebo.material</uri>
            </script>
          </material>
        </visual>
        <self_collide>0</self_collide>
        <enable_wind>0</enable_wind>
        <kinematic>0</kinematic>
      </link>
    </model>
    <model name='unit_box_0_clone_12'>
      <pose>5.86134 -5.82204 0.5 0 -0 0</pose>
      <link name='link'>
        <inertial>
          <mass>1</mass>
          <inertia>
            <ixx>0.166667</ixx>
            <ixy>0</ixy>
            <ixz>0</ixz>
            <iyy>0.166667</iyy>
            <iyz>0</iyz>
            <izz>0.166667</izz>
          </inertia>
          <pose>0 0 0 0 -0 0</pose>
        </inertial>
        <collision name='collision'>
          <geometry>
            <box>
              <size>1 1 1</size>
            </box>
          </geometry>
          <max_contacts>10</max_contacts>
          <surface>
            <contact>
              <ode/>
            </contact>
            <bounce/>
            <friction>
              <torsional>
                <ode/>
              </torsional>
              <ode/>
            </friction>
          </surface>
        </collision>
        <visual name='visual'>
          <geometry>
            <box>
              <size>1 1 1</size>
            </box>
          </geometry>
          <material>
            <script>
              <name>Gazebo/Grey</name>
              <uri>file://media/materials/scripts/gazebo.material</uri>
            </script>
          </material>
        </visual>
        <self_collide>0</self_collide>
        <enable_wind>0</enable_wind>
        <kinematic>0</kinematic>
      </link>
    </model>
    <model name='unit_box_0_clone_13'>
      <pose>5.88548 -6.92463 0.5 0 -0 0</pose>
      <link name='link'>
        <inertial>
          <mass>1</mass>
          <inertia>
            <ixx>0.166667</ixx>
            <ixy>0</ixy>
            <ixz>0</ixz>
            <iyy>0.166667</iyy>
            <iyz>0</iyz>
            <izz>0.166667</izz>
          </inertia>
          <pose>0 0 0 0 -0 0</pose>
        </inertial>
        <collision name='collision'>
          <geometry>
            <box>
              <size>1 1 1</size>
            </box>
          </geometry>
          <max_contacts>10</max_contacts>
          <surface>
            <contact>
              <ode/>
            </contact>
            <bounce/>
            <friction>
              <torsional>
                <ode/>
              </torsional>
              <ode/>
            </friction>
          </surface>
        </collision>
        <visual name='visual'>
          <geometry>
            <box>
              <size>1 1 1</size>
            </box>
          </geometry>
          <material>
            <script>
              <name>Gazebo/Grey</name>
              <uri>file://media/materials/scripts/gazebo.material</uri>
            </script>
          </material>
        </visual>
        <self_collide>0</self_collide>
        <enable_wind>0</enable_wind>
        <kinematic>0</kinematic>
      </link>
    </model>
    <model name='unit_box_0_clone_14'>
      <pose>5.81792 -8.05519 0.5 0 -0 0</pose>
      <link name='link'>
        <inertial>
          <mass>1</mass>
          <inertia>
            <ixx>0.166667</ixx>
            <ixy>0</ixy>
            <ixz>0</ixz>
            <iyy>0.166667</iyy>
            <iyz>0</iyz>
            <izz>0.166667</izz>
          </inertia>
          <pose>0 0 0 0 -0 0</pose>
        </inertial>
        <collision name='collision'>
          <geometry>
            <box>
              <size>1 1 1</size>
            </box>
          </geometry>
          <max_contacts>10</max_contacts>
          <surface>
            <contact>
              <ode/>
            </contact>
            <bounce/>
            <friction>
              <torsional>
                <ode/>
              </torsional>
              <ode/>
            </friction>
          </surface>
        </collision>
        <visual name='visual'>
          <geometry>
            <box>
              <size>1 1 1</size>
            </box>
          </geometry>
          <material>
            <script>
              <name>Gazebo/Grey</name>
              <uri>file://media/materials/scripts/gazebo.material</uri>
            </script>
          </material>
        </visual>
        <self_collide>0</self_collide>
        <enable_wind>0</enable_wind>
        <kinematic>0</kinematic>
      </link>
    </model>
    <state world_name='default'>
      <sim_time>3 873000000</sim_time>
      <real_time>4 110618724</real_time>
      <wall_time>1734132375 537636591</wall_time>
      <iterations>3873</iterations>
      <model name='ground_plane'>
        <pose>0 0 0 0 -0 0</pose>
        <scale>1 1 1</scale>
        <link name='link'>
          <pose>0 0 0 0 -0 0</pose>
          <velocity>0 0 0 0 -0 0</velocity>
          <acceleration>0 0 0 0 -0 0</acceleration>
          <wrench>0 0 0 0 -0 0</wrench>
        </link>
      </model>
      <model name='my_bot'>
        <pose>-0.038033 0.021734 0.199999 0 -0.005322 -0.010668</pose>
        <scale>1 1 1</scale>
        <link name='base_link'>
          <pose>-0.038033 0.021734 0.199999 0 -0.005322 -0.010668</pose>
          <velocity>-0.001081 6.1e-05 -0.000217 5.4e-05 0.000571 -3.6e-05</velocity>
          <acceleration>-1.09978 0.021674 -1.16113 0.096576 1.15873 -0.018668</acceleration>
          <wrench>-60.8177 1.19859 -64.2103 0 -0 0</wrench>
        </link>
        <link name='cart'>
          <pose>-1.8713 0.041291 0.19024 8.1e-05 0.005321 -3.13705</pose>
          <velocity>-0.000983 0.00011 0.000434 8.4e-05 0.000619 -0.003381</velocity>
          <acceleration>-0.355174 -0.081498 1.89096 0.141135 1.26619 0.0673</acceleration>
          <wrench>-17.7587 -4.0749 94.5481 0 -0 0</wrench>
        </link>
        <link name='cart2'>
          <pose>-5.10462 0.026591 0.173036 0.000265 0.005312 -3.10237</pose>
          <velocity>-0.000214 0.011027 0.002598 0.000113 0.000817 0.004455</velocity>
          <acceleration>1.96467 -0.088743 6.73777 -2.82543 1.44609 2.76399</acceleration>
          <wrench>39.2933 -1.77486 134.755 0 -0 0</wrench>
        </link>
        <link name='cart2_left_wheel'>
          <pose>-6.67592 -0.735603 0.164722 -1.57054 0.006054 -3.10237</pose>
          <velocity>0.003171 0.004012 0.003803 0.000119 0.000645 0.004458</velocity>
          <acceleration>-0.217499 0.4439 7.6764 0.342994 0.013354 -0.468304</acceleration>
          <wrench>-1.0875 2.2195 38.382 0 -0 0</wrench>
        </link>
        <link name='cart2_right_wheel'>
          <pose>-6.73081 0.663321 0.164352 1.57106 0.010475 -3.10237</pose>
          <velocity>-0.003079 0.003765 0.004001 9e-05 0.000991 0.00446</velocity>
          <acceleration>0.272423 0.458804 8.14918 0.309856 0.012053 -0.460146</acceleration>
          <wrench>1.36211 2.29402 40.7459 0 -0 0</wrench>
        </link>
        <link name='cart3'>
          <pose>-7.83587 -0.080579 0.158511 0 0.00532 3.13114</pose>
          <velocity>0.001534 -0.001247 0.004102 0.000186 0.000569 -0.000735</velocity>
          <acceleration>4.15636 -0.013501 9.22852 0.353503 1.1244 0.331079</acceleration>
          <wrench>83.1272 -0.270019 184.57 0 -0 0</wrench>
        </link>
        <link name='cart3_left_wheel'>
          <pose>-9.44151 -0.613817 0.15 1.5708 -1.4403 -0.010454</pose>
          <velocity>0.001223 6.1e-05 0.005021 -0.000409 0.008168 -9.8e-05</velocity>
          <acceleration>3.266 0.454987 10.0614 2.10028 -0.260498 -1.17956</acceleration>
          <wrench>16.33 2.27493 50.3069 0 -0 0</wrench>
        </link>
        <link name='cart3_right_wheel'>
          <pose>-9.43001 0.486122 0.15 -1.5708 -0.763065 -0.010455</pose>
          <velocity>0.002038 -0.000159 0.005323 0.00106 0.013581 -0.000151</velocity>
          <acceleration>2.90896 0.009455 10.6636 -1.15053 -0.774568 -1.32509</acceleration>
          <wrench>14.5448 0.047277 53.3178 0 -0 0</wrench>
        </link>
        <link name='cart_left_wheel'>
          <pose>-4.06761 -0.768703 0.178598 -1.57072 -0.000693 -3.13705</pose>
          <velocity>-0.003656 0.007482 0.001573 5.8e-05 0.000546 -0.003377</velocity>
          <acceleration>-1.56934 -0.140386 3.07676 0.078855 0.000365 0.095304</acceleration>
          <wrench>-7.84669 -0.701931 15.3838 0 -0 0</wrench>
        </link>
        <link name='cart_right_wheel'>
          <pose>-4.07488 0.831281 0.178468 1.57088 0.007402 -3.13705</pose>
          <velocity>0.001744 0.007526 0.001671 4.4e-05 0.00038 -0.003375</velocity>
          <acceleration>-1.69612 -0.095343 3.2071 0.046357 0.000218 0.099325</acceleration>
          <wrench>-8.4806 -0.476716 16.0355 0 -0 0</wrench>
        </link>
        <link name='left_wheel'>
          <pose>-0.032698 0.521704 0.200001 -1.57081 -0.016106 -0.01067</pose>
          <velocity>-0.00076 -2.7e-05 6.5e-05 0.00022 -0.003303 -0.001612</velocity>
          <acceleration>-1.31041 -0.088007 0.148796 -2.63039 -0.150676 2.94995</acceleration>
          <wrench>-6.55206 -0.440034 0.743978 0 -0 0</wrench>
        </link>
        <link name='right_wheel'>
          <pose>-0.043366 -0.478237 0.200001 1.57081 -0.003569 -0.010665</pose>
          <velocity>-0.000778 9.9e-05 9.2e-05 -0.000562 -0.003407 0.001548</velocity>
          <acceleration>-1.29502 0.207444 0.197828 2.11325 -0.193771 -3.01991</acceleration>
          <wrench>-6.47508 1.03722 0.989141 0 -0 0</wrench>
        </link>
      </model>
      <model name='unit_box'>
        <pose>5.88641 -2.63811 0.5 -1e-06 -0 0.000947</pose>
        <scale>1 1 1</scale>
        <link name='link'>
          <pose>5.88641 -2.63811 0.5 -1e-06 -0 0.000947</pose>
          <velocity>0.003063 -0.004755 0.001992 0.009514 0.00613 -7e-06</velocity>
          <acceleration>2.62565 -8.89631 6.38547 -1.58797 1.56643 -0.54323</acceleration>
          <wrench>2.62565 -8.89631 6.38547 0 -0 0</wrench>
        </link>
      </model>
      <model name='unit_box_0'>
        <pose>5.90529 -3.67736 0.499996 7e-06 1e-06 1.4e-05</pose>
        <scale>1 1 1</scale>
        <link name='link'>
          <pose>5.90529 -3.67736 0.499996 7e-06 1e-06 1.4e-05</pose>
          <velocity>-0.000483 -0.003311 -0.003712 0.009152 0.001432 -0.002409</velocity>
          <acceleration>-0.848142 -4.26256 -5.08741 -0.78921 -0.76812 -1.11134</acceleration>
          <wrench>-0.848142 -4.26256 -5.08741 0 -0 0</wrench>
        </link>
      </model>
      <model name='unit_box_0_clone'>
        <pose>5.90019 -4.70989 0.499995 -1e-05 1e-06 -0.001022</pose>
        <scale>1 1 1</scale>
        <link name='link'>
          <pose>5.90019 -4.70989 0.499995 -1e-05 1e-06 -0.001022</pose>
          <velocity>-0.002112 0.006924 -0.004199 -0.013824 -0.004583 -0.000291</velocity>
          <acceleration>-4.78917 9.60867 -4.19876 2.79807 0.512799 2.85056</acceleration>
          <wrench>-4.78917 9.60867 -4.19876 0 -0 0</wrench>
        </link>
      </model>
      <model name='unit_box_0_clone_0'>
        <pose>5.86201 -5.77662 1.49999 0 -2.3e-05 -0.000837</pose>
        <scale>1 1 1</scale>
        <link name='link'>
          <pose>5.86201 -5.77662 1.49999 0 -2.3e-05 -0.000837</pose>
          <velocity>-0.005369 -0.000713 -0.00547 0.001405 -0.024065 -3.3e-05</velocity>
          <acceleration>-2.52803 -2.6205 0.858416 2.77326 0.83742 -2.43205</acceleration>
          <wrench>-2.52803 -2.6205 0.858416 0 -0 0</wrench>
        </link>
      </model>
      <model name='unit_box_0_clone_1'>
        <pose>5.82031 -6.87015 0.499997 8e-06 -3e-06 -0.000903</pose>
        <scale>1 1 1</scale>
        <link name='link'>
          <pose>5.82031 -6.87015 0.499997 8e-06 -3e-06 -0.000903</pose>
          <velocity>0.000964 -0.003407 -0.004067 0.008517 0.00023 0.001701</velocity>
          <acceleration>0.500333 -4.71251 -6.8591 -1.53676 -0.701239 1.63547</acceleration>
          <wrench>0.500333 -4.71251 -6.8591 0 -0 0</wrench>
        </link>
      </model>
      <model name='unit_box_0_clone_10'>
        <pose>5.92953 -3.67235 1.5 8e-06 0 1.6e-05</pose>
        <scale>1 1 1</scale>
        <link name='link'>
          <pose>5.92953 -3.67235 1.5 8e-06 0 1.6e-05</pose>
          <velocity>-0.000152 -0.008074 0.000881 0.000223 -0.000776 -0.002366</velocity>
          <acceleration>-3.06877 -3.95381 1.54 -2.90695 1.42776 2.84465</acceleration>
          <wrench>-3.06877 -3.95381 1.54 0 -0 0</wrench>
        </link>
      </model>
      <model name='unit_box_0_clone_11'>
        <pose>5.86697 -4.72898 1.49999 -3e-06 7e-06 -0.000936</pose>
        <scale>1 1 1</scale>
        <link name='link'>
          <pose>5.86697 -4.72898 1.49999 -3e-06 7e-06 -0.000936</pose>
          <velocity>-0.00059 0.011474 0.00311 0.004753 0.007663 -0.000473</velocity>
          <acceleration>-5.26799 6.49979 13.6818 3.05292 -0.142806 3.06697</acceleration>
          <wrench>-5.26799 6.49979 13.6818 0 -0 0</wrench>
        </link>
      </model>
      <model name='unit_box_0_clone_12'>
        <pose>5.86027 -5.82188 0.5 0 0 -0.001179</pose>
        <scale>1 1 1</scale>
        <link name='link'>
          <pose>5.86027 -5.82188 0.5 0 0 -0.001179</pose>
          <velocity>0.003332 -1.5e-05 0.003318 2.9e-05 0.006665 -6e-06</velocity>
          <acceleration>6.91953 -0.027632 6.66259 0.037655 1.27301 0.004474</acceleration>
          <wrench>6.91953 -0.027632 6.66259 0 -0 0</wrench>
        </link>
      </model>
      <model name='unit_box_0_clone_13'>
        <pose>5.82682 -6.86918 1.49999 -3e-06 -3e-06 -0.000831</pose>
        <scale>1 1 1</scale>
        <link name='link'>
          <pose>5.82682 -6.86918 1.49999 -3e-06 -3e-06 -0.000831</pose>
          <velocity>0.001177 -0.003255 -0.006459 -0.008798 0.00021 0.001707</velocity>
          <acceleration>2.23397 -0.870762 -6.20387 -0.829637 -1.17168 0.652537</acceleration>
          <wrench>2.23397 -0.870762 -6.20387 0 -0 0</wrench>
        </link>
      </model>
      <model name='unit_box_0_clone_14'>
        <pose>5.77013 -7.94972 1.5 3e-06 3e-06 -0.00124</pose>
        <scale>1 1 1</scale>
        <link name='link'>
          <pose>5.77013 -7.94972 1.5 3e-06 3e-06 -0.00124</pose>
          <velocity>0.000482 0.008777 0.010207 0.001141 0.000756 2.3e-05</velocity>
          <acceleration>-0.065066 8.19991 26.1339 3.02828 -0.713122 -0.328452</acceleration>
          <wrench>-0.065066 8.19991 26.1339 0 -0 0</wrench>
        </link>
      </model>
      <model name='unit_box_0_clone_2'>
        <pose>5.77103 -7.92555 0.5 1e-06 0 -0.001273</pose>
        <scale>1 1 1</scale>
        <link name='link'>
          <pose>5.77103 -7.92555 0.5 1e-06 0 -0.001273</pose>
          <velocity>5.1e-05 0.004673 0.005082 -0.00935 0.000104 5e-06</velocity>
          <acceleration>-0.015341 11.0607 11.4913 3.01088 0.004042 -0.019691</acceleration>
          <wrench>-0.015341 11.0607 11.4913 0 -0 0</wrench>
        </link>
      </model>
      <model name='unit_box_0_clone_3'>
        <pose>12.2713 -3.12447 0.5 0 -0 0</pose>
        <scale>1 1 1</scale>
        <link name='link'>
          <pose>12.2713 -3.12447 0.5 0 -0 0</pose>
          <velocity>-2e-06 0.004885 0.004891 -0.00977 -5e-06 -0</velocity>
          <acceleration>-0.004709 9.78112 9.78158 -0.712677 -0.009414 4.3e-05</acceleration>
          <wrench>-0.004709 9.78112 9.78158 0 -0 0</wrench>
        </link>
      </model>
      <model name='unit_box_0_clone_4'>
        <pose>12.278 -4.14062 0.5 0 -0 0</pose>
        <scale>1 1 1</scale>
        <link name='link'>
          <pose>12.278 -4.14062 0.5 0 -0 0</pose>
          <velocity>-2e-06 0.004885 0.004891 -0.00977 -5e-06 -0</velocity>
          <acceleration>-0.004709 9.78112 9.78158 -0.712677 -0.009414 4.3e-05</acceleration>
          <wrench>-0.004709 9.78112 9.78158 0 -0 0</wrench>
        </link>
      </model>
      <model name='unit_box_0_clone_5'>
        <pose>12.2897 -5.17848 0.5 0 -0 0</pose>
        <scale>1 1 1</scale>
        <link name='link'>
          <pose>12.2897 -5.17848 0.5 0 -0 0</pose>
          <velocity>-2e-06 0.004885 0.004891 -0.00977 -5e-06 -0</velocity>
          <acceleration>-0.004709 9.78112 9.78158 -0.712677 -0.009414 4.3e-05</acceleration>
          <wrench>-0.004709 9.78112 9.78158 0 -0 0</wrench>
        </link>
      </model>
      <model name='unit_box_0_clone_6'>
        <pose>12.2614 -6.21878 0.5 0 -0 0</pose>
        <scale>1 1 1</scale>
        <link name='link'>
          <pose>12.2614 -6.21878 0.5 0 -0 0</pose>
          <velocity>-2e-06 0.004885 0.004891 -0.00977 -5e-06 -0</velocity>
          <acceleration>-0.004709 9.78112 9.78158 -0.712677 -0.009414 4.3e-05</acceleration>
          <wrench>-0.004709 9.78112 9.78158 0 -0 0</wrench>
        </link>
      </model>
      <model name='unit_box_0_clone_7'>
        <pose>12.18 -7.30325 0.5 0 -0 0</pose>
        <scale>1 1 1</scale>
        <link name='link'>
          <pose>12.18 -7.30325 0.5 0 -0 0</pose>
          <velocity>-2e-06 0.004885 0.004891 -0.00977 -5e-06 -0</velocity>
          <acceleration>-0.004709 9.78112 9.78158 -0.712677 -0.009414 4.3e-05</acceleration>
          <wrench>-0.004709 9.78112 9.78158 0 -0 0</wrench>
        </link>
      </model>
      <model name='unit_box_0_clone_8'>
        <pose>12.0953 -8.42307 0.5 0 -0 0</pose>
        <scale>1 1 1</scale>
        <link name='link'>
          <pose>12.0953 -8.42307 0.5 0 -0 0</pose>
          <velocity>-2e-06 0.004885 0.004891 -0.00977 -5e-06 -0</velocity>
          <acceleration>-0.004709 9.78112 9.78158 -0.712677 -0.009414 4.3e-05</acceleration>
          <wrench>-0.004709 9.78112 9.78158 0 -0 0</wrench>
        </link>
      </model>
      <model name='unit_box_0_clone_9'>
        <pose>5.84002 -2.63244 1.5 -1.8e-05 -1.8e-05 0.000585</pose>
        <scale>1 1 1</scale>
        <link name='link'>
          <pose>5.84002 -2.63244 1.5 -1.8e-05 -1.8e-05 0.000585</pose>
          <velocity>0.001672 -0.002254 0.006943 -0.014515 -0.008914 -2.6e-05</velocity>
          <acceleration>2.67536 -6.91639 12.0873 0.527378 -1.45371 2.58246</acceleration>
          <wrench>2.67536 -6.91639 12.0873 0 -0 0</wrench>
        </link>
      </model>
      <light name='sun'>
        <pose>0 0 10 0 -0 0</pose>
      </light>
    </state>
    <gui fullscreen='0'>
      <camera name='user_camera'>
        <pose>-6.27447 -12.495 14.0801 0 0.81164 0.516197</pose>
        <view_controller>orbit</view_controller>
        <projection_type>perspective</projection_type>
      </camera>
    </gui>
  </world>
</sdf>
