<sdf version='1.7'>
  <world name='default'>
    <light name='sun' type='directional'>
      <cast_shadows>1</cast_shadows>
      <pose>0 0 10 0 -0 0</pose>
      <diffuse>0.8 0.8 0.8 1</diffuse>
      <specular>0.2 0.2 0.2 1</specular>
      <attenuation>
        <range>1000</range>
        <constant>0.9</constant>
        <linear>0.01</linear>
        <quadratic>0.001</quadratic>
      </attenuation>
      <direction>-0.5 0.1 -0.9</direction>
      <spot>
        <inner_angle>0</inner_angle>
        <outer_angle>0</outer_angle>
        <falloff>0</falloff>
      </spot>
    </light>
    <model name='ground_plane'>
      <static>1</static>
      <link name='link'>
        <collision name='collision'>
          <geometry>
            <plane>
              <normal>0 0 1</normal>
              <size>100 100</size>
            </plane>
          </geometry>
          <surface>
            <friction>
              <ode>
                <mu>100</mu>
                <mu2>50</mu2>
              </ode>
              <torsional>
                <ode/>
              </torsional>
            </friction>
            <contact>
              <ode/>
            </contact>
            <bounce/>
          </surface>
          <max_contacts>10</max_contacts>
        </collision>
        <visual name='visual'>
          <cast_shadows>0</cast_shadows>
          <geometry>
            <plane>
              <normal>0 0 1</normal>
              <size>100 100</size>
            </plane>
          </geometry>
          <material>
            <script>
              <uri>file://media/materials/scripts/gazebo.material</uri>
              <name>Gazebo/Grey</name>
            </script>
          </material>
        </visual>
        <self_collide>0</self_collide>
        <enable_wind>0</enable_wind>
        <kinematic>0</kinematic>
      </link>
    </model>
    <gravity>0 0 -9.8</gravity>
    <magnetic_field>6e-06 2.3e-05 -4.2e-05</magnetic_field>
    <atmosphere type='adiabatic'/>
    <physics type='ode'>
      <max_step_size>0.001</max_step_size>
      <real_time_factor>1</real_time_factor>
      <real_time_update_rate>1000</real_time_update_rate>
    </physics>
    <scene>
      <ambient>0.4 0.4 0.4 1</ambient>
      <background>0.7 0.7 0.7 1</background>
      <shadows>1</shadows>
    </scene>
    <audio>
      <device>default</device>
    </audio>
    <wind/>
    <spherical_coordinates>
      <surface_model>EARTH_WGS84</surface_model>
      <latitude_deg>0</latitude_deg>
      <longitude_deg>0</longitude_deg>
      <elevation>0</elevation>
      <heading_deg>0</heading_deg>
    </spherical_coordinates>
    <model name='my_bot'>
      <link name='base_link'>
        <inertial>
          <pose>0.579204 0 0.764919 0 -0 0</pose>
          <mass>55.3</mass>
          <inertia>
            <ixx>20.3378</ixx>
            <ixy>0</ixy>
            <ixz>2.43909</ixz>
            <iyy>30.6094</iyy>
            <iyz>0</iyz>
            <izz>15.6893</izz>
          </inertia>
        </inertial>
        <collision name='base_link_fixed_joint_lump__chassis_collision'>
          <pose>0.5225 0 0.85 0 -0 0</pose>
          <geometry>
            <box>
              <size>1.645 0.8 1.8</size>
            </box>
          </geometry>
          <surface>
            <contact>
              <ode/>
            </contact>
            <friction>
              <ode/>
              <torsional>
                <ode/>
              </torsional>
            </friction>
            <bounce/>
          </surface>
          <max_contacts>10</max_contacts>
        </collision>
        <collision name='base_link_fixed_joint_lump__camera_ray_collision_1'>
          <pose>1.35 0 1 0 -0 0</pose>
          <geometry>
            <cylinder>
              <length>0.04</length>
              <radius>0.05</radius>
            </cylinder>
          </geometry>
          <surface>
            <contact>
              <ode/>
            </contact>
            <friction>
              <ode/>
              <torsional>
                <ode/>
              </torsional>
            </friction>
            <bounce/>
          </surface>
          <max_contacts>10</max_contacts>
        </collision>
        <collision name='base_link_fixed_joint_lump__caster_wheel_collision_2'>
          <pose>1.1 0 -0.1 0 -0 0</pose>
          <geometry>
            <sphere>
              <radius>0.1</radius>
            </sphere>
          </geometry>
          <surface>
            <contact>
              <ode/>
            </contact>
            <friction>
              <ode>
                <mu>0.15</mu>
                <mu2>0.15</mu2>
              </ode>
              <torsional>
                <ode/>
              </torsional>
            </friction>
            <bounce/>
          </surface>
          <max_contacts>10</max_contacts>
        </collision>
        <collision name='base_link_fixed_joint_lump__lidar_l_collision_3'>
          <pose>1.35 0.4 1 0 -0 0</pose>
          <geometry>
            <cylinder>
              <length>0.04</length>
              <radius>0.05</radius>
            </cylinder>
          </geometry>
          <surface>
            <contact>
              <ode/>
            </contact>
            <friction>
              <ode/>
              <torsional>
                <ode/>
              </torsional>
            </friction>
            <bounce/>
          </surface>
          <max_contacts>10</max_contacts>
        </collision>
        <collision name='base_link_fixed_joint_lump__lidar_r_collision_4'>
          <pose>1.35 -0.4 1 0 -0 0</pose>
          <geometry>
            <cylinder>
              <length>0.04</length>
              <radius>0.05</radius>
            </cylinder>
          </geometry>
          <surface>
            <contact>
              <ode/>
            </contact>
            <friction>
              <ode/>
              <torsional>
                <ode/>
              </torsional>
            </friction>
            <bounce/>
          </surface>
          <max_contacts>10</max_contacts>
        </collision>
        <visual name='base_link_fixed_joint_lump__chassis_visual'>
          <pose>0.5225 0 0.85 0 -0 0</pose>
          <geometry>
            <box>
              <size>1.645 0.8 1.8</size>
            </box>
          </geometry>
          <material>
            <script>
              <name>Gazebo/White</name>
              <uri>file://media/materials/scripts/gazebo.material</uri>
            </script>
          </material>
        </visual>
        <visual name='base_link_fixed_joint_lump__camera_ray_visual_1'>
          <pose>1.35 0 1 0 -0 0</pose>
          <geometry>
            <cylinder>
              <length>0.04</length>
              <radius>0.05</radius>
            </cylinder>
          </geometry>
          <material>
            <script>
              <name>ambient</name>
              <uri>file://media/materials/scripts/gazebo.material</uri>
            </script>
          </material>
        </visual>
        <visual name='base_link_fixed_joint_lump__caster_wheel_visual_2'>
          <pose>1.1 0 -0.1 0 -0 0</pose>
          <geometry>
            <sphere>
              <radius>0.1</radius>
            </sphere>
          </geometry>
          <material>
            <script>
              <name>Gazebo/Black</name>
              <uri>file://media/materials/scripts/gazebo.material</uri>
            </script>
          </material>
        </visual>
        <visual name='base_link_fixed_joint_lump__lidar_l_visual_3'>
          <pose>1.35 0.4 1 0 -0 0</pose>
          <geometry>
            <cylinder>
              <length>0.04</length>
              <radius>0.05</radius>
            </cylinder>
          </geometry>
          <material>
            <script>
              <name>Gazebo/Red</name>
              <uri>file://media/materials/scripts/gazebo.material</uri>
            </script>
          </material>
        </visual>
        <visual name='base_link_fixed_joint_lump__lidar_r_visual_4'>
          <pose>1.35 -0.4 1 0 -0 0</pose>
          <geometry>
            <cylinder>
              <length>0.04</length>
              <radius>0.05</radius>
            </cylinder>
          </geometry>
          <material>
            <script>
              <name>Gazebo/Yellow</name>
              <uri>file://media/materials/scripts/gazebo.material</uri>
            </script>
          </material>
        </visual>
        <sensor name='camera_ray' type='ray'>
          <visualize>1</visualize>
          <update_rate>10</update_rate>
          <ray>
            <scan>
              <horizontal>
                <samples>86</samples>
                <min_angle>-0.75</min_angle>
                <max_angle>0.75</max_angle>
                <resolution>1</resolution>
              </horizontal>
              <vertical>
                <samples>1</samples>
                <min_angle>0</min_angle>
                <max_angle>0</max_angle>
              </vertical>
            </scan>
            <range>
              <min>0.3</min>
              <max>5</max>
            </range>
          </ray>
          <plugin name='camera_ray_controller' filename='libgazebo_ros_ray_sensor.so'>
            <ros>
              <argument>~/out:=scan</argument>
            </ros>
            <output_type>sensor_msgs/LaserScan</output_type>
            <frame_name>camera_ray</frame_name>
          </plugin>
          <pose>1.35 0 1 0 -0 0</pose>
        </sensor>
        <sensor name='lidar_l' type='ray'>
          <visualize>1</visualize>
          <update_rate>10</update_rate>
          <ray>
            <scan>
              <horizontal>
                <samples>360</samples>
                <min_angle>-3.14</min_angle>
                <max_angle>3.14</max_angle>
                <resolution>1</resolution>
              </horizontal>
              <vertical>
                <samples>1</samples>
                <min_angle>0</min_angle>
                <max_angle>0</max_angle>
              </vertical>
            </scan>
            <range>
              <min>0.3</min>
              <max>5</max>
            </range>
          </ray>
          <plugin name='lidar_l_controller' filename='libgazebo_ros_ray_sensor.so'>
            <ros>
              <argument>~/out:=scan</argument>
            </ros>
            <output_type>sensor_msgs/LaserScan</output_type>
            <frame_name>lidar_l</frame_name>
          </plugin>
          <pose>1.35 0.4 1 0 -0 0</pose>
        </sensor>
        <sensor name='lidar_r' type='ray'>
          <visualize>1</visualize>
          <update_rate>10</update_rate>
          <ray>
            <scan>
              <horizontal>
                <samples>360</samples>
                <min_angle>-3.14</min_angle>
                <max_angle>3.14</max_angle>
                <resolution>1</resolution>
              </horizontal>
              <vertical>
                <samples>1</samples>
                <min_angle>0</min_angle>
                <max_angle>0</max_angle>
              </vertical>
            </scan>
            <range>
              <min>0.3</min>
              <max>5</max>
            </range>
          </ray>
          <plugin name='lidar_r_controller' filename='libgazebo_ros_ray_sensor.so'>
            <ros>
              <argument>~/out:=scan</argument>
            </ros>
            <output_type>sensor_msgs/LaserScan</output_type>
            <frame_name>lidar_r</frame_name>
          </plugin>
          <pose>1.35 -0.4 1 0 -0 0</pose>
        </sensor>
        <self_collide>0</self_collide>
        <enable_wind>0</enable_wind>
        <kinematic>0</kinematic>
      </link>
      <joint name='cart_joint' type='revolute'>
        <pose relative_to='base_link'>-1.8334 0 0 0 -0 3.14159</pose>
        <parent>base_link</parent>
        <child>cart</child>
        <axis>
          <xyz>0 0 1</xyz>
          <limit>
            <lower>-1.57</lower>
            <upper>1.57</upper>
            <effort>10</effort>
            <velocity>1</velocity>
          </limit>
          <dynamics>
            <spring_reference>0</spring_reference>
            <spring_stiffness>0</spring_stiffness>
          </dynamics>
        </axis>
      </joint>
      <link name='cart'>
        <pose relative_to='cart_joint'>0 0 0 0 -0 0</pose>
        <inertial>
          <pose>0.9 0 1.12 0 -0 0</pose>
          <mass>50</mass>
          <inertia>
            <ixx>16.4167</ixx>
            <ixy>0</ixy>
            <ixz>0</ixz>
            <iyy>55.1634</iyy>
            <iyz>0</iyz>
            <izz>52.8301</izz>
          </inertia>
        </inertial>
        <collision name='cart_collision'>
          <pose>0.9 0 1.12 0 -0 0</pose>
          <geometry>
            <box>
              <size>3.315 1.3 1.5</size>
            </box>
          </geometry>
          <max_contacts>10</max_contacts>
          <surface>
            <contact>
              <ode/>
            </contact>
            <bounce/>
            <friction>
              <torsional>
                <ode/>
              </torsional>
              <ode/>
            </friction>
          </surface>
        </collision>
        <visual name='cart_visual'>
          <pose>0.9 0 0.7 0 -0 0</pose>
          <geometry>
            <box>
              <size>3.315 1.3 1.5</size>
            </box>
          </geometry>
        </visual>
        <self_collide>0</self_collide>
        <enable_wind>0</enable_wind>
        <kinematic>0</kinematic>
      </link>
      <joint name='cart2_joint' type='revolute'>
        <pose relative_to='cart'>3.2334 0 0 0 -0 0</pose>
        <parent>cart</parent>
        <child>cart2</child>
        <axis>
          <xyz>0 0 1</xyz>
          <limit>
            <lower>-1.57</lower>
            <upper>1.57</upper>
            <effort>10</effort>
            <velocity>1</velocity>
          </limit>
          <dynamics>
            <spring_reference>0</spring_reference>
            <spring_stiffness>0</spring_stiffness>
          </dynamics>
        </axis>
      </joint>
      <link name='cart2'>
        <pose relative_to='cart2_joint'>0 0 0 0 -0 0</pose>
        <inertial>
          <pose>0.9 0 1.12 0 -0 0</pose>
          <mass>20</mass>
          <inertia>
            <ixx>5.8035</ixx>
            <ixy>0</ixy>
            <ixz>0</ixz>
            <iyy>9.15</iyy>
            <iyz>0</iyz>
            <izz>7.4535</izz>
          </inertia>
        </inertial>
        <collision name='cart2_collision'>
          <pose>0.9 0 1.12 0 -0 0</pose>
          <geometry>
            <box>
              <size>1.8 1.11 1.5</size>
            </box>
          </geometry>
          <max_contacts>10</max_contacts>
          <surface>
            <contact>
              <ode/>
            </contact>
            <bounce/>
            <friction>
              <torsional>
                <ode/>
              </torsional>
              <ode/>
            </friction>
          </surface>
        </collision>
        <visual name='cart2_visual'>
          <pose>0.9 0 0.7 0 -0 0</pose>
          <geometry>
            <box>
              <size>1.8 1.11 1.5</size>
            </box>
          </geometry>
        </visual>
        <self_collide>0</self_collide>
        <enable_wind>0</enable_wind>
        <kinematic>0</kinematic>
      </link>
      <joint name='cart2_left_wheel_joint' type='revolute'>
        <pose relative_to='cart2'>1.6 0.55 0 -1.5708 0 0</pose>
        <parent>cart2</parent>
        <child>cart2_left_wheel</child>
        <axis>
          <xyz>0 0 1</xyz>
          <limit>
            <lower>-1e+16</lower>
            <upper>1e+16</upper>
          </limit>
          <dynamics>
            <spring_reference>0</spring_reference>
            <spring_stiffness>0</spring_stiffness>
          </dynamics>
        </axis>
      </joint>
      <link name='cart2_left_wheel'>
        <pose relative_to='cart2_left_wheel_joint'>0 0 0 0 -0 0</pose>
        <inertial>
          <pose>0 0 0 0 -0 0</pose>
          <mass>5</mass>
          <inertia>
            <ixx>0.0447917</ixx>
            <ixy>0</ixy>
            <ixz>0</ixz>
            <iyy>0.0447917</iyy>
            <iyz>0</iyz>
            <izz>0.05625</izz>
          </inertia>
        </inertial>
        <collision name='cart2_left_wheel_collision'>
          <pose>0 0 0 0 -0 0</pose>
          <geometry>
            <cylinder>
              <length>0.2</length>
              <radius>0.15</radius>
            </cylinder>
          </geometry>
          <surface>
            <contact>
              <ode/>
            </contact>
            <friction>
              <ode/>
              <torsional>
                <ode/>
              </torsional>
            </friction>
            <bounce/>
          </surface>
          <max_contacts>10</max_contacts>
        </collision>
        <visual name='cart2_left_wheel_visual'>
          <pose>0 0 0 0 -0 0</pose>
          <geometry>
            <cylinder>
              <length>0.2</length>
              <radius>0.15</radius>
            </cylinder>
          </geometry>
          <material>
            <script>
              <name>Gazebo/Blue</name>
              <uri>file://media/materials/scripts/gazebo.material</uri>
            </script>
          </material>
        </visual>
        <self_collide>0</self_collide>
        <enable_wind>0</enable_wind>
        <kinematic>0</kinematic>
      </link>
      <joint name='cart2_right_wheel_joint' type='revolute'>
        <pose relative_to='cart2'>1.6 -0.55 0 1.5708 -0 0</pose>
        <parent>cart2</parent>
        <child>cart2_right_wheel</child>
        <axis>
          <xyz>0 0 -1</xyz>
          <limit>
            <lower>-1e+16</lower>
            <upper>1e+16</upper>
          </limit>
          <dynamics>
            <spring_reference>0</spring_reference>
            <spring_stiffness>0</spring_stiffness>
          </dynamics>
        </axis>
      </joint>
      <link name='cart2_right_wheel'>
        <pose relative_to='cart2_right_wheel_joint'>0 0 0 0 -0 0</pose>
        <inertial>
          <pose>0 0 0 0 -0 0</pose>
          <mass>5</mass>
          <inertia>
            <ixx>0.0447917</ixx>
            <ixy>0</ixy>
            <ixz>0</ixz>
            <iyy>0.0447917</iyy>
            <iyz>0</iyz>
            <izz>0.05625</izz>
          </inertia>
        </inertial>
        <collision name='cart2_right_wheel_collision'>
          <pose>0 0 0 0 -0 0</pose>
          <geometry>
            <cylinder>
              <length>0.2</length>
              <radius>0.15</radius>
            </cylinder>
          </geometry>
          <surface>
            <contact>
              <ode/>
            </contact>
            <friction>
              <ode/>
              <torsional>
                <ode/>
              </torsional>
            </friction>
            <bounce/>
          </surface>
          <max_contacts>10</max_contacts>
        </collision>
        <visual name='cart2_right_wheel_visual'>
          <pose>0 0 0 0 -0 0</pose>
          <geometry>
            <cylinder>
              <length>0.2</length>
              <radius>0.15</radius>
            </cylinder>
          </geometry>
          <material>
            <script>
              <name>Gazebo/Blue</name>
              <uri>file://media/materials/scripts/gazebo.material</uri>
            </script>
          </material>
        </visual>
        <self_collide>0</self_collide>
        <enable_wind>0</enable_wind>
        <kinematic>0</kinematic>
      </link>
      <joint name='cart3_joint' type='revolute'>
        <pose relative_to='cart2'>2.7334 0 0 0 -0 0</pose>
        <parent>cart2</parent>
        <child>cart3</child>
        <axis>
          <xyz>0 0 1</xyz>
          <limit>
            <lower>-1.57</lower>
            <upper>1.57</upper>
            <effort>10</effort>
            <velocity>1</velocity>
          </limit>
          <dynamics>
            <spring_reference>0</spring_reference>
            <spring_stiffness>0</spring_stiffness>
          </dynamics>
        </axis>
      </joint>
      <link name='cart3'>
        <pose relative_to='cart3_joint'>0 0 0 0 -0 0</pose>
        <inertial>
          <pose>0.9 0 1.12 0 -0 0</pose>
          <mass>20</mass>
          <inertia>
            <ixx>4.72537</ixx>
            <ixy>0</ixy>
            <ixz>0</ixz>
            <iyy>10.6182</iyy>
            <iyz>0</iyz>
            <izz>7.84354</izz>
          </inertia>
        </inertial>
        <collision name='cart3_collision'>
          <pose>0.9 0 1.12 0 -0 0</pose>
          <geometry>
            <box>
              <size>2.03 0.765 1.5</size>
            </box>
          </geometry>
          <max_contacts>10</max_contacts>
          <surface>
            <contact>
              <ode/>
            </contact>
            <bounce/>
            <friction>
              <torsional>
                <ode/>
              </torsional>
              <ode/>
            </friction>
          </surface>
        </collision>
        <visual name='cart3_visual'>
          <pose>0.9 0 0.7 0 -0 0</pose>
          <geometry>
            <box>
              <size>2.03 0.765 1.5</size>
            </box>
          </geometry>
        </visual>
        <self_collide>0</self_collide>
        <enable_wind>0</enable_wind>
        <kinematic>0</kinematic>
      </link>
      <joint name='cart3_left_wheel_joint' type='revolute'>
        <pose relative_to='cart3'>1.6 0.55 0 -1.5708 0 0</pose>
        <parent>cart3</parent>
        <child>cart3_left_wheel</child>
        <axis>
          <xyz>0 0 1</xyz>
          <limit>
            <lower>-1e+16</lower>
            <upper>1e+16</upper>
          </limit>
          <dynamics>
            <spring_reference>0</spring_reference>
            <spring_stiffness>0</spring_stiffness>
          </dynamics>
        </axis>
      </joint>
      <link name='cart3_left_wheel'>
        <pose relative_to='cart3_left_wheel_joint'>0 0 0 0 -0 0</pose>
        <inertial>
          <pose>0 0 0 0 -0 0</pose>
          <mass>5</mass>
          <inertia>
            <ixx>0.0447917</ixx>
            <ixy>0</ixy>
            <ixz>0</ixz>
            <iyy>0.0447917</iyy>
            <iyz>0</iyz>
            <izz>0.05625</izz>
          </inertia>
        </inertial>
        <collision name='cart3_left_wheel_collision'>
          <pose>0 0 0 0 -0 0</pose>
          <geometry>
            <cylinder>
              <length>0.2</length>
              <radius>0.15</radius>
            </cylinder>
          </geometry>
          <surface>
            <contact>
              <ode/>
            </contact>
            <friction>
              <ode/>
              <torsional>
                <ode/>
              </torsional>
            </friction>
            <bounce/>
          </surface>
          <max_contacts>10</max_contacts>
        </collision>
        <visual name='cart3_left_wheel_visual'>
          <pose>0 0 0 0 -0 0</pose>
          <geometry>
            <cylinder>
              <length>0.2</length>
              <radius>0.15</radius>
            </cylinder>
          </geometry>
          <material>
            <script>
              <name>Gazebo/Blue</name>
              <uri>file://media/materials/scripts/gazebo.material</uri>
            </script>
          </material>
        </visual>
        <self_collide>0</self_collide>
        <enable_wind>0</enable_wind>
        <kinematic>0</kinematic>
      </link>
      <joint name='cart3_right_wheel_joint' type='revolute'>
        <pose relative_to='cart3'>1.6 -0.55 0 1.5708 -0 0</pose>
        <parent>cart3</parent>
        <child>cart3_right_wheel</child>
        <axis>
          <xyz>0 0 -1</xyz>
          <limit>
            <lower>-1e+16</lower>
            <upper>1e+16</upper>
          </limit>
          <dynamics>
            <spring_reference>0</spring_reference>
            <spring_stiffness>0</spring_stiffness>
          </dynamics>
        </axis>
      </joint>
      <link name='cart3_right_wheel'>
        <pose relative_to='cart3_right_wheel_joint'>0 0 0 0 -0 0</pose>
        <inertial>
          <pose>0 0 0 0 -0 0</pose>
          <mass>5</mass>
          <inertia>
            <ixx>0.0447917</ixx>
            <ixy>0</ixy>
            <ixz>0</ixz>
            <iyy>0.0447917</iyy>
            <iyz>0</iyz>
            <izz>0.05625</izz>
          </inertia>
        </inertial>
        <collision name='cart3_right_wheel_collision'>
          <pose>0 0 0 0 -0 0</pose>
          <geometry>
            <cylinder>
              <length>0.2</length>
              <radius>0.15</radius>
            </cylinder>
          </geometry>
          <surface>
            <contact>
              <ode/>
            </contact>
            <friction>
              <ode/>
              <torsional>
                <ode/>
              </torsional>
            </friction>
            <bounce/>
          </surface>
          <max_contacts>10</max_contacts>
        </collision>
        <visual name='cart3_right_wheel_visual'>
          <pose>0 0 0 0 -0 0</pose>
          <geometry>
            <cylinder>
              <length>0.2</length>
              <radius>0.15</radius>
            </cylinder>
          </geometry>
          <material>
            <script>
              <name>Gazebo/Blue</name>
              <uri>file://media/materials/scripts/gazebo.material</uri>
            </script>
          </material>
        </visual>
        <self_collide>0</self_collide>
        <enable_wind>0</enable_wind>
        <kinematic>0</kinematic>
      </link>
      <joint name='cart_left_wheel_joint' type='revolute'>
        <pose relative_to='cart'>2.2 0.6 0 -1.5708 0 0</pose>
        <parent>cart</parent>
        <child>cart_left_wheel</child>
        <axis>
          <xyz>0 0 1</xyz>
          <limit>
            <lower>-1e+16</lower>
            <upper>1e+16</upper>
          </limit>
          <dynamics>
            <spring_reference>0</spring_reference>
            <spring_stiffness>0</spring_stiffness>
          </dynamics>
        </axis>
      </joint>
      <link name='cart_left_wheel'>
        <pose relative_to='cart_left_wheel_joint'>0 0 0 0 -0 0</pose>
        <inertial>
          <pose>0 0 0 0 -0 0</pose>
          <mass>5</mass>
          <inertia>
            <ixx>0.0447917</ixx>
            <ixy>0</ixy>
            <ixz>0</ixz>
            <iyy>0.0447917</iyy>
            <iyz>0</iyz>
            <izz>0.05625</izz>
          </inertia>
        </inertial>
        <collision name='cart_left_wheel_collision'>
          <pose>0 0 0 0 -0 0</pose>
          <geometry>
            <cylinder>
              <length>0.2</length>
              <radius>0.15</radius>
            </cylinder>
          </geometry>
          <surface>
            <contact>
              <ode/>
            </contact>
            <friction>
              <ode/>
              <torsional>
                <ode/>
              </torsional>
            </friction>
            <bounce/>
          </surface>
          <max_contacts>10</max_contacts>
        </collision>
        <visual name='cart_left_wheel_visual'>
          <pose>0 0 0 0 -0 0</pose>
          <geometry>
            <cylinder>
              <length>0.2</length>
              <radius>0.15</radius>
            </cylinder>
          </geometry>
          <material>
            <script>
              <name>Gazebo/Blue</name>
              <uri>file://media/materials/scripts/gazebo.material</uri>
            </script>
          </material>
        </visual>
        <self_collide>0</self_collide>
        <enable_wind>0</enable_wind>
        <kinematic>0</kinematic>
      </link>
      <joint name='cart_right_wheel_joint' type='revolute'>
        <pose relative_to='cart'>2.2 -0.6 0 1.5708 -0 0</pose>
        <parent>cart</parent>
        <child>cart_right_wheel</child>
        <axis>
          <xyz>0 0 -1</xyz>
          <limit>
            <lower>-1e+16</lower>
            <upper>1e+16</upper>
          </limit>
          <dynamics>
            <spring_reference>0</spring_reference>
            <spring_stiffness>0</spring_stiffness>
          </dynamics>
        </axis>
      </joint>
      <link name='cart_right_wheel'>
        <pose relative_to='cart_right_wheel_joint'>0 0 0 0 -0 0</pose>
        <inertial>
          <pose>0 0 0 0 -0 0</pose>
          <mass>5</mass>
          <inertia>
            <ixx>0.0447917</ixx>
            <ixy>0</ixy>
            <ixz>0</ixz>
            <iyy>0.0447917</iyy>
            <iyz>0</iyz>
            <izz>0.05625</izz>
          </inertia>
        </inertial>
        <collision name='cart_right_wheel_collision'>
          <pose>0 0 0 0 -0 0</pose>
          <geometry>
            <cylinder>
              <length>0.2</length>
              <radius>0.15</radius>
            </cylinder>
          </geometry>
          <surface>
            <contact>
              <ode/>
            </contact>
            <friction>
              <ode/>
              <torsional>
                <ode/>
              </torsional>
            </friction>
            <bounce/>
          </surface>
          <max_contacts>10</max_contacts>
        </collision>
        <visual name='cart_right_wheel_visual'>
          <pose>0 0 0 0 -0 0</pose>
          <geometry>
            <cylinder>
              <length>0.2</length>
              <radius>0.15</radius>
            </cylinder>
          </geometry>
          <material>
            <script>
              <name>Gazebo/Blue</name>
              <uri>file://media/materials/scripts/gazebo.material</uri>
            </script>
          </material>
        </visual>
        <self_collide>0</self_collide>
        <enable_wind>0</enable_wind>
        <kinematic>0</kinematic>
      </link>
      <joint name='left_wheel_joint' type='revolute'>
        <pose relative_to='base_link'>0 0.4 0 -1.5708 0 0</pose>
        <parent>base_link</parent>
        <child>left_wheel</child>
        <axis>
          <xyz>0 0 1</xyz>
          <limit>
            <lower>-1e+16</lower>
            <upper>1e+16</upper>
          </limit>
          <dynamics>
            <spring_reference>0</spring_reference>
            <spring_stiffness>0</spring_stiffness>
          </dynamics>
        </axis>
      </joint>
      <link name='left_wheel'>
        <pose relative_to='left_wheel_joint'>0 0 0 0 -0 0</pose>
        <inertial>
          <pose>0 0 0 0 -0 0</pose>
          <mass>5</mass>
          <inertia>
            <ixx>0.0541667</ixx>
            <ixy>0</ixy>
            <ixz>0</ixz>
            <iyy>0.0541667</iyy>
            <iyz>0</iyz>
            <izz>0.1</izz>
          </inertia>
        </inertial>
        <collision name='left_wheel_collision'>
          <pose>0 0 0 0 -0 0</pose>
          <geometry>
            <cylinder>
              <length>0.1</length>
              <radius>0.2</radius>
            </cylinder>
          </geometry>
          <surface>
            <contact>
              <ode/>
            </contact>
            <friction>
              <ode/>
              <torsional>
                <ode/>
              </torsional>
            </friction>
            <bounce/>
          </surface>
          <max_contacts>10</max_contacts>
        </collision>
        <visual name='left_wheel_visual'>
          <pose>0 0 0 0 -0 0</pose>
          <geometry>
            <cylinder>
              <length>0.1</length>
              <radius>0.2</radius>
            </cylinder>
          </geometry>
          <material>
            <script>
              <name>Gazebo/Blue</name>
              <uri>file://media/materials/scripts/gazebo.material</uri>
            </script>
          </material>
        </visual>
        <self_collide>0</self_collide>
        <enable_wind>0</enable_wind>
        <kinematic>0</kinematic>
      </link>
      <joint name='right_wheel_joint' type='revolute'>
        <pose relative_to='base_link'>0 -0.4 0 1.5708 -0 0</pose>
        <parent>base_link</parent>
        <child>right_wheel</child>
        <axis>
          <xyz>0 0 -1</xyz>
          <limit>
            <lower>-1e+16</lower>
            <upper>1e+16</upper>
          </limit>
          <dynamics>
            <spring_reference>0</spring_reference>
            <spring_stiffness>0</spring_stiffness>
          </dynamics>
        </axis>
      </joint>
      <link name='right_wheel'>
        <pose relative_to='right_wheel_joint'>0 0 0 0 -0 0</pose>
        <inertial>
          <pose>0 0 0 0 -0 0</pose>
          <mass>5</mass>
          <inertia>
            <ixx>0.0541667</ixx>
            <ixy>0</ixy>
            <ixz>0</ixz>
            <iyy>0.0541667</iyy>
            <iyz>0</iyz>
            <izz>0.1</izz>
          </inertia>
        </inertial>
        <collision name='right_wheel_collision'>
          <pose>0 0 0 0 -0 0</pose>
          <geometry>
            <cylinder>
              <length>0.1</length>
              <radius>0.2</radius>
            </cylinder>
          </geometry>
          <surface>
            <contact>
              <ode/>
            </contact>
            <friction>
              <ode/>
              <torsional>
                <ode/>
              </torsional>
            </friction>
            <bounce/>
          </surface>
          <max_contacts>10</max_contacts>
        </collision>
        <visual name='right_wheel_visual'>
          <pose>0 0 0 0 -0 0</pose>
          <geometry>
            <cylinder>
              <length>0.1</length>
              <radius>0.2</radius>
            </cylinder>
          </geometry>
          <material>
            <script>
              <name>Gazebo/Blue</name>
              <uri>file://media/materials/scripts/gazebo.material</uri>
            </script>
          </material>
        </visual>
        <self_collide>0</self_collide>
        <enable_wind>0</enable_wind>
        <kinematic>0</kinematic>
      </link>
      <static>0</static>
      <plugin name='diff_drive' filename='libgazebo_ros_diff_drive.so'>
        <left_joint>left_wheel_joint</left_joint>
        <right_joint>right_wheel_joint</right_joint>
        <wheel_separation>0.35</wheel_separation>
        <wheel_diameter>0.1</wheel_diameter>
        <max_wheel_torque>200</max_wheel_torque>
        <max_wheel_acceleration>10.0</max_wheel_acceleration>
        <odometry_frame>odom</odometry_frame>
        <robot_base_frame>base_link</robot_base_frame>
        <publish_odom>1</publish_odom>
        <publish_odom_tf>1</publish_odom_tf>
        <publish_wheel_tf>1</publish_wheel_tf>
      </plugin>
      <pose>0 0 0 0 -0 0</pose>
    </model>
    <model name='unit_box'>
      <pose>4.23848 -3.09226 0.5 0 -0 0</pose>
      <link name='link'>
        <inertial>
          <mass>1</mass>
          <inertia>
            <ixx>0.166667</ixx>
            <ixy>0</ixy>
            <ixz>0</ixz>
            <iyy>0.166667</iyy>
            <iyz>0</iyz>
            <izz>0.166667</izz>
          </inertia>
          <pose>0 0 0 0 -0 0</pose>
        </inertial>
        <collision name='collision'>
          <geometry>
            <box>
              <size>1 1 1</size>
            </box>
          </geometry>
          <max_contacts>10</max_contacts>
          <surface>
            <contact>
              <ode/>
            </contact>
            <bounce/>
            <friction>
              <torsional>
                <ode/>
              </torsional>
              <ode/>
            </friction>
          </surface>
        </collision>
        <visual name='visual'>
          <geometry>
            <box>
              <size>1 1 1</size>
            </box>
          </geometry>
          <material>
            <script>
              <name>Gazebo/Grey</name>
              <uri>file://media/materials/scripts/gazebo.material</uri>
            </script>
          </material>
        </visual>
        <self_collide>0</self_collide>
        <enable_wind>0</enable_wind>
        <kinematic>0</kinematic>
      </link>
    </model>
    <model name='unit_box_clone'>
      <pose>3.135 -2.9547 0.5 0 -0 0</pose>
      <link name='link'>
        <inertial>
          <mass>1</mass>
          <inertia>
            <ixx>0.166667</ixx>
            <ixy>0</ixy>
            <ixz>0</ixz>
            <iyy>0.166667</iyy>
            <iyz>0</iyz>
            <izz>0.166667</izz>
          </inertia>
          <pose>0 0 0 0 -0 0</pose>
        </inertial>
        <collision name='collision'>
          <geometry>
            <box>
              <size>1 1 1</size>
            </box>
          </geometry>
          <max_contacts>10</max_contacts>
          <surface>
            <contact>
              <ode/>
            </contact>
            <bounce/>
            <friction>
              <torsional>
                <ode/>
              </torsional>
              <ode/>
            </friction>
          </surface>
        </collision>
        <visual name='visual'>
          <geometry>
            <box>
              <size>1 1 1</size>
            </box>
          </geometry>
          <material>
            <script>
              <name>Gazebo/Grey</name>
              <uri>file://media/materials/scripts/gazebo.material</uri>
            </script>
          </material>
        </visual>
        <self_collide>0</self_collide>
        <enable_wind>0</enable_wind>
        <kinematic>0</kinematic>
      </link>
    </model>
    <model name='unit_box_clone_0'>
      <pose>1.88411 -3.0355 0.5 0 -0 0</pose>
      <link name='link'>
        <inertial>
          <mass>1</mass>
          <inertia>
            <ixx>0.166667</ixx>
            <ixy>0</ixy>
            <ixz>0</ixz>
            <iyy>0.166667</iyy>
            <iyz>0</iyz>
            <izz>0.166667</izz>
          </inertia>
          <pose>0 0 0 0 -0 0</pose>
        </inertial>
        <collision name='collision'>
          <geometry>
            <box>
              <size>1 1 1</size>
            </box>
          </geometry>
          <max_contacts>10</max_contacts>
          <surface>
            <contact>
              <ode/>
            </contact>
            <bounce/>
            <friction>
              <torsional>
                <ode/>
              </torsional>
              <ode/>
            </friction>
          </surface>
        </collision>
        <visual name='visual'>
          <geometry>
            <box>
              <size>1 1 1</size>
            </box>
          </geometry>
          <material>
            <script>
              <name>Gazebo/Grey</name>
              <uri>file://media/materials/scripts/gazebo.material</uri>
            </script>
          </material>
        </visual>
        <self_collide>0</self_collide>
        <enable_wind>0</enable_wind>
        <kinematic>0</kinematic>
      </link>
    </model>
    <model name='unit_box_clone_1'>
      <pose>4.21544 -4.03887 0.5 0 -0 0</pose>
      <link name='link'>
        <inertial>
          <mass>1</mass>
          <inertia>
            <ixx>0.166667</ixx>
            <ixy>0</ixy>
            <ixz>0</ixz>
            <iyy>0.166667</iyy>
            <iyz>0</iyz>
            <izz>0.166667</izz>
          </inertia>
          <pose>0 0 0 0 -0 0</pose>
        </inertial>
        <collision name='collision'>
          <geometry>
            <box>
              <size>1 1 1</size>
            </box>
          </geometry>
          <max_contacts>10</max_contacts>
          <surface>
            <contact>
              <ode/>
            </contact>
            <bounce/>
            <friction>
              <torsional>
                <ode/>
              </torsional>
              <ode/>
            </friction>
          </surface>
        </collision>
        <visual name='visual'>
          <geometry>
            <box>
              <size>1 1 1</size>
            </box>
          </geometry>
          <material>
            <script>
              <name>Gazebo/Grey</name>
              <uri>file://media/materials/scripts/gazebo.material</uri>
            </script>
          </material>
        </visual>
        <self_collide>0</self_collide>
        <enable_wind>0</enable_wind>
        <kinematic>0</kinematic>
      </link>
    </model>
    <model name='unit_box_clone_2'>
      <pose>4.23785 -5.15744 0.5 0 -0 0</pose>
      <link name='link'>
        <inertial>
          <mass>1</mass>
          <inertia>
            <ixx>0.166667</ixx>
            <ixy>0</ixy>
            <ixz>0</ixz>
            <iyy>0.166667</iyy>
            <iyz>0</iyz>
            <izz>0.166667</izz>
          </inertia>
          <pose>0 0 0 0 -0 0</pose>
        </inertial>
        <collision name='collision'>
          <geometry>
            <box>
              <size>1 1 1</size>
            </box>
          </geometry>
          <max_contacts>10</max_contacts>
          <surface>
            <contact>
              <ode/>
            </contact>
            <bounce/>
            <friction>
              <torsional>
                <ode/>
              </torsional>
              <ode/>
            </friction>
          </surface>
        </collision>
        <visual name='visual'>
          <geometry>
            <box>
              <size>1 1 1</size>
            </box>
          </geometry>
          <material>
            <script>
              <name>Gazebo/Grey</name>
              <uri>file://media/materials/scripts/gazebo.material</uri>
            </script>
          </material>
        </visual>
        <self_collide>0</self_collide>
        <enable_wind>0</enable_wind>
        <kinematic>0</kinematic>
      </link>
    </model>
    <model name='unit_box_clone_3'>
      <pose>4.30768 -6.24066 0.5 0 -0 0</pose>
      <link name='link'>
        <inertial>
          <mass>1</mass>
          <inertia>
            <ixx>0.166667</ixx>
            <ixy>0</ixy>
            <ixz>0</ixz>
            <iyy>0.166667</iyy>
            <iyz>0</iyz>
            <izz>0.166667</izz>
          </inertia>
          <pose>0 0 0 0 -0 0</pose>
        </inertial>
        <collision name='collision'>
          <geometry>
            <box>
              <size>1 1 1</size>
            </box>
          </geometry>
          <max_contacts>10</max_contacts>
          <surface>
            <contact>
              <ode/>
            </contact>
            <bounce/>
            <friction>
              <torsional>
                <ode/>
              </torsional>
              <ode/>
            </friction>
          </surface>
        </collision>
        <visual name='visual'>
          <geometry>
            <box>
              <size>1 1 1</size>
            </box>
          </geometry>
          <material>
            <script>
              <name>Gazebo/Grey</name>
              <uri>file://media/materials/scripts/gazebo.material</uri>
            </script>
          </material>
        </visual>
        <self_collide>0</self_collide>
        <enable_wind>0</enable_wind>
        <kinematic>0</kinematic>
      </link>
    </model>
    <model name='unit_box_clone_4'>
      <pose>4.33199 -7.29131 0.5 0 -0 0</pose>
      <link name='link'>
        <inertial>
          <mass>1</mass>
          <inertia>
            <ixx>0.166667</ixx>
            <ixy>0</ixy>
            <ixz>0</ixz>
            <iyy>0.166667</iyy>
            <iyz>0</iyz>
            <izz>0.166667</izz>
          </inertia>
          <pose>0 0 0 0 -0 0</pose>
        </inertial>
        <collision name='collision'>
          <geometry>
            <box>
              <size>1 1 1</size>
            </box>
          </geometry>
          <max_contacts>10</max_contacts>
          <surface>
            <contact>
              <ode/>
            </contact>
            <bounce/>
            <friction>
              <torsional>
                <ode/>
              </torsional>
              <ode/>
            </friction>
          </surface>
        </collision>
        <visual name='visual'>
          <geometry>
            <box>
              <size>1 1 1</size>
            </box>
          </geometry>
          <material>
            <script>
              <name>Gazebo/Grey</name>
              <uri>file://media/materials/scripts/gazebo.material</uri>
            </script>
          </material>
        </visual>
        <self_collide>0</self_collide>
        <enable_wind>0</enable_wind>
        <kinematic>0</kinematic>
      </link>
    </model>
    <model name='unit_box_clone_4_clone'>
      <pose>6.93809 -4.73144 0.5 0 -0 0</pose>
      <link name='link'>
        <inertial>
          <mass>1</mass>
          <inertia>
            <ixx>0.166667</ixx>
            <ixy>0</ixy>
            <ixz>0</ixz>
            <iyy>0.166667</iyy>
            <iyz>0</iyz>
            <izz>0.166667</izz>
          </inertia>
          <pose>0 0 0 0 -0 0</pose>
        </inertial>
        <collision name='collision'>
          <geometry>
            <box>
              <size>1 1 1</size>
            </box>
          </geometry>
          <max_contacts>10</max_contacts>
          <surface>
            <contact>
              <ode/>
            </contact>
            <bounce/>
            <friction>
              <torsional>
                <ode/>
              </torsional>
              <ode/>
            </friction>
          </surface>
        </collision>
        <visual name='visual'>
          <geometry>
            <box>
              <size>1 1 1</size>
            </box>
          </geometry>
          <material>
            <script>
              <name>Gazebo/Grey</name>
              <uri>file://media/materials/scripts/gazebo.material</uri>
            </script>
          </material>
        </visual>
        <self_collide>0</self_collide>
        <enable_wind>0</enable_wind>
        <kinematic>0</kinematic>
      </link>
    </model>
    <model name='unit_box_clone_4_clone_clone'>
      <pose>6.91416 -5.81443 0.5 0 -0 0</pose>
      <link name='link'>
        <inertial>
          <mass>1</mass>
          <inertia>
            <ixx>0.166667</ixx>
            <ixy>0</ixy>
            <ixz>0</ixz>
            <iyy>0.166667</iyy>
            <iyz>0</iyz>
            <izz>0.166667</izz>
          </inertia>
          <pose>0 0 0 0 -0 0</pose>
        </inertial>
        <collision name='collision'>
          <geometry>
            <box>
              <size>1 1 1</size>
            </box>
          </geometry>
          <max_contacts>10</max_contacts>
          <surface>
            <contact>
              <ode/>
            </contact>
            <bounce/>
            <friction>
              <torsional>
                <ode/>
              </torsional>
              <ode/>
            </friction>
          </surface>
        </collision>
        <visual name='visual'>
          <geometry>
            <box>
              <size>1 1 1</size>
            </box>
          </geometry>
          <material>
            <script>
              <name>Gazebo/Grey</name>
              <uri>file://media/materials/scripts/gazebo.material</uri>
            </script>
          </material>
        </visual>
        <self_collide>0</self_collide>
        <enable_wind>0</enable_wind>
        <kinematic>0</kinematic>
      </link>
    </model>
    <model name='unit_box_clone_4_clone_clone_0'>
      <pose>6.84533 -6.89971 0.5 0 -0 0</pose>
      <link name='link'>
        <inertial>
          <mass>1</mass>
          <inertia>
            <ixx>0.166667</ixx>
            <ixy>0</ixy>
            <ixz>0</ixz>
            <iyy>0.166667</iyy>
            <iyz>0</iyz>
            <izz>0.166667</izz>
          </inertia>
          <pose>0 0 0 0 -0 0</pose>
        </inertial>
        <collision name='collision'>
          <geometry>
            <box>
              <size>1 1 1</size>
            </box>
          </geometry>
          <max_contacts>10</max_contacts>
          <surface>
            <contact>
              <ode/>
            </contact>
            <bounce/>
            <friction>
              <torsional>
                <ode/>
              </torsional>
              <ode/>
            </friction>
          </surface>
        </collision>
        <visual name='visual'>
          <geometry>
            <box>
              <size>1 1 1</size>
            </box>
          </geometry>
          <material>
            <script>
              <name>Gazebo/Grey</name>
              <uri>file://media/materials/scripts/gazebo.material</uri>
            </script>
          </material>
        </visual>
        <self_collide>0</self_collide>
        <enable_wind>0</enable_wind>
        <kinematic>0</kinematic>
      </link>
    </model>
    <model name='unit_box_clone_4_clone_clone_1'>
      <pose>6.88351 -7.99943 0.5 0 -0 0</pose>
      <link name='link'>
        <inertial>
          <mass>1</mass>
          <inertia>
            <ixx>0.166667</ixx>
            <ixy>0</ixy>
            <ixz>0</ixz>
            <iyy>0.166667</iyy>
            <iyz>0</iyz>
            <izz>0.166667</izz>
          </inertia>
          <pose>0 0 0 0 -0 0</pose>
        </inertial>
        <collision name='collision'>
          <geometry>
            <box>
              <size>1 1 1</size>
            </box>
          </geometry>
          <max_contacts>10</max_contacts>
          <surface>
            <contact>
              <ode/>
            </contact>
            <bounce/>
            <friction>
              <torsional>
                <ode/>
              </torsional>
              <ode/>
            </friction>
          </surface>
        </collision>
        <visual name='visual'>
          <geometry>
            <box>
              <size>1 1 1</size>
            </box>
          </geometry>
          <material>
            <script>
              <name>Gazebo/Grey</name>
              <uri>file://media/materials/scripts/gazebo.material</uri>
            </script>
          </material>
        </visual>
        <self_collide>0</self_collide>
        <enable_wind>0</enable_wind>
        <kinematic>0</kinematic>
      </link>
    </model>
    <model name='unit_box_clone_4_clone_clone_2'>
      <pose>6.82289 -9.06896 0.5 0 -0 0</pose>
      <link name='link'>
        <inertial>
          <mass>1</mass>
          <inertia>
            <ixx>0.166667</ixx>
            <ixy>0</ixy>
            <ixz>0</ixz>
            <iyy>0.166667</iyy>
            <iyz>0</iyz>
            <izz>0.166667</izz>
          </inertia>
          <pose>0 0 0 0 -0 0</pose>
        </inertial>
        <collision name='collision'>
          <geometry>
            <box>
              <size>1 1 1</size>
            </box>
          </geometry>
          <max_contacts>10</max_contacts>
          <surface>
            <contact>
              <ode/>
            </contact>
            <bounce/>
            <friction>
              <torsional>
                <ode/>
              </torsional>
              <ode/>
            </friction>
          </surface>
        </collision>
        <visual name='visual'>
          <geometry>
            <box>
              <size>1 1 1</size>
            </box>
          </geometry>
          <material>
            <script>
              <name>Gazebo/Grey</name>
              <uri>file://media/materials/scripts/gazebo.material</uri>
            </script>
          </material>
        </visual>
        <self_collide>0</self_collide>
        <enable_wind>0</enable_wind>
        <kinematic>0</kinematic>
      </link>
    </model>
    <model name='unit_box_clone_5'>
      <pose>10.548 -2.81354 0.5 0 -0 0</pose>
      <link name='link'>
        <inertial>
          <mass>1</mass>
          <inertia>
            <ixx>0.166667</ixx>
            <ixy>0</ixy>
            <ixz>0</ixz>
            <iyy>0.166667</iyy>
            <iyz>0</iyz>
            <izz>0.166667</izz>
          </inertia>
          <pose>0 0 0 0 -0 0</pose>
        </inertial>
        <collision name='collision'>
          <geometry>
            <box>
              <size>1 1 1</size>
            </box>
          </geometry>
          <max_contacts>10</max_contacts>
          <surface>
            <contact>
              <ode/>
            </contact>
            <bounce/>
            <friction>
              <torsional>
                <ode/>
              </torsional>
              <ode/>
            </friction>
          </surface>
        </collision>
        <visual name='visual'>
          <geometry>
            <box>
              <size>1 1 1</size>
            </box>
          </geometry>
          <material>
            <script>
              <name>Gazebo/Grey</name>
              <uri>file://media/materials/scripts/gazebo.material</uri>
            </script>
          </material>
        </visual>
        <self_collide>0</self_collide>
        <enable_wind>0</enable_wind>
        <kinematic>0</kinematic>
      </link>
    </model>
    <model name='unit_box_clone_5_clone'>
      <pose>10.5283 -3.89603 0.5 0 -0 0</pose>
      <link name='link'>
        <inertial>
          <mass>1</mass>
          <inertia>
            <ixx>0.166667</ixx>
            <ixy>0</ixy>
            <ixz>0</ixz>
            <iyy>0.166667</iyy>
            <iyz>0</iyz>
            <izz>0.166667</izz>
          </inertia>
          <pose>0 0 0 0 -0 0</pose>
        </inertial>
        <collision name='collision'>
          <geometry>
            <box>
              <size>1 1 1</size>
            </box>
          </geometry>
          <max_contacts>10</max_contacts>
          <surface>
            <contact>
              <ode/>
            </contact>
            <bounce/>
            <friction>
              <torsional>
                <ode/>
              </torsional>
              <ode/>
            </friction>
          </surface>
        </collision>
        <visual name='visual'>
          <geometry>
            <box>
              <size>1 1 1</size>
            </box>
          </geometry>
          <material>
            <script>
              <name>Gazebo/Grey</name>
              <uri>file://media/materials/scripts/gazebo.material</uri>
            </script>
          </material>
        </visual>
        <self_collide>0</self_collide>
        <enable_wind>0</enable_wind>
        <kinematic>0</kinematic>
      </link>
    </model>
    <model name='unit_box_clone_5_clone_0'>
      <pose>10.5856 -4.97492 0.5 0 -0 0</pose>
      <link name='link'>
        <inertial>
          <mass>1</mass>
          <inertia>
            <ixx>0.166667</ixx>
            <ixy>0</ixy>
            <ixz>0</ixz>
            <iyy>0.166667</iyy>
            <iyz>0</iyz>
            <izz>0.166667</izz>
          </inertia>
          <pose>0 0 0 0 -0 0</pose>
        </inertial>
        <collision name='collision'>
          <geometry>
            <box>
              <size>1 1 1</size>
            </box>
          </geometry>
          <max_contacts>10</max_contacts>
          <surface>
            <contact>
              <ode/>
            </contact>
            <bounce/>
            <friction>
              <torsional>
                <ode/>
              </torsional>
              <ode/>
            </friction>
          </surface>
        </collision>
        <visual name='visual'>
          <geometry>
            <box>
              <size>1 1 1</size>
            </box>
          </geometry>
          <material>
            <script>
              <name>Gazebo/Grey</name>
              <uri>file://media/materials/scripts/gazebo.material</uri>
            </script>
          </material>
        </visual>
        <self_collide>0</self_collide>
        <enable_wind>0</enable_wind>
        <kinematic>0</kinematic>
      </link>
    </model>
    <model name='unit_box_clone_5_clone_1'>
      <pose>10.5648 -6.07092 0.5 0 -0 0</pose>
      <link name='link'>
        <inertial>
          <mass>1</mass>
          <inertia>
            <ixx>0.166667</ixx>
            <ixy>0</ixy>
            <ixz>0</ixz>
            <iyy>0.166667</iyy>
            <iyz>0</iyz>
            <izz>0.166667</izz>
          </inertia>
          <pose>0 0 0 0 -0 0</pose>
        </inertial>
        <collision name='collision'>
          <geometry>
            <box>
              <size>1 1 1</size>
            </box>
          </geometry>
          <max_contacts>10</max_contacts>
          <surface>
            <contact>
              <ode/>
            </contact>
            <bounce/>
            <friction>
              <torsional>
                <ode/>
              </torsional>
              <ode/>
            </friction>
          </surface>
        </collision>
        <visual name='visual'>
          <geometry>
            <box>
              <size>1 1 1</size>
            </box>
          </geometry>
          <material>
            <script>
              <name>Gazebo/Grey</name>
              <uri>file://media/materials/scripts/gazebo.material</uri>
            </script>
          </material>
        </visual>
        <self_collide>0</self_collide>
        <enable_wind>0</enable_wind>
        <kinematic>0</kinematic>
      </link>
    </model>
    <model name='unit_box_clone_5_clone_2'>
      <pose>10.5145 -7.18903 0.5 0 -0 0</pose>
      <link name='link'>
        <inertial>
          <mass>1</mass>
          <inertia>
            <ixx>0.166667</ixx>
            <ixy>0</ixy>
            <ixz>0</ixz>
            <iyy>0.166667</iyy>
            <iyz>0</iyz>
            <izz>0.166667</izz>
          </inertia>
          <pose>0 0 0 0 -0 0</pose>
        </inertial>
        <collision name='collision'>
          <geometry>
            <box>
              <size>1 1 1</size>
            </box>
          </geometry>
          <max_contacts>10</max_contacts>
          <surface>
            <contact>
              <ode/>
            </contact>
            <bounce/>
            <friction>
              <torsional>
                <ode/>
              </torsional>
              <ode/>
            </friction>
          </surface>
        </collision>
        <visual name='visual'>
          <geometry>
            <box>
              <size>1 1 1</size>
            </box>
          </geometry>
          <material>
            <script>
              <name>Gazebo/Grey</name>
              <uri>file://media/materials/scripts/gazebo.material</uri>
            </script>
          </material>
        </visual>
        <self_collide>0</self_collide>
        <enable_wind>0</enable_wind>
        <kinematic>0</kinematic>
      </link>
    </model>
    <model name='unit_box_clone_5_clone_3'>
      <pose>10.4782 -8.26164 0.5 0 -0 0</pose>
      <link name='link'>
        <inertial>
          <mass>1</mass>
          <inertia>
            <ixx>0.166667</ixx>
            <ixy>0</ixy>
            <ixz>0</ixz>
            <iyy>0.166667</iyy>
            <iyz>0</iyz>
            <izz>0.166667</izz>
          </inertia>
          <pose>0 0 0 0 -0 0</pose>
        </inertial>
        <collision name='collision'>
          <geometry>
            <box>
              <size>1 1 1</size>
            </box>
          </geometry>
          <max_contacts>10</max_contacts>
          <surface>
            <contact>
              <ode/>
            </contact>
            <bounce/>
            <friction>
              <torsional>
                <ode/>
              </torsional>
              <ode/>
            </friction>
          </surface>
        </collision>
        <visual name='visual'>
          <geometry>
            <box>
              <size>1 1 1</size>
            </box>
          </geometry>
          <material>
            <script>
              <name>Gazebo/Grey</name>
              <uri>file://media/materials/scripts/gazebo.material</uri>
            </script>
          </material>
        </visual>
        <self_collide>0</self_collide>
        <enable_wind>0</enable_wind>
        <kinematic>0</kinematic>
      </link>
    </model>
    <state world_name='default'>
      <sim_time>3 735000000</sim_time>
      <real_time>3 970851887</real_time>
      <wall_time>1734131486 631587075</wall_time>
      <iterations>3735</iterations>
      <model name='ground_plane'>
        <pose>0 0 0 0 -0 0</pose>
        <scale>1 1 1</scale>
        <link name='link'>
          <pose>0 0 0 0 -0 0</pose>
          <velocity>0 0 0 0 -0 0</velocity>
          <acceleration>0 0 0 0 -0 0</acceleration>
          <wrench>0 0 0 0 -0 0</wrench>
        </link>
      </model>
      <model name='my_bot'>
        <pose>-0.040578 0.002456 0.2 2e-06 -0.005323 -0.029804</pose>
        <scale>1 1 1</scale>
        <link name='base_link'>
          <pose>-0.040578 0.002456 0.2 2e-06 -0.005323 -0.029804</pose>
          <velocity>-0.001769 0.000187 -0.000376 0.00019 0.001037 1.8e-05</velocity>
          <acceleration>-1.26374 0.054829 -1.79963 -2.78518 1.10599 3.13973</acceleration>
          <wrench>-69.8848 3.03203 -99.5193 0 -0 0</wrench>
        </link>
        <link name='cart'>
          <pose>-1.87314 0.057089 0.190239 0.000209 0.005318 -3.13172</pose>
          <velocity>-0.001625 0.000114 0.000869 0.000254 0.001127 -0.005278</velocity>
          <acceleration>-0.138223 -0.183649 3.98217 -2.63098 0.935427 3.1231</acceleration>
          <wrench>-6.91118 -9.18247 199.109 0 -0 0</wrench>
        </link>
        <link name='cart2'>
          <pose>-5.10633 0.025153 0.173043 0.000246 0.005314 -3.12467</pose>
          <velocity>-0.000518 0.017128 0.004712 0.000329 0.001532 0.006631</velocity>
          <acceleration>2.80991 -0.157817 12.0657 -2.38317 0.185659 2.71701</acceleration>
          <wrench>56.1981 -3.15634 241.314 0 -0 0</wrench>
        </link>
        <link name='cart2_left_wheel'>
          <pose>-6.69677 -0.551841 0.164676 -1.57055 0.006225 -3.12467</pose>
          <velocity>0.003287 0.006562 0.006972 0.000342 0.000707 0.006633</velocity>
          <acceleration>-0.7581 0.913046 13.6997 0.778447 0.013061 -0.529154</acceleration>
          <wrench>-3.7905 4.56523 68.4983 0 -0 0</wrench>
        </link>
        <link name='cart2_right_wheel'>
          <pose>-6.71538 0.548002 0.164406 1.57105 0.010948 -3.12467</pose>
          <velocity>-0.004026 0.006435 0.00736 0.000315 0.00089 0.00664</velocity>
          <acceleration>-0.322157 0.917213 14.5551 0.736318 0.012348 -0.513755</acceleration>
          <wrench>-1.61078 4.58607 72.7755 0 -0 0</wrench>
        </link>
        <link name='cart3'>
          <pose>-7.83929 -0.021098 0.158513 1e-06 0.005321 3.11251</pose>
          <velocity>0.001904 -0.001211 0.007665 0.000447 0.001132 -0.000638</velocity>
          <acceleration>5.67195 -0.384549 17.4211 -2.32656 0.866689 -2.70036</acceleration>
          <wrench>113.439 -7.69099 348.423 0 -0 0</wrench>
        </link>
        <link name='cart3_left_wheel'>
          <pose>-9.45458 -0.524336 0.15 1.5708 -0.883677 -0.029082</pose>
          <velocity>0.001716 -1.1e-05 0.009417 7.2e-05 0.011455 -8.1e-05</velocity>
          <acceleration>3.56682 0.571144 18.7932 -0.325885 -0.628761 2.00894</acceleration>
          <wrench>17.8341 2.85572 93.9658 0 -0 0</wrench>
        </link>
        <link name='cart3_right_wheel'>
          <pose>-9.4226 0.575197 0.15 -1.57079 -0.984148 -0.029084</pose>
          <velocity>0.002448 -0.000344 0.010074 0.00229 0.016317 -0.000152</velocity>
          <acceleration>3.166 0.001335 20.1152 0.273296 -1.39459 -1.28845</acceleration>
          <wrench>15.83 0.006676 100.576 0 -0 0</wrench>
        </link>
        <link name='cart_left_wheel'>
          <pose>-4.06707 -0.564611 0.178663 -1.57059 -0.000156 -3.13172</pose>
          <velocity>-0.004779 0.011594 0.002922 0.000192 0.000501 -0.005276</velocity>
          <acceleration>-2.37457 0.168293 6.08925 0.348204 0.003437 -0.020514</acceleration>
          <wrench>-11.8729 0.841467 30.4462 0 -0 0</wrench>
        </link>
        <link name='cart_right_wheel'>
          <pose>-4.07892 0.635331 0.178412 1.57101 0.00686 -3.13171</pose>
          <velocity>0.001546 0.01168 0.003169 0.000173 0.000418 -0.005274</velocity>
          <acceleration>-2.36494 0.208016 6.52621 0.315462 0.003114 -0.016268</acceleration>
          <wrench>-11.8247 1.04008 32.6311 0 -0 0</wrench>
        </link>
        <link name='left_wheel'>
          <pose>-0.028658 0.402276 0.200002 -1.57083 -0.012928 -0.029807</pose>
          <velocity>-0.001223 4.1e-05 2.3e-05 -4e-06 -0.00527 -0.002784</velocity>
          <acceleration>-1.83752 0.094634 0.026236 2.87168 1.03583 0.259697</acceleration>
          <wrench>-9.1876 0.473168 0.131181 0 -0 0</wrench>
        </link>
        <link name='right_wheel'>
          <pose>-0.052497 -0.397364 0.200002 1.57083 -0.003336 -0.029801</pose>
          <velocity>-0.001185 0.000229 0.000151 -0.001272 -0.005075 0.002814</velocity>
          <acceleration>-1.80372 0.435306 0.290649 1.09293 0.923515 -0.287246</acceleration>
          <wrench>-9.01858 2.17653 1.45325 0 -0 0</wrench>
        </link>
      </model>
      <model name='unit_box'>
        <pose>4.23851 -3.06538 0.500015 -2.5e-05 4e-06 -0.000933</pose>
        <scale>1 1 1</scale>
        <link name='link'>
          <pose>4.23851 -3.06538 0.500015 -2.5e-05 4e-06 -0.000933</pose>
          <velocity>-0.006908 -0.000356 -0.007435 0.008682 -0.005898 -0.007942</velocity>
          <acceleration>-0.019515 -1.13938 -1.66757 -2.77879 1.15613 -1.20983</acceleration>
          <wrench>-0.019515 -1.13938 -1.66757 0 -0 0</wrench>
        </link>
      </model>
      <model name='unit_box_clone'>
        <pose>3.135 -2.95471 0.499995 1e-05 -0 0</pose>
        <scale>1 1 1</scale>
        <link name='link'>
          <pose>3.135 -2.95471 0.499995 1e-05 -0 0</pose>
          <velocity>2e-06 -0.004896 -0.004891 0.009792 5e-06 0</velocity>
          <acceleration>0.004709 -0.011055 -9.78158 0.022108 0.009414 -1e-06</acceleration>
          <wrench>0.004709 -0.011055 -9.78158 0 -0 0</wrench>
        </link>
      </model>
      <model name='unit_box_clone_0'>
        <pose>1.88411 -3.03551 0.499995 1e-05 -0 0</pose>
        <scale>1 1 1</scale>
        <link name='link'>
          <pose>1.88411 -3.03551 0.499995 1e-05 -0 0</pose>
          <velocity>2e-06 -0.004896 -0.004891 0.009792 5e-06 0</velocity>
          <acceleration>0.004709 -0.011055 -9.78158 0.022108 0.009414 -1e-06</acceleration>
          <wrench>0.004709 -0.011055 -9.78158 0 -0 0</wrench>
        </link>
      </model>
      <model name='unit_box_clone_1'>
        <pose>4.21455 -4.06569 0.5 0 0 -0.000791</pose>
        <scale>1 1 1</scale>
        <link name='link'>
          <pose>4.21455 -4.06569 0.5 0 0 -0.000791</pose>
          <velocity>-0.001602 -0.002436 0.000865 0.004871 -0.003205 -0</velocity>
          <acceleration>-3.14877 -5.08845 1.74113 -2.38878 -0.013068 0.000664</acceleration>
          <wrench>-3.14877 -5.08845 1.74113 0 -0 0</wrench>
        </link>
      </model>
      <model name='unit_box_clone_2'>
        <pose>4.23787 -5.15748 1.49999 -9e-06 7e-06 2.7e-05</pose>
        <scale>1 1 1</scale>
        <link name='link'>
          <pose>4.23787 -5.15748 1.49999 -9e-06 7e-06 2.7e-05</pose>
          <velocity>-0.000924 0.005894 -0.003213 0.001674 -0.000225 0.001146</velocity>
          <acceleration>-0.292541 0.26554 -5.01505 2.14672 -1.31885 1.12322</acceleration>
          <wrench>-0.292541 0.26554 -5.01505 0 -0 0</wrench>
        </link>
      </model>
      <model name='unit_box_clone_3'>
        <pose>4.30769 -6.24065 0.500002 -6e-06 -1e-06 -2.8e-05</pose>
        <scale>1 1 1</scale>
        <link name='link'>
          <pose>4.30769 -6.24065 0.500002 -6e-06 -1e-06 -2.8e-05</pose>
          <velocity>0.00057 0.001185 0.001062 -0.007011 -0.003702 0.004791</velocity>
          <acceleration>-0.405144 2.01261 1.40414 2.24666 -1.03836 3.11017</acceleration>
          <wrench>-0.405144 2.01261 1.40414 0 -0 0</wrench>
        </link>
      </model>
      <model name='unit_box_clone_4'>
        <pose>4.33198 -7.29131 0.5 -1e-06 -1e-06 1e-05</pose>
        <scale>1 1 1</scale>
        <link name='link'>
          <pose>4.33198 -7.29131 0.5 -1e-06 -1e-06 1e-05</pose>
          <velocity>0.00012 0.000762 0.001283 -0.00157 0.001415 -0.000808</velocity>
          <acceleration>1.69616 1.25256 2.5562 0.696246 -1.43182 2.26232</acceleration>
          <wrench>1.69616 1.25256 2.5562 0 -0 0</wrench>
        </link>
      </model>
      <model name='unit_box_clone_4_clone'>
        <pose>4.2553 -3.01272 1.50001 -2.5e-05 4e-06 0.000467</pose>
        <scale>1 1 1</scale>
        <link name='link'>
          <pose>4.2553 -3.01272 1.50001 -2.5e-05 4e-06 0.000467</pose>
          <velocity>-0.015128 -0.009227 -0.004186 0.008795 -0.011376 -0.007944</velocity>
          <acceleration>-5.71397 -5.3752 3.11847 -2.57418 0.98709 -2.43189</acceleration>
          <wrench>-5.71397 -5.3752 3.11847 0 -0 0</wrench>
        </link>
      </model>
      <model name='unit_box_clone_4_clone_clone'>
        <pose>4.22578 -4.07997 1.49999 -9e-06 9e-06 0.000112</pose>
        <scale>1 1 1</scale>
        <link name='link'>
          <pose>4.22578 -4.07997 1.49999 -9e-06 9e-06 0.000112</pose>
          <velocity>0.005822 -0.001276 -0.008312 -0.009255 0.010102 -0.002064</velocity>
          <acceleration>-1.93223 -1.19295 -7.86778 -2.92213 -0.973739 -2.04808</acceleration>
          <wrench>-1.93223 -1.19295 -7.86778 0 -0 0</wrench>
        </link>
      </model>
      <model name='unit_box_clone_4_clone_clone_0'>
        <pose>4.23146 -5.17276 0.499997 -1.3e-05 7e-06 4e-06</pose>
        <scale>1 1 1</scale>
        <link name='link'>
          <pose>4.23146 -5.17276 0.499997 -1.3e-05 7e-06 4e-06</pose>
          <velocity>-0.000684 0.000359 -0.006039 -0.012728 -0.000223 0.001145</velocity>
          <acceleration>-0.06104 0.832402 -13.487 -0.991787 1.025 1.07284</acceleration>
          <wrench>-0.06104 0.832402 -13.487 0 -0 0</wrench>
        </link>
      </model>
      <model name='unit_box_clone_4_clone_clone_1'>
        <pose>4.31974 -6.21313 1.5 2e-06 -2e-06 -7e-06</pose>
        <scale>1 1 1</scale>
        <link name='link'>
          <pose>4.31974 -6.21313 1.5 2e-06 -2e-06 -7e-06</pose>
          <velocity>-0.003552 -0.000393 0.00331 0.010272 -0.004472 0.004975</velocity>
          <acceleration>-8.26287 -8.32809 9.96674 2.77686 -0.841617 0.04258</acceleration>
          <wrench>-8.26287 -8.32809 9.96674 0 -0 0</wrench>
        </link>
      </model>
      <model name='unit_box_clone_4_clone_clone_2'>
        <pose>4.34225 -7.26577 1.5 6e-06 1e-06 2.7e-05</pose>
        <scale>1 1 1</scale>
        <link name='link'>
          <pose>4.34225 -7.26577 1.5 6e-06 1e-06 2.7e-05</pose>
          <velocity>0.001963 -0.003977 0.000615 0.010975 0.002979 -0.001746</velocity>
          <acceleration>6.52806 -6.60466 3.50992 -0.774696 -0.521634 -1.86825</acceleration>
          <wrench>6.52806 -6.60466 3.50992 0 -0 0</wrench>
        </link>
      </model>
      <model name='unit_box_clone_5'>
        <pose>10.548 -2.81354 0.499995 1e-05 -0 0</pose>
        <scale>1 1 1</scale>
        <link name='link'>
          <pose>10.548 -2.81354 0.499995 1e-05 -0 0</pose>
          <velocity>2e-06 -0.004896 -0.004891 0.009792 5e-06 0</velocity>
          <acceleration>0.004709 -0.011055 -9.78158 0.022108 0.009414 -1e-06</acceleration>
          <wrench>0.004709 -0.011055 -9.78158 0 -0 0</wrench>
        </link>
      </model>
      <model name='unit_box_clone_5_clone'>
        <pose>10.5283 -3.89603 0.499995 1e-05 -0 0</pose>
        <scale>1 1 1</scale>
        <link name='link'>
          <pose>10.5283 -3.89603 0.499995 1e-05 -0 0</pose>
          <velocity>2e-06 -0.004896 -0.004891 0.009792 5e-06 0</velocity>
          <acceleration>0.004709 -0.011055 -9.78158 0.022108 0.009414 -1e-06</acceleration>
          <wrench>0.004709 -0.011055 -9.78158 0 -0 0</wrench>
        </link>
      </model>
      <model name='unit_box_clone_5_clone_0'>
        <pose>10.5856 -4.97492 0.499995 1e-05 -0 0</pose>
        <scale>1 1 1</scale>
        <link name='link'>
          <pose>10.5856 -4.97492 0.499995 1e-05 -0 0</pose>
          <velocity>2e-06 -0.004896 -0.004891 0.009792 5e-06 0</velocity>
          <acceleration>0.004709 -0.011055 -9.78158 0.022108 0.009414 -1e-06</acceleration>
          <wrench>0.004709 -0.011055 -9.78158 0 -0 0</wrench>
        </link>
      </model>
      <model name='unit_box_clone_5_clone_1'>
        <pose>10.5648 -6.07092 0.499995 1e-05 -0 0</pose>
        <scale>1 1 1</scale>
        <link name='link'>
          <pose>10.5648 -6.07092 0.499995 1e-05 -0 0</pose>
          <velocity>2e-06 -0.004896 -0.004891 0.009792 5e-06 0</velocity>
          <acceleration>0.004709 -0.011055 -9.78158 0.022108 0.009414 -1e-06</acceleration>
          <wrench>0.004709 -0.011055 -9.78158 0 -0 0</wrench>
        </link>
      </model>
      <model name='unit_box_clone_5_clone_2'>
        <pose>10.5145 -7.18903 0.499995 1e-05 -0 0</pose>
        <scale>1 1 1</scale>
        <link name='link'>
          <pose>10.5145 -7.18903 0.499995 1e-05 -0 0</pose>
          <velocity>2e-06 -0.004896 -0.004891 0.009792 5e-06 0</velocity>
          <acceleration>0.004709 -0.011055 -9.78158 0.022108 0.009414 -1e-06</acceleration>
          <wrench>0.004709 -0.011055 -9.78158 0 -0 0</wrench>
        </link>
      </model>
      <model name='unit_box_clone_5_clone_3'>
        <pose>10.4782 -8.26164 0.499995 1e-05 -0 0</pose>
        <scale>1 1 1</scale>
        <link name='link'>
          <pose>10.4782 -8.26164 0.499995 1e-05 -0 0</pose>
          <velocity>2e-06 -0.004896 -0.004891 0.009792 5e-06 0</velocity>
          <acceleration>0.004709 -0.011055 -9.78158 0.022108 0.009414 -1e-06</acceleration>
          <wrench>0.004709 -0.011055 -9.78158 0 -0 0</wrench>
        </link>
      </model>
      <light name='sun'>
        <pose>0 0 10 0 -0 0</pose>
      </light>
    </state>
    <gui fullscreen='0'>
      <camera name='user_camera'>
        <pose>-3.83827 2.20737 13.8437 0 0.949797 -0.827818</pose>
        <view_controller>orbit</view_controller>
        <projection_type>perspective</projection_type>
      </camera>
    </gui>
  </world>
</sdf>
